Workbook

Sheet Supuestos
A1: Cafés Monte Bianco – Supuestos y datos del caso (miles de €, salvo indicación)
A2: Azul = dato del caso o supuesto editable · Negro = fórmula · Verde = vínculo a otra hoja · Amarillo = supuesto clave
A3: Concepto | B3: Valor | C3: Unidad | D3: Fuente / comentario
A5: 1. Estado de resultados 2019 (Anexo 1)
A6: Ingresos marca propia 2019 | B6: 7902.72 | C6: miles € | D6: Anexo 1
A7: Ingresos marca de calidad superior 2019 | B7: 36705.24 | C7: miles € | D7: Anexo 1
A8: Costo de mercadería vendida 2019 | B8: 26421 | C8: miles € | D8: Anexo 1 (incluye depreciación)
A9: Depreciación 2019 incluida en el CMV | B9: 2081 | C9: miles € | D9: Nota (*) del Anexo 1
A10: Gastos de marketing 2019 | B10: 3303 | C10: miles € | D10: Anexo 1
A11: Gastos de I+D 2019 | B11: 2647 | C11: miles € | D11: Anexo 1
A12: Gastos de venta 2019 | B12: 2844 | C12: miles € | D12: Anexo 1
A13: Gastos administrativos 2019 | B13: 3781 | C13: miles € | D13: Anexo 1
A14: Gastos de intereses 2019 | B14: 3043 | C14: miles € | D14: Anexo 1
A15: Tasa de impuestos | B15: 0.4 | C15: % | D15: Anexo 1
A17: 2. Balance al 31-dic-2019 (Anexo 1)
A18: Caja | B18: 892 | C18: miles € | D18: Anexo 1
A19: Inventario de materia prima | B19: 2313 | C19: miles € | D19: Anexo 1
A20: Bienes terminados | B20: 913 | C20: miles € | D20: Anexo 1
A21: Bienes terminados (kg) | B21: 174000 | C21: kg | D21: Anexo 1 y Anexo 5 (inventario inicial)
A22: Cuentas a cobrar | B22: 7448.928 | C22: miles € | D22: Anexo 1
A23: Bienes de uso (bruto, incluye la ampliación de 4,5 M€) | B23: 33706 | C23: miles € | D23: Anexo 1
A24: Depreciación acumulada | B24: 9758 | C24: miles € | D24: Anexo 1 (se resta)
A25: Lote desocupado incluido en bienes de uso | B25: 10000 | C25: miles € | D25: Nota (*) del balance; se asume en miles de € como el resto del estado
A26: Cuentas a pagar | B26: 388 | C26: miles € | D26: Anexo 1
A27: Línea de crédito | B27: 20000 | C27: miles € | D27: Anexo 1
A28: Deuda a largo plazo | B28: 8000 | C28: miles € | D28: Anexo 1
A29: Límite total de la línea de crédito | B29: 20000 | C29: miles € | D29: Texto del caso (Dino)
A31: 3. Volúmenes 2019 (Anexo 4)
A32: Kilos vendidos marca propia 2019 | B32: 1152000 | C32: kg | D32: Anexo 4
A33: Kilos vendidos calidad superior 2019 | B33: 1196000 | C33: kg | D33: Anexo 4
A35: 4. Capacidad e inversión
A36: Capacidad de producción mensual tras la ampliación | B36: 500000 | C36: kg/mes | D36: 350.000 + 150.000 kg/mes (texto del caso y Anexo 5)
A37: Capacidad anual | B37: =B36*12 -> 6000000 | C37: kg/año | D37: 6.000.000 kg (Anexo 5)
A38: Inversión de la ampliación (ya incluida en bienes de uso 2019) | B38: 4500 | C38: miles € | D38: Texto del caso
A39: Vida útil de la ampliación | B39: 15 | C39: años | D39: Texto del caso
A40: Depreciación incremental anual | B40: =B38/B39 -> 300 | C40: miles € | D40: Lineal
A41: Depreciación total 2020 | B41: =B9+B40 -> 2381 | C41: miles € | D41: 2.081 base + incremental (indicación del enunciado)
A42: ¿Los costos fijos del Anexo 3 ya incluyen la depreciación base? (1 = sí, 0 = no) | B42: 1 | C42: 1/0 | D42: Supuesto: sí, porque la depreciación 2019 está dentro del CMV; con 0 se suma 2.081 aparte al CMV
A44: 5. Marca propia (Anexos 2 y 3)
A45: Precio marca propia | B45: =Anexos!B4 -> 7 | C45: €/kg | D45: Anexo 2 / texto (7,00 €/kg)
...

Sheet Anexos
A1: Datos de los Anexos 2, 3 y 4
A2: Fuente: caso HBS 204-S18, Cafés Monte Bianco
A3: Calidad del café | B3: D | C3: C | D3: B | E3: BB | F3: A | G3: AA | H3: AAA
A4: Precio por kilo (€) | B4: 7 | C4: 15.5 | D4: 21 | E4: 24 | F4: 28 | G4: 31 | H4: 34
A5: Costo unitario variable (€/kg) | B5: 5.25 | C5: 9.93 | D5: 11.36 | E5: 12.96 | F5: 14.15 | G5: 15.25 | H5: 16.26
A6: Costos fijos (miles €) * | B6: 2641 | C6: 3262 | D6: 3262 | E6: 3262 | F6: 3262 | G6: 3262 | H6: 3262
A7: * Los costos fijos de calidad superior incluyen los costos fijos de marca propia (Anexo 3).
A8: Anexo 2 – Volumen anual estimado (kg) según % de gasto de marketing / ventas
A9: Marketing / ventas | B9: D | C9: C | D9: B | E9: BB | F9: A | G9: AA | H9: AAA
A10: 0 | B10: 6000000 | C10: 2395000 | D10: 1645000 | E10: 1529000 | F10: 1103000 | G10: 667000 | H10: 127000
A11: 0.01 | C11: 2455000 | D11: 1696000 | E11: 1566000 | F11: 1145000 | G11: 717000 | H11: 157000
A12: 0.02 | C12: 2545000 | D12: 1720700 | E12: 1649000 | F12: 1226000 | G12: 799000 | H12: 229000
A13: 0.03 | C13: 2665000 | D13: 1896000 | E13: 1760000 | F13: 1334000 | G13: 910000 | H13: 325000
A14: 0.04 | C14: 2800000 | D14: 2024000 | E14: 1884000 | F14: 1456000 | G14: 1034000 | H14: 433000
A15: 0.05 | C15: 2950000 | D15: 2166000 | E15: 2022000 | F15: 1591000 | G15: 1172000 | H15: 553000
A16: 0.06 | C16: 3130000 | D16: 2367000 | E16: 2157000 | F16: 1723000 | G16: 1307000 | H16: 667000
A17: 0.07 | C17: 3196000 | D17: 2417000 | E17: 2195000 | F17: 1792000 | G17: 1345000 | H17: 694000
A18: 0.08 | C18: 3268000 | D18: 2446000 | E18: 2231000 | F18: 1823000 | G18: 1366000 | H18: 752000
A19: 0.09 | C19: 3310000 | D19: 2465000 | E19: 2258000 | F19: 1837000 | G19: 1495000 | H19: 875000
A20: 0.1 | C20: 3340000 | D20: 2494000 | E20: 2286000 | F20: 1843000 | G20: 1523000 | H20: 935000
A23: Anexo 4 – Ventas 2019 por mes
A24: Mes | B24: % del total anual | C24: Marca propia (kg) | D24: Calidad superior (kg)
A25: Enero | B25: 0.071 | C25: =Supuestos!$B$32*B25 -> 81792 | D25: =Supuestos!$B$33*B25 -> 84916
A26: Febrero | B26: 0.09 | C26: =Supuestos!$B$32*B26 -> 103680 | D26: =Supuestos!$B$33*B26 -> 107640
A27: Marzo | B27: 0.118 | C27: =Supuestos!$B$32*B27 -> 135936 | D27: =Supuestos!$B$33*B27 -> 141128
A28: Abril | B28: 0.075 | C28: =Supuestos!$B$32*B28 -> 86400 | D28: =Supuestos!$B$33*B28 -> 89700
A29: Mayo | B29: 0.081 | C29: =Supuestos!$B$32*B29 -> 93312 | D29: =Supuestos!$B$33*B29 -> 96876
A30: Junio | B30: 0.05 | C30: =Supuestos!$B$32*B30 -> 57600 | D30: =Supuestos!$B$33*B30 -> 59800
A31: Julio | B31: 0.042 | C31: =Supuestos!$B$32*B31 -> 48384 | D31: =Supuestos!$B$33*B31 -> 50232
A32: Agosto | B32: 0.033 | C32: =Supuestos!$B$32*B32 -> 38016 | D32: =Supuestos!$B$33*B32 -> 39468
A33: Septiembre | B33: 0.068 | C33: =Supuestos!$B$32*B33 -> 78336 | D33: =Supuestos!$B$33*B33 -> 81328
A34: Octubre | B34: 0.131 | C34: =Supuestos!$B$32*B34 -> 150912 | D34: =Supuestos!$B$33*B34 -> 156676
A35: Noviembre | B35: 0.121 | C35: =Supuestos!$B$32*B35 -> 139392 | D35: =Supuestos!$B$33*B35 -> 144716
A36: Diciembre | B36: 0.12 | C36: =Supuestos!$B$32*B36 -> 138240 | D36: =Supuestos!$B$33*B36 -> 143520
A37: Total | B37: =SUM(B25:B36) -> 1 | C37: =SUM(C25:C36) -> 1152000 | D37: =SUM(D25:D36) -> 1196000

Sheet Diagnostico_2019
A1: Diagnóstico financiero 2019 – ¿fue un año “excelente”?
A2: Miles de €
A3: Estado de resultados 2019
A4: Concepto | B4: Miles € | C4: % de ventas
A5: Ingresos marca propia | B5: =Supuestos!$B$6 -> 7902.72 | C5: =B5/$B$7 -> 0.17715941
A6: Ingresos calidad superior | B6: =Supuestos!$B$7 -> 36705.24 | C6: =B6/$B$7 -> 0.82284059
A7: Ingresos totales | B7: =B5+B6 -> 44607.96 | C7: =B7/$B$7 -> 1
A8: Costo de mercadería vendida (incluye depreciación) | B8: =Supuestos!$B$8 -> 26421 | C8: =B8/$B$7 -> 0.59229339
A9: Margen bruto | B9: =B7-B8 -> 18186.96 | C9: =B9/$B$7 -> 0.40770661
A10: Gastos de marketing | B10: =Supuestos!$B$10 -> 3303 | C10: =B10/$B$7 -> 0.074045081
A11: Gastos de I+D | B11: =Supuestos!$B$11 -> 2647 | C11: =B11/$B$7 -> 0.059339185
A12: Gastos de venta | B12: =Supuestos!$B$12 -> 2844 | C12: =B12/$B$7 -> 0.063755437
A13: Gastos administrativos | B13: =Supuestos!$B$13 -> 3781 | C13: =B13/$B$7 -> 0.084760657
A14: Utilidad operativa (EBIT) | B14: =B9-SUM(B10:B13) -> 5611.96 | C14: =B14/$B$7 -> 0.12580625
A15: Gastos de intereses | B15: =Supuestos!$B$14 -> 3043 | C15: =B15/$B$7 -> 0.068216525
A16: Utilidad antes de impuestos | B16: =B14-B15 -> 2568.96 | C16: =B16/$B$7 -> 0.057589722
A17: Impuestos | B17: =MAX(0,B16)*Supuestos!$B$15 -> 1027.584 | C17: =B17/$B$7 -> 0.023035889
A18: Utilidad neta | B18: =B16-B17 -> 1541.376 | C18: =B18/$B$7 -> 0.034553833
A19: Depreciación (dentro del CMV) | B19: =Supuestos!$B$9 -> 2081 | C19: =B19/$B$7 -> 0.046650867
A20: EBITDA | B20: =B14+B19 -> 7692.96 | C20: =B20/$B$7 -> 0.17245711
A22: Balance al 31-dic-2019
A23: Concepto | B23: Miles € | C23: % del activo
A24: Caja | B24: =Supuestos!$B$18 -> 892 | C24: =B24/$B$32 -> 0.025116199
A25: Inventario de materia prima | B25: =Supuestos!$B$19 -> 2313 | C25: =B25/$B$32 -> 0.065127543
A26: Bienes terminados | B26: =Supuestos!$B$20 -> 913 | C26: =B26/$B$32 -> 0.0257075
A27: Cuentas a cobrar | B27: =Supuestos!$B$22 -> 7448.928 | C27: =B27/$B$32 -> 0.20974076
A28: Activo corriente | B28: =SUM(B24:B27) -> 11566.928 | C28: =B28/$B$32 -> 0.325692
A29: Bienes de uso (bruto) | B29: =Supuestos!$B$23 -> 33706 | C29: =B29/$B$32 -> 0.9490657
A30: Depreciación acumulada | B30: =-Supuestos!$B$24 -> -9758 | C30: =B30/$B$32 -> -0.2747577
A31: Bienes de uso netos | B31: =B29+B30 -> 23948 | C31: =B31/$B$32 -> 0.674308
A32: Total activos | B32: =B28+B31 -> 35514.928 | C32: =B32/$B$32 -> 1
A33: Cuentas a pagar | B33: =Supuestos!$B$26 -> 388 | C33: =B33/$B$32 -> 0.010924983
A34: Línea de crédito | B34: =Supuestos!$B$27 -> 20000 | C34: =B34/$B$32 -> 0.56314348
A35: Pasivo corriente | B35: =B33+B34 -> 20388 | C35: =B35/$B$32 -> 0.57406846
A36: Deuda a largo plazo | B36: =Supuestos!$B$28 -> 8000 | C36: =B36/$B$32 -> 0.22525739
A37: Total pasivos | B37: =B35+B36 -> 28388 | C37: =B37/$B$32 -> 0.79932585
A38: Patrimonio neto | B38: =B32-B37 -> 7126.928 | C38: =B38/$B$32 -> 0.20067415
A39: Total pasivos y patrimonio | B39: =B37+B38 -> 35514.928 | C39: =B39/$B$32 -> 1
A40: Nota: el total del activo suma 35.515 (el PDF del caso muestra 33.515 por error de tipeo; el patrimonio de 7.127 cuadra con 35.515).
A42: Indicadores clave 2019
...

Sheet Mix_Produccion
A1: Mini estado de resultados por alternativa de mix: (p – cv)·q – CF – %M·p·q
A2: Miles de €. Capacidad = 6.000.000 kg; la capacidad no usada por calidad superior se llena con marca propia a 7 €/kg (demanda garantizada a plena capacidad).
A3: Capacidad anual (kg) | B3: =Supuestos!$B$37 -> 6000000
A4: Precio marca propia (€/kg) | B4: =Supuestos!$B$45 -> 7
A5: Costo variable marca propia (€/kg) | B5: =Supuestos!$B$46 -> 5.25
A6: Costos fijos solo marca propia | B6: =Supuestos!$B$47 -> 2641
A7: Costos fijos con calidad superior (incluyen los de marca propia) | B7: =Supuestos!$B$48 -> 3262
A8: Resultado solo marca propia (D) a plena capacidad | B8: =(B4-B5)*B3/1000-B6 -> 7859
A10: Tabla A – Resultado vendiendo SOLO calidad superior (miles €)
A11: Calidad | C11: =Anexos!C3 -> C | D11: =Anexos!D3 -> B | E11: =Anexos!E3 -> BB | F11: =Anexos!F3 -> A | G11: =Anexos!G3 -> AA | H11: =Anexos!H3 -> AAA
A12: Precio (€/kg) | C12: =Anexos!C4 -> 15.5 | D12: =Anexos!D4 -> 21 | E12: =Anexos!E4 -> 24 | F12: =Anexos!F4 -> 28 | G12: =Anexos!G4 -> 31 | H12: =Anexos!H4 -> 34
A13: Costo variable (€/kg) | C13: =Anexos!C5 -> 9.93 | D13: =Anexos!D5 -> 11.36 | E13: =Anexos!E5 -> 12.96 | F13: =Anexos!F5 -> 14.15 | G13: =Anexos!G5 -> 15.25 | H13: =Anexos!H5 -> 16.26
A14: % marketing / ventas ↓
A15: =Anexos!A10 -> 0 | C15: =(C$12-C$13-$A15*C$12)*Anexos!C10/1000-$B$7 -> 10078.15 | D15: =(D$12-D$13-$A15*D$12)*Anexos!D10/1000-$B$7 -> 12595.8 | E15: =(E$12-E$13-$A15*E$12)*Anexos!E10/1000-$B$7 -> 13618.16 | F15: =(F$12-F$13-$A15*F$12)*Anexos!F10/1000-$B$7 -> 12014.55 | G15: =(G$12-G$13-$A15*G$12)*Anexos!G10/1000-$B$7 -> 7243.25 | H15: =(H$12-H$13-$A15*H$12)*Anexos!H10/1000-$B$7 -> -1009.02
A16: =Anexos!A11 -> 0.01 | C16: =(C$12-C$13-$A16*C$12)*Anexos!C11/1000-$B$7 -> 10031.825 | D16: =(D$12-D$13-$A16*D$12)*Anexos!D11/1000-$B$7 -> 12731.28 | E16: =(E$12-E$13-$A16*E$12)*Anexos!E11/1000-$B$7 -> 13650.8 | F16: =(F$12-F$13-$A16*F$12)*Anexos!F11/1000-$B$7 -> 12275.65 | G16: =(G$12-G$13-$A16*G$12)*Anexos!G11/1000-$B$7 -> 7808.48 | H16: =(H$12-H$13-$A16*H$12)*Anexos!H11/1000-$B$7 -> -530.2
A17: =Anexos!A12 -> 0.02 | C17: =(C$12-C$13-$A17*C$12)*Anexos!C12/1000-$B$7 -> 10124.7 | D17: =(D$12-D$13-$A17*D$12)*Anexos!D12/1000-$B$7 -> 12602.854 | E17: =(E$12-E$13-$A17*E$12)*Anexos!E12/1000-$B$7 -> 14151.44 | F17: =(F$12-F$13-$A17*F$12)*Anexos!F12/1000-$B$7 -> 13031.54 | G17: =(G$12-G$13-$A17*G$12)*Anexos!G12/1000-$B$7 -> 8826.87 | H17: =(H$12-H$13-$A17*H$12)*Anexos!H12/1000-$B$7 -> 644.74
A18: =Anexos!A13 -> 0.03 | C18: =(C$12-C$13-$A18*C$12)*Anexos!C13/1000-$B$7 -> 10342.825 | D18: =(D$12-D$13-$A18*D$12)*Anexos!D13/1000-$B$7 -> 13820.96 | E18: =(E$12-E$13-$A18*E$12)*Anexos!E13/1000-$B$7 -> 14901.2 | F18: =(F$12-F$13-$A18*F$12)*Anexos!F13/1000-$B$7 -> 14093.34 | G18: =(G$12-G$13-$A18*G$12)*Anexos!G13/1000-$B$7 -> 10224.2 | H18: =(H$12-H$13-$A18*H$12)*Anexos!H13/1000-$B$7 -> 2172
A19: =Anexos!A14 -> 0.04 | C19: =(C$12-C$13-$A19*C$12)*Anexos!C14/1000-$B$7 -> 10598 | D19: =(D$12-D$13-$A19*D$12)*Anexos!D14/1000-$B$7 -> 14549.2 | E19: =(E$12-E$13-$A19*E$12)*Anexos!E14/1000-$B$7 -> 15728.72 | F19: =(F$12-F$13-$A19*F$12)*Anexos!F14/1000-$B$7 -> 15272.88 | G19: =(G$12-G$13-$A19*G$12)*Anexos!G14/1000-$B$7 -> 11741.34 | H19: =(H$12-H$13-$A19*H$12)*Anexos!H14/1000-$B$7 -> 3830.54
A20: =Anexos!A15 -> 0.05 | C20: =(C$12-C$13-$A20*C$12)*Anexos!C15/1000-$B$7 -> 10883.25 | D20: =(D$12-D$13-$A20*D$12)*Anexos!D15/1000-$B$7 -> 15343.94 | E20: =(E$12-E$13-$A20*E$12)*Anexos!E15/1000-$B$7 -> 16634.48 | F20: =(F$12-F$13-$A20*F$12)*Anexos!F15/1000-$B$7 -> 16545.95 | G20: =(G$12-G$13-$A20*G$12)*Anexos!G15/1000-$B$7 -> 13380.4 | H20: =(H$12-H$13-$A20*H$12)*Anexos!H15/1000-$B$7 -> 5608.12
A21: =Anexos!A16 -> 0.06 | C21: =(C$12-C$13-$A21*C$12)*Anexos!C16/1000-$B$7 -> 11261.2 | D21: =(D$12-D$13-$A21*D$12)*Anexos!D16/1000-$B$7 -> 16573.46 | E21: =(E$12-E$13-$A21*E$12)*Anexos!E16/1000-$B$7 -> 17445.2 | F21: =(F$12-F$13-$A21*F$12)*Anexos!F16/1000-$B$7 -> 17706.91 | G21: =(G$12-G$13-$A21*G$12)*Anexos!G16/1000-$B$7 -> 14892.23 | H21: =(H$12-H$13-$A21*H$12)*Anexos!H16/1000-$B$7 -> 7209.9
A22: =Anexos!A17 -> 0.07 | C22: =(C$12-C$13-$A22*C$12)*Anexos!C17/1000-$B$7 -> 11072.06 | D22: =(D$12-D$13-$A22*D$12)*Anexos!D17/1000-$B$7 -> 16484.89 | E22: =(E$12-E$13-$A22*E$12)*Anexos!E17/1000-$B$7 -> 17283.2 | F22: =(F$12-F$13-$A22*F$12)*Anexos!F17/1000-$B$7 -> 18044.88 | G22: =(G$12-G$13-$A22*G$12)*Anexos!G17/1000-$B$7 -> 15003.1 | H22: =(H$12-H$13-$A22*H$12)*Anexos!H17/1000-$B$7 -> 7397.84
A23: =Anexos!A18 -> 0.08 | C23: =(C$12-C$13-$A23*C$12)*Anexos!C18/1000-$B$7 -> 10888.44 | D23: =(D$12-D$13-$A23*D$12)*Anexos!D18/1000-$B$7 -> 16208.16 | E23: =(E$12-E$13-$A23*E$12)*Anexos!E18/1000-$B$7 -> 17084.72 | F23: =(F$12-F$13-$A23*F$12)*Anexos!F18/1000-$B$7 -> 17903.03 | G23: =(G$12-G$13-$A23*G$12)*Anexos!G18/1000-$B$7 -> 14864.82 | H23: =(H$12-H$13-$A23*H$12)*Anexos!H18/1000-$B$7 -> 8033.04
A24: =Anexos!A19 -> 0.09 | C24: =(C$12-C$13-$A24*C$12)*Anexos!C19/1000-$B$7 -> 10557.25 | D24: =(D$12-D$13-$A24*D$12)*Anexos!D19/1000-$B$7 -> 15841.75 | E24: =(E$12-E$13-$A24*E$12)*Anexos!E19/1000-$B$7 -> 16789.04 | F24: =(F$12-F$13-$A24*F$12)*Anexos!F19/1000-$B$7 -> 17551.21 | G24: =(G$12-G$13-$A24*G$12)*Anexos!G19/1000-$B$7 -> 16113.2 | H24: =(H$12-H$13-$A24*H$12)*Anexos!H19/1000-$B$7 -> 9583
A25: =Anexos!A20 -> 0.1 | C25: =(C$12-C$13-$A25*C$12)*Anexos!C20/1000-$B$7 -> 10164.8 | D25: =(D$12-D$13-$A25*D$12)*Anexos!D20/1000-$B$7 -> 15542.76 | E25: =(E$12-E$13-$A25*E$12)*Anexos!E20/1000-$B$7 -> 16489.04 | F25: =(F$12-F$13-$A25*F$12)*Anexos!F20/1000-$B$7 -> 17103.15 | G25: =(G$12-G$13-$A25*G$12)*Anexos!G20/1000-$B$7 -> 16003.95 | H25: =(H$12-H$13-$A25*H$12)*Anexos!H20/1000-$B$7 -> 10145.9
A28: Tabla B – Capacidad ociosa si se vende SOLO calidad superior (% de 6.000.000 kg)
A29: Calidad | C29: =Anexos!C3 -> C | D29: =Anexos!D3 -> B | E29: =Anexos!E3 -> BB | F29: =Anexos!F3 -> A | G29: =Anexos!G3 -> AA | H29: =Anexos!H3 -> AAA
A30: Precio (€/kg) | C30: =Anexos!C4 -> 15.5 | D30: =Anexos!D4 -> 21 | E30: =Anexos!E4 -> 24 | F30: =Anexos!F4 -> 28 | G30: =Anexos!G4 -> 31 | H30: =Anexos!H4 -> 34
A31: Costo variable (€/kg) | C31: =Anexos!C5 -> 9.93 | D31: =Anexos!D5 -> 11.36 | E31: =Anexos!E5 -> 12.96 | F31: =Anexos!F5 -> 14.15 | G31: =Anexos!G5 -> 15.25 | H31: =Anexos!H5 -> 16.26
A32: % marketing / ventas ↓
A33: =Anexos!A10 -> 0 | C33: =1-Anexos!C10/$B$3 -> 0.60083333 | D33: =1-Anexos!D10/$B$3 -> 0.72583333 | E33: =1-Anexos!E10/$B$3 -> 0.74516667 | F33: =1-Anexos!F10/$B$3 -> 0.81616667 | G33: =1-Anexos!G10/$B$3 -> 0.88883333 | H33: =1-Anexos!H10/$B$3 -> 0.97883333
A34: =Anexos!A11 -> 0.01 | C34: =1-Anexos!C11/$B$3 -> 0.59083333 | D34: =1-Anexos!D11/$B$3 -> 0.71733333 | E34: =1-Anexos!E11/$B$3 -> 0.739 | F34: =1-Anexos!F11/$B$3 -> 0.80916667 | G34: =1-Anexos!G11/$B$3 -> 0.8805 | H34: =1-Anexos!H11/$B$3 -> 0.97383333
A35: =Anexos!A12 -> 0.02 | C35: =1-Anexos!C12/$B$3 -> 0.57583333 | D35: =1-Anexos!D12/$B$3 -> 0.71321667 | E35: =1-Anexos!E12/$B$3 -> 0.72516667 | F35: =1-Anexos!F12/$B$3 -> 0.79566667 | G35: =1-Anexos!G12/$B$3 -> 0.86683333 | H35: =1-Anexos!H12/$B$3 -> 0.96183333
A36: =Anexos!A13 -> 0.03 | C36: =1-Anexos!C13/$B$3 -> 0.55583333 | D36: =1-Anexos!D13/$B$3 -> 0.684 | E36: =1-Anexos!E13/$B$3 -> 0.70666667 | F36: =1-Anexos!F13/$B$3 -> 0.77766667 | G36: =1-Anexos!G13/$B$3 -> 0.84833333 | H36: =1-Anexos!H13/$B$3 -> 0.94583333
A37: =Anexos!A14 -> 0.04 | C37: =1-Anexos!C14/$B$3 -> 0.53333333 | D37: =1-Anexos!D14/$B$3 -> 0.66266667 | E37: =1-Anexos!E14/$B$3 -> 0.686 | F37: =1-Anexos!F14/$B$3 -> 0.75733333 | G37: =1-Anexos!G14/$B$3 -> 0.82766667 | H37: =1-Anexos!H14/$B$3 -> 0.92783333
A38: =Anexos!A15 -> 0.05 | C38: =1-Anexos!C15/$B$3 -> 0.50833333 | D38: =1-Anexos!D15/$B$3 -> 0.639 | E38: =1-Anexos!E15/$B$3 -> 0.663 | F38: =1-Anexos!F15/$B$3 -> 0.73483333 | G38: =1-Anexos!G15/$B$3 -> 0.80466667 | H38: =1-Anexos!H15/$B$3 -> 0.90783333
A39: =Anexos!A16 -> 0.06 | C39: =1-Anexos!C16/$B$3 -> 0.47833333 | D39: =1-Anexos!D16/$B$3 -> 0.6055 | E39: =1-Anexos!E16/$B$3 -> 0.6405 | F39: =1-Anexos!F16/$B$3 -> 0.71283333 | G39: =1-Anexos!G16/$B$3 -> 0.78216667 | H39: =1-Anexos!H16/$B$3 -> 0.88883333
A40: =Anexos!A17 -> 0.07 | C40: =1-Anexos!C17/$B$3 -> 0.46733333 | D40: =1-Anexos!D17/$B$3 -> 0.59716667 | E40: =1-Anexos!E17/$B$3 -> 0.63416667 | F40: =1-Anexos!F17/$B$3 -> 0.70133333 | G40: =1-Anexos!G17/$B$3 -> 0.77583333 | H40: =1-Anexos!H17/$B$3 -> 0.88433333
A41: =Anexos!A18 -> 0.08 | C41: =1-Anexos!C18/$B$3 -> 0.45533333 | D41: =1-Anexos!D18/$B$3 -> 0.59233333 | E41: =1-Anexos!E18/$B$3 -> 0.62816667 | F41: =1-Anexos!F18/$B$3 -> 0.69616667 | G41: =1-Anexos!G18/$B$3 -> 0.77233333 | H41: =1-Anexos!H18/$B$3 -> 0.87466667
A42: =Anexos!A19 -> 0.09 | C42: =1-Anexos!C19/$B$3 -> 0.44833333 | D42: =1-Anexos!D19/$B$3 -> 0.58916667 | E42: =1-Anexos!E19/$B$3 -> 0.62366667 | F42: =1-Anexos!F19/$B$3 -> 0.69383333 | G42: =1-Anexos!G19/$B$3 -> 0.75083333 | H42: =1-Anexos!H19/$B$3 -> 0.85416667
A43: =Anexos!A20 -> 0.1 | C43: =1-Anexos!C20/$B$3 -> 0.44333333 | D43: =1-Anexos!D20/$B$3 -> 0.58433333 | E43: =1-Anexos!E20/$B$3 -> 0.619 | F43: =1-Anexos!F20/$B$3 -> 0.69283333 | G43: =1-Anexos!G20/$B$3 -> 0.74616667 | H43: =1-Anexos!H20/$B$3 -> 0.84416667
...

Sheet EEFF_2020
A1: Estados financieros proyectados 2020 – comparación de estrategias (miles €)
A2: Deuda constante (línea de crédito 20.000 + largo plazo 8.000); la caja es la variable de cierre del balance.
A3: Concepto | B3: 2019 Real | C3: 2020 Solo marca propia | D3: 2020 MIX óptimo | E3: Comentario
A5: Supuestos operativos
A6: Calidad de alta gama | B6: Mix 2019 | C6: — | D6: =Mix_Produccion!$B$79 -> A
A7: Kilos marca propia | B7: =Supuestos!$B$32 -> 1152000 | C7: =Supuestos!$B$37 -> 6000000 | D7: =Mix_Produccion!$B$82 -> 4208000
A8: Precio marca propia (€/kg) | B8: =Supuestos!$B$6/B7*1000 -> 6.86 | C8: =Supuestos!$B$45 -> 7 | D8: =Supuestos!$B$45 -> 7
A9: Costo variable marca propia (€/kg) | C9: =Supuestos!$B$46 -> 5.25 | D9: =Supuestos!$B$46 -> 5.25
A10: Kilos calidad superior | B10: =Supuestos!$B$33 -> 1196000 | C10: 0 | D10: =Mix_Produccion!$B$81 -> 1792000
A11: Precio calidad superior (€/kg) | B11: =Supuestos!$B$7/B10*1000 -> 30.69 | C11: 0 | D11: =Mix_Produccion!$B$83 -> 28
A12: Costo variable calidad superior (€/kg) | C12: 0 | D12: =Mix_Produccion!$B$84 -> 14.15
A13: % marketing / ventas de calidad superior | B13: =Supuestos!$B$10/Supuestos!$B$7 -> 0.089987152 | C13: 0 | D13: =Mix_Produccion!$B$80 -> 0.07
A14: Costos fijos de manufactura (Anexo 3) | C14: =Supuestos!$B$47 -> 2641 | D14: =Supuestos!$B$48 -> 3262
A15: Uso de la capacidad de 6.000.000 kg | B15: =(B7+B10)/Supuestos!$B$37 -> 0.39133333 | C15: =(C7+C10)/Supuestos!$B$37 -> 1 | D15: =(D7+D10)/Supuestos!$B$37 -> 1
A17: Estado de resultados
A18: Ventas marca propia | B18: =Supuestos!$B$6 -> 7902.72 | C18: =C7*C8/1000 -> 42000 | D18: =D7*D8/1000 -> 29456
A19: Ventas calidad superior | B19: =Supuestos!$B$7 -> 36705.24 | C19: =C10*C11/1000 -> 0 | D19: =D10*D11/1000 -> 50176
A20: Ventas totales | B20: =B18+B19 -> 44607.96 | C20: =C18+C19 -> 42000 | D20: =D18+D19 -> 79632
A21: Costo variable marca propia | C21: =C7*C9/1000 -> 31500 | D21: =D7*D9/1000 -> 22092
A22: Costo variable calidad superior | C22: =C10*C12/1000 -> 0 | D22: =D10*D12/1000 -> 25356.8
A23: Costos fijos de manufactura (incluyen depreciación base 2.081) | C23: =C14 -> 2641 | D23: =D14 -> 3262
A24: Depreciación incremental de la ampliación (4.500 / 15) | C24: =Supuestos!$B$40 -> 300 | D24: =Supuestos!$B$40 -> 300
A25: Depreciación base adicional (solo si el supuesto = 0) | C25: =(1-Supuestos!$B$42)*Supuestos!$B$9 -> 0 | D25: =(1-Supuestos!$B$42)*Supuestos!$B$9 -> 0
A26: Costo de mercadería vendida | B26: =Supuestos!$B$8 -> 26421 | C26: =SUM(C21:C25) -> 34441 | D26: =SUM(D21:D25) -> 51010.8
A27: Margen bruto | B27: =B20-B26 -> 18186.96 | C27: =C20-C26 -> 7559 | D27: =D20-D26 -> 28621.2
A28: Gastos de marketing | B28: =Supuestos!$B$10 -> 3303 | C28: =Supuestos!$B$10*(1-Supuestos!$B$51) -> 0 | D28: =D13*D19 -> 3512.32 | E28: Mix: %M × ventas de calidad superior
A29: Gastos de I+D | B29: =Supuestos!$B$11 -> 2647 | C29: =Supuestos!$B$11*(1-Supuestos!$B$53) -> 661.75 | D29: =Supuestos!$B$11*(1-Supuestos!$B$58) -> 2647
A30: Gastos de venta | B30: =Supuestos!$B$12 -> 2844 | C30: =Supuestos!$B$12*(1-Supuestos!$B$52) -> 995.4 | D30: =Supuestos!$B$12*(1-Supuestos!$B$57) -> 2844
A31: Gastos administrativos | B31: =Supuestos!$B$13 -> 3781 | C31: =Supuestos!$B$13*(1-Supuestos!$B$54) -> 1890.5 | D31: =Supuestos!$B$13*(1-Supuestos!$B$59) -> 3781
A32: Total gastos operativos | B32: =SUM(B28:B31) -> 12575 | C32: =SUM(C28:C31) -> 3547.65 | D32: =SUM(D28:D31) -> 12784.32
A33: Utilidad operativa (EBIT) | B33: =B27-B32 -> 5611.96 | C33: =C27-C32 -> 4011.35 | D33: =D27-D32 -> 15836.88
A34: Gastos de intereses | B34: =Supuestos!$B$14 -> 3043 | C34: =Supuestos!$B$70*(Supuestos!$B$27+Supuestos!$B$28) -> 3043 | D34: =Supuestos!$B$70*(Supuestos!$B$27+Supuestos!$B$28) -> 3043 | E34: Deuda constante × tasa implícita 2019
A35: Utilidad antes de impuestos | B35: =B33-B34 -> 2568.96 | C35: =C33-C34 -> 968.35 | D35: =D33-D34 -> 12793.88
A36: Impuestos (40 %) | B36: =MAX(0,B35)*Supuestos!$B$15 -> 1027.584 | C36: =MAX(0,C35)*Supuestos!$B$15 -> 387.34 | D36: =MAX(0,D35)*Supuestos!$B$15 -> 5117.552
A37: Utilidad neta | B37: =B35-B36 -> 1541.376 | C37: =C35-C36 -> 581.01 | D37: =D35-D36 -> 7676.328
A38: Memo: depreciación total del año | B38: =Supuestos!$B$9 -> 2081 | C38: =Supuestos!$B$41 -> 2381 | D38: =Supuestos!$B$41 -> 2381
A39: Memo: EBITDA | B39: =B33+B38 -> 7692.96 | C39: =C33+C38 -> 6392.35 | D39: =D33+D38 -> 18217.88
A41: Balance general al 31 de diciembre
A42: Caja (variable de cierre) | B42: =Supuestos!$B$18 -> 892 | C42: =C57-SUM(C43:C45)-C49 -> -4018.6208 | D42: =D57-SUM(D43:D45)-D49 -> 411.47421 | E42: Negativa = faltante que habría que financiar
A43: Inventario de materia prima | B43: =Supuestos!$B$19 -> 2313 | C43: =(C26-C38)/Supuestos!$B$66 -> 3046.622 | D43: =(D26-D38)/Supuestos!$B$66 -> 4621.2296 | E43: Rotación 2019 sobre CMV sin depreciación
...

Sheet Mejoras_MP
A1: ¿Se pueden mejorar los indicadores de la estrategia de solo marca propia? (miles €)
A2: Cada palanca se mide por separado contra el escenario base; la fila final las suma (aproximación: ignora interacciones menores).
A3: Palancas (celdas amarillas editables)
A4: Meses de cobro negociados con los minoristas (base = 3) | B4: 2
A5: Aumento de precio negociado (€/kg) | B5: 0.25
A6: Venta del lote desocupado a valor libro, aplicada a reducir la línea de crédito | B6: =Supuestos!$B$25 -> 10000
A7: Días de pago a proveedores (base ≈ 6 días) | B7: 30
A8: Reducción del inventario de materia prima | B8: 0.3
A10: Base: 2020 solo marca propia
A11: Utilidad neta | B11: =EEFF_2020!$C$37 -> 581.01
A12: Patrimonio final | B12: =EEFF_2020!$C$56 -> 7707.938
A13: Excedente / (necesidad) de financiamiento | B13: =EEFF_2020!$C$60 -> -4858.4709
A14: Deuda financiera | B14: =EEFF_2020!$C$52+EEFF_2020!$C$54 -> 28000
A15: Cuentas a cobrar | B15: =EEFF_2020!$C$45 -> 15624
A17: Efecto de cada palanca
A18: Palanca | B18: Δ Utilidad neta | C18: Δ Caja (+ libera / – consume) | D18: Δ Deuda | E18: Utilidad neta resultante | F18: Excedente / (necesidad) de financiamiento resultante | G18: ROE resultante
A19: ="Cobro en "&B4&" meses en lugar de 3" -> Cobro en 2 meses en lugar de 3 | B19: =0 -> 0 | C19: =B15-(EEFF_2020!$C$18*SUM(OFFSET(Anexos!$B$36,1-$B$4,0,$B$4,1))) -> 5502 | D19: =0 -> 0 | E19: =$B$11+B19 -> 581.01 | F19: =$B$13+C19 -> 643.52914 | G19: =E19/($B$12+B19) -> 0.075378136
A20: ="Precio +"&TEXT(B5,"0.00")&" €/kg" -> Precio +0.25 €/kg | B20: =$B$5*EEFF_2020!$C$7/1000*(1-Supuestos!$B$15) -> 900 | C20: =B20-$B$5*EEFF_2020!$C$7/1000*Supuestos!$B$64 -> 342 | D20: =0 -> 0 | E20: =$B$11+B20 -> 1481.01 | F20: =$B$13+C20 -> -4516.4709 | G20: =E20/($B$12+B20) -> 0.17205166
A21: Venta del lote y reducción de deuda | B21: =$B$6*Supuestos!$B$70*(1-Supuestos!$B$15) -> 652.07143 | C21: =B21 -> 652.07143 | D21: =-$B$6 -> -10000 | E21: =$B$11+B21 -> 1233.0814 | F21: =$B$13+C21 -> -4206.3994 | G21: =E21/($B$12+B21) -> 0.14749761
A22: Alargar el pago a proveedores | B22: =0 -> 0 | C22: =(EEFF_2020!$C$26-EEFF_2020!$C$38)*$B$7/365-EEFF_2020!$C$51 -> 2124.0052 | D22: =0 -> 0 | E22: =$B$11+B22 -> 581.01 | F22: =$B$13+C22 -> -2734.4656 | G22: =E22/($B$12+B22) -> 0.075378136
A23: Reducir inventario de materia prima | B23: =0 -> 0 | C23: =EEFF_2020!$C$43*$B$8 -> 913.98661 | D23: =0 -> 0 | E23: =$B$11+B23 -> 581.01 | F23: =$B$13+C23 -> -3944.4843 | G23: =E23/($B$12+B23) -> 0.075378136
A24: Todas las palancas juntas | B24: =SUM(B19:B23) -> 1552.0714 | C24: =SUM(C19:C23) -> 9534.0633 | D24: =SUM(D19:D23) -> -10000 | E24: =$B$11+B24 -> 2133.0814 | F24: =$B$13+C24 -> 4675.5924 | G24: =E24/($B$12+B24) -> 0.23035413
A26: Referencias
A27: Utilidad neta 2019 | B27: =EEFF_2020!$B$37 -> 1541.376
A28: Utilidad neta 2020 – MIX óptimo | B28: =EEFF_2020!$D$37 -> 7676.328
A29: Deuda / patrimonio con todas las palancas | B29: =($B$14+D24)/($B$12+B24) -> 1.9438425
A31: Lectura: las palancas de capital de trabajo reducen la necesidad de caja, pero la utilidad de la estrategia sigue muy por debajo de 2019 y del mix; el problema de fondo es el bajo margen unitario (1,75 €/kg).

Sheet Plan_Mensual
A1: Plan mensual 2020: ventas, producción, inventario y composición de las cuentas a cobrar
A2: Escenario solo marca propia replica el Anexo 5; en el mix la calidad superior no se almacena (se produce al ritmo de la venta) y la marca propia usa la capacidad restante.
A4: Mes | B4: % ventas | C4: Capacidad (kg) | D4: MP: ventas (kg) | E4: MP: producción (kg) | F4: MP: inventario final (kg) | G4: MP: ventas (miles €) | H4: MIX: calidad sup. (kg) | I4: MIX: marca propia (kg) | J4: MIX: capacidad libre p/ MP (kg) | K4: MIX: producción MP (kg) | L4: MIX: inventario MP (kg) | M4: MIX: ventas (miles €)
A5: Inventario inicial | F5: =Supuestos!$B$21 -> 174000 | L5: =Supuestos!$B$21 -> 174000
A6: Enero | B6: =Anexos!B25 -> 0.071 | C6: =Supuestos!$B$36 -> 500000 | D6: =Supuestos!$B$37*B6 -> 426000 | E6: =MIN(C6,MAX(0,D6+F6-F5)) -> 500000 | F6: =MAX(F7+D7-C7,0) -> 248000 | G6: =D6*Supuestos!$B$45/1000 -> 2982 | H6: =Mix_Produccion!$B$81*B6 -> 127232 | I6: =Mix_Produccion!$B$82*B6 -> 298768 | J6: =C6-H6 -> 372768 | K6: =MIN(J6,MAX(0,I6+L6-L5)) -> 372768 | L6: =MAX(L7+I7-J7,0) -> 248000 | M6: =(H6*Mix_Produccion!$B$83+I6*Supuestos!$B$45)/1000 -> 5653.872
A7: Febrero | B7: =Anexos!B26 -> 0.09 | C7: =Supuestos!$B$36 -> 500000 | D7: =Supuestos!$B$37*B7 -> 540000 | E7: =MIN(C7,MAX(0,D7+F7-F6)) -> 500000 | F7: =MAX(F8+D8-C8,0) -> 208000 | G7: =D7*Supuestos!$B$45/1000 -> 3780 | H7: =Mix_Produccion!$B$81*B7 -> 161280 | I7: =Mix_Produccion!$B$82*B7 -> 378720 | J7: =C7-H7 -> 338720 | K7: =MIN(J7,MAX(0,I7+L7-L6)) -> 338720 | L7: =MAX(L8+I8-J8,0) -> 208000 | M7: =(H7*Mix_Produccion!$B$83+I7*Supuestos!$B$45)/1000 -> 7166.88
A8: Marzo | B8: =Anexos!B27 -> 0.118 | C8: =Supuestos!$B$36 -> 500000 | D8: =Supuestos!$B$37*B8 -> 708000 | E8: =MIN(C8,MAX(0,D8+F8-F7)) -> 500000 | F8: =MAX(F9+D9-C9,0) -> 0 | G8: =D8*Supuestos!$B$45/1000 -> 4956 | H8: =Mix_Produccion!$B$81*B8 -> 211456 | I8: =Mix_Produccion!$B$82*B8 -> 496544 | J8: =C8-H8 -> 288544 | K8: =MIN(J8,MAX(0,I8+L8-L7)) -> 288544 | L8: =MAX(L9+I9-J9,0) -> 0 | M8: =(H8*Mix_Produccion!$B$83+I8*Supuestos!$B$45)/1000 -> 9396.576
A9: Abril | B9: =Anexos!B28 -> 0.075 | C9: =Supuestos!$B$36 -> 500000 | D9: =Supuestos!$B$37*B9 -> 450000 | E9: =MIN(C9,MAX(0,D9+F9-F8)) -> 450000 | F9: =MAX(F10+D10-C10,0) -> 0 | G9: =D9*Supuestos!$B$45/1000 -> 3150 | H9: =Mix_Produccion!$B$81*B9 -> 134400 | I9: =Mix_Produccion!$B$82*B9 -> 315600 | J9: =C9-H9 -> 365600 | K9: =MIN(J9,MAX(0,I9+L9-L8)) -> 315600 | L9: =MAX(L10+I10-J10,0) -> 0 | M9: =(H9*Mix_Produccion!$B$83+I9*Supuestos!$B$45)/1000 -> 5972.4
A10: Mayo | B10: =Anexos!B29 -> 0.081 | C10: =Supuestos!$B$36 -> 500000 | D10: =Supuestos!$B$37*B10 -> 486000 | E10: =MIN(C10,MAX(0,D10+F10-F9)) -> 486000 | F10: =MAX(F11+D11-C11,0) -> 0 | G10: =D10*Supuestos!$B$45/1000 -> 3402 | H10: =Mix_Produccion!$B$81*B10 -> 145152 | I10: =Mix_Produccion!$B$82*B10 -> 340848 | J10: =C10-H10 -> 354848 | K10: =MIN(J10,MAX(0,I10+L10-L9)) -> 340848 | L10: =MAX(L11+I11-J11,0) -> 0 | M10: =(H10*Mix_Produccion!$B$83+I10*Supuestos!$B$45)/1000 -> 6450.192
A11: Junio | B11: =Anexos!B30 -> 0.05 | C11: =Supuestos!$B$36 -> 500000 | D11: =Supuestos!$B$37*B11 -> 300000 | E11: =MIN(C11,MAX(0,D11+F11-F10)) -> 390000 | F11: =MAX(F12+D12-C12,0) -> 90000 | G11: =D11*Supuestos!$B$45/1000 -> 2100 | H11: =Mix_Produccion!$B$81*B11 -> 89600 | I11: =Mix_Produccion!$B$82*B11 -> 210400 | J11: =C11-H11 -> 410400 | K11: =MIN(J11,MAX(0,I11+L11-L10)) -> 300400 | L11: =MAX(L12+I12-J12,0) -> 90000 | M11: =(H11*Mix_Produccion!$B$83+I11*Supuestos!$B$45)/1000 -> 3981.6
A12: Julio | B12: =Anexos!B31 -> 0.042 | C12: =Supuestos!$B$36 -> 500000 | D12: =Supuestos!$B$37*B12 -> 252000 | E12: =MIN(C12,MAX(0,D12+F12-F11)) -> 500000 | F12: =MAX(F13+D13-C13,0) -> 338000 | G12: =D12*Supuestos!$B$45/1000 -> 1764 | H12: =Mix_Produccion!$B$81*B12 -> 75264 | I12: =Mix_Produccion!$B$82*B12 -> 176736 | J12: =C12-H12 -> 424736 | K12: =MIN(J12,MAX(0,I12+L12-L11)) -> 424736 | L12: =MAX(L13+I13-J13,0) -> 338000 | M12: =(H12*Mix_Produccion!$B$83+I12*Supuestos!$B$45)/1000 -> 3344.544
A13: Agosto | B13: =Anexos!B32 -> 0.033 | C13: =Supuestos!$B$36 -> 500000 | D13: =Supuestos!$B$37*B13 -> 198000 | E13: =MIN(C13,MAX(0,D13+F13-F12)) -> 500000 | F13: =MAX(F14+D14-C14,0) -> 640000 | G13: =D13*Supuestos!$B$45/1000 -> 1386 | H13: =Mix_Produccion!$B$81*B13 -> 59136 | I13: =Mix_Produccion!$B$82*B13 -> 138864 | J13: =C13-H13 -> 440864 | K13: =MIN(J13,MAX(0,I13+L13-L12)) -> 440864 | L13: =MAX(L14+I14-J14,0) -> 640000 | M13: =(H13*Mix_Produccion!$B$83+I13*Supuestos!$B$45)/1000 -> 2627.856
A14: Septiembre | B14: =Anexos!B33 -> 0.068 | C14: =Supuestos!$B$36 -> 500000 | D14: =Supuestos!$B$37*B14 -> 408000 | E14: =MIN(C14,MAX(0,D14+F14-F13)) -> 500000 | F14: =MAX(F15+D15-C15,0) -> 732000 | G14: =D14*Supuestos!$B$45/1000 -> 2856 | H14: =Mix_Produccion!$B$81*B14 -> 121856 | I14: =Mix_Produccion!$B$82*B14 -> 286144 | J14: =C14-H14 -> 378144 | K14: =MIN(J14,MAX(0,I14+L14-L13)) -> 378144 | L14: =MAX(L15+I15-J15,0) -> 732000 | M14: =(H14*Mix_Produccion!$B$83+I14*Supuestos!$B$45)/1000 -> 5414.976
A15: Octubre | B15: =Anexos!B34 -> 0.131 | C15: =Supuestos!$B$36 -> 500000 | D15: =Supuestos!$B$37*B15 -> 786000 | E15: =MIN(C15,MAX(0,D15+F15-F14)) -> 500000 | F15: =MAX(F16+D16-C16,0) -> 446000 | G15: =D15*Supuestos!$B$45/1000 -> 5502 | H15: =Mix_Produccion!$B$81*B15 -> 234752 | I15: =Mix_Produccion!$B$82*B15 -> 551248 | J15: =C15-H15 -> 265248 | K15: =MIN(J15,MAX(0,I15+L15-L14)) -> 265248 | L15: =MAX(L16+I16-J16,0) -> 446000 | M15: =(H15*Mix_Produccion!$B$83+I15*Supuestos!$B$45)/1000 -> 10431.792
A16: Noviembre | B16: =Anexos!B35 -> 0.121 | C16: =Supuestos!$B$36 -> 500000 | D16: =Supuestos!$B$37*B16 -> 726000 | E16: =MIN(C16,MAX(0,D16+F16-F15)) -> 500000 | F16: =MAX(F17+D17-C17,0) -> 220000 | G16: =D16*Supuestos!$B$45/1000 -> 5082 | H16: =Mix_Produccion!$B$81*B16 -> 216832 | I16: =Mix_Produccion!$B$82*B16 -> 509168 | J16: =C16-H16 -> 283168 | K16: =MIN(J16,MAX(0,I16+L16-L15)) -> 283168 | L16: =MAX(L17+I17-J17,0) -> 220000 | M16: =(H16*Mix_Produccion!$B$83+I16*Supuestos!$B$45)/1000 -> 9635.472
A17: Diciembre | B17: =Anexos!B36 -> 0.12 | C17: =Supuestos!$B$36 -> 500000 | D17: =Supuestos!$B$37*B17 -> 720000 | E17: =MIN(C17,MAX(0,D17+F17-F16)) -> 500000 | F17: =Supuestos!$B$69 -> 0 | G17: =D17*Supuestos!$B$45/1000 -> 5040 | H17: =Mix_Produccion!$B$81*B17 -> 215040 | I17: =Mix_Produccion!$B$82*B17 -> 504960 | J17: =C17-H17 -> 284960 | K17: =MIN(J17,MAX(0,I17+L17-L16)) -> 284960 | L17: =Supuestos!$B$69 -> 0 | M17: =(H17*Mix_Produccion!$B$83+I17*Supuestos!$B$45)/1000 -> 9555.84
A18: Total | B18: =SUM(B6:B17) -> 1 | C18: =SUM(C6:C17) -> 6000000 | D18: =SUM(D6:D17) -> 6000000 | E18: =SUM(E6:E17) -> 5826000 | G18: =SUM(G6:G17) -> 42000 | H18: =SUM(H6:H17) -> 1792000 | I18: =SUM(I6:I17) -> 4208000 | J18: =SUM(J6:J17) -> 4208000 | K18: =SUM(K6:K17) -> 4034000 | M18: =SUM(M6:M17) -> 79632
A20: Control MP: inicial + producción – ventas – final (debe ser 0) | B20: =F5+E18-D18-F17 -> 0
A21: Control MIX: inicial + producción MP – ventas MP – final (debe ser 0) | B21: =L5+K18-I18-L17 -> 0
A22: Control MIX: meses en que la calidad superior excede la capacidad (debe ser 0) | B22: =COUNTIF(J6:J17,"<0") -> 0
A24: Composición de las cuentas a cobrar al 31-dic-2020 (miles €)
A25: Mes | B25: Solo MP | C25: MIX: calidad sup. | D25: MIX: marca propia | E25: MIX: total
A26: Octubre | B26: =G15 -> 5502 | C26: =IF("Octubre"="Diciembre",H15*Mix_Produccion!$B$83/1000,0) -> 0 | D26: =I15*Supuestos!$B$45/1000 -> 3858.736 | E26: =C26+D26 -> 3858.736
A27: Noviembre | B27: =G16 -> 5082 | C27: =IF("Noviembre"="Diciembre",H16*Mix_Produccion!$B$83/1000,0) -> 0 | D27: =I16*Supuestos!$B$45/1000 -> 3564.176 | E27: =C27+D27 -> 3564.176
A28: Diciembre | B28: =G17 -> 5040 | C28: =IF("Diciembre"="Diciembre",H17*Mix_Produccion!$B$83/1000,0) -> 6021.12 | D28: =I17*Supuestos!$B$45/1000 -> 3534.72 | E28: =C28+D28 -> 9555.84
A29: Total CxC | B29: =SUM(B26:B28) -> 15624 | C29: =SUM(C26:C28) -> 6021.12 | D29: =SUM(D26:D28) -> 10957.632 | E29: =SUM(E26:E28) -> 16978.752
A30: Comparación: CxC al 31-dic-2019 | B30: =Supuestos!$B$22 -> 7448.928
A31: Nota: con 3 meses de cobro, la CxC solo de marca propia equivale al 37,2 % de las ventas anuales (oct 13,1 % + nov 12,1 % + dic 12,0 %), no a 90/365 = 24,7 %, porque las ventas no son estacionarias.
