Workbook

Sheet Resumen
A1: Nelson Nurseries - Resumen de resultados (miles de USD)
A2: Todas las cifras están vinculadas a las hojas de cálculo; cambiar 'Supuestos' actualiza todo.
A4: Escenario | B4: Ventas | C4: Utilidad neta | D4: Margen neto | E4: ROE | F4: Flujo caja libre | G4: Deuda requerida | H4: Deuda/patrimonio | I4: Cobertura int.
A5: ='Proyeccion 2020'!B4 -> Base: ratios 2019 | B5: ='Proyeccion 2020'!B20 -> 1363.44 | C5: ='Proyeccion 2020'!B29 -> 71.946516 | D5: ='Proyeccion 2020'!B71 -> 0.052768377 | E5: ='Proyeccion 2020'!B73 -> 0.059649897 | F5: ='Proyeccion 2020'!B65 -> -190.12348 | G5: ='Proyeccion 2020'!B47 -> 289.79868 | H5: ='Proyeccion 2020'!B81 -> 0.24026823 | I5: ='Proyeccion 2020'!B82 -> 7.2819782
A6: ='Proyeccion 2020'!C4 -> Base sin reponer caja (0,9%) | B6: ='Proyeccion 2020'!C20 -> 1363.44 | C6: ='Proyeccion 2020'!C29 -> 75.931729 | D6: ='Proyeccion 2020'!C71 -> 0.055691288 | E6: ='Proyeccion 2020'!C73 -> 0.062746664 | F6: ='Proyeccion 2020'!C65 -> -186.13827 | G6: ='Proyeccion 2020'!C47 -> 188.95827 | H6: ='Proyeccion 2020'!C81 -> 0.15614686 | I6: ='Proyeccion 2020'!C82 -> 11.168115
A7: ='Proyeccion 2020'!D4 -> Medida: cobranza DSO 45 | B7: ='Proyeccion 2020'!D20 -> 1363.44 | C7: ='Proyeccion 2020'!D29 -> 72.860974 | D7: ='Proyeccion 2020'!D71 -> 0.053439076 | E7: ='Proyeccion 2020'!D73 -> 0.060362298 | F7: ='Proyeccion 2020'!D65 -> -166.98437 | G7: ='Proyeccion 2020'!D47 -> 266.65957 | H7: ='Proyeccion 2020'!D81 -> 0.2209164 | I7: ='Proyeccion 2020'!D82 -> 7.9138645
A8: ='Proyeccion 2020'!E4 -> Medida: inventario DIO 450 | B8: ='Proyeccion 2020'!E20 -> 1363.44 | C8: ='Proyeccion 2020'!E29 -> 73.886588 | D8: ='Proyeccion 2020'!E71 -> 0.054191302 | E8: ='Proyeccion 2020'!E73 -> 0.06116001 | F8: ='Proyeccion 2020'!E65 -> -141.03259 | G8: ='Proyeccion 2020'!E47 -> 240.70779 | H8: ='Proyeccion 2020'!E81 -> 0.19924713 | I8: ='Proyeccion 2020'!E82 -> 8.7670935
A9: ='Proyeccion 2020'!F4 -> Base con salario dueños fijo | B9: ='Proyeccion 2020'!F20 -> 1363.44 | C9: ='Proyeccion 2020'!F29 -> 81.441768 | D9: ='Proyeccion 2020'!F71 -> 0.059732565 | E9: ='Proyeccion 2020'!F73 -> 0.066994875 | F9: ='Proyeccion 2020'!F65 -> -180.62823 | G9: ='Proyeccion 2020'!F47 -> 280.30343 | H9: ='Proyeccion 2020'!F81 -> 0.23058062 | I9: ='Proyeccion 2020'!F82 -> 8.3519381
A10: ='Proyeccion 2020'!G4 -> Plan combinado (DSO 45 + DIO 450) | B10: ='Proyeccion 2020'!G20 -> 1363.44 | C10: ='Proyeccion 2020'!G29 -> 74.801046 | D10: ='Proyeccion 2020'!G71 -> 0.054862001 | E10: ='Proyeccion 2020'!G73 -> 0.061870125 | F10: ='Proyeccion 2020'!G65 -> -117.89347 | G10: ='Proyeccion 2020'!G47 -> 217.56867 | H10: ='Proyeccion 2020'!G81 -> 0.17995739 | I10: ='Proyeccion 2020'!G82 -> 9.6995015
A11: ='Proyeccion 2020'!H4 -> Plan recomendado: combinado + caja 3% con línea comprometida | B11: ='Proyeccion 2020'!H20 -> 1363.44 | C11: ='Proyeccion 2020'!H29 -> 77.606057 | D11: ='Proyeccion 2020'!H71 -> 0.056919305 | E11: ='Proyeccion 2020'!H73 -> 0.064041648 | F11: ='Proyeccion 2020'!H65 -> -115.08846 | G11: ='Proyeccion 2020'!H47 -> 146.59166 | H11: ='Proyeccion 2020'!H81 -> 0.12096957 | I11: ='Proyeccion 2020'!H82 -> 14.395823
A12: ='Proyeccion 2020'!I4 -> Riesgo: alza salario H2A (+2 pp costo) | B12: ='Proyeccion 2020'!I20 -> 1363.44 | C12: ='Proyeccion 2020'!I29 -> 53.220773 | D12: ='Proyeccion 2020'!I71 -> 0.039034188 | E12: ='Proyeccion 2020'!I73 -> 0.044820484 | F12: ='Proyeccion 2020'!I65 -> -244.43301 | G12: ='Proyeccion 2020'!I47 -> 344.10821 | H12: ='Proyeccion 2020'!I81 -> 0.28979467 | I12: ='Proyeccion 2020'!I82 -> 4.9135349
A13: ='Proyeccion 2020'!J4 -> Riesgo: ventas +15%, inventario para +30% | B13: ='Proyeccion 2020'!J20 -> 1206.12 | C13: ='Proyeccion 2020'!J29 -> 59.857043 | D13: ='Proyeccion 2020'!J71 -> 0.049627768 | E13: ='Proyeccion 2020'!J73 -> 0.050129132 | F13: ='Proyeccion 2020'!J65 -> -183.46296 | G13: ='Proyeccion 2020'!J47 -> 270.55256 | H13: ='Proyeccion 2020'!J81 -> 0.22658261 | I13: ='Proyeccion 2020'!J82 -> 6.5981777
A15: Referencias
A16: Crecimiento autosostenible (sin financiamiento externo) | B16: =Indicadores!E30 -> 0.056642445
A17: Flujo de caja libre acumulado 2017-2019 | B17: ='Flujo de caja'!F13 -> -110.7
A18: Utilidad neta acumulada 2017-2019 | B18: ='Flujo de caja'!F5 -> 138.1
A19: Costo anual de no tomar el descuento de proveedores | B19: ='Descuento proveedores'!B7 -> 0.37244898

Sheet Supuestos
A1: Nelson Nurseries - Supuestos del modelo (miles de USD)
A2: Azul = dato ingresado; negro = fórmula; verde = vínculo a otra hoja; amarillo = supuesto clave que se puede cambiar.
A4: Crecimiento de ventas 2020 | B4: 0.3 | C4: Caso p.2: Roger espera un crecimiento récord de 30% en 2020.
A5: Capex 2020 | B5: 75 | C5: Caso p.2: Christine espera capex de USD 75 mil (incluye la compra de 12 acres).
A6: Depreciación 2020 | B6: 46 | C6: Caso p.2: depreciación esperada 2020 USD 46 mil.
A7: Tasa de interés de la deuda | B7: 0.065 | C7: Caso p.2: tasa hipotecaria vigente 6,5%. Se usa como costo de la deuda nueva.
A8: Caja objetivo (% de ventas) | B8: 0.08 | C8: Caso p.2: meta operativa de Christine = 8% de las ventas.
A9: Caja mínima alternativa (% ventas, nivel 2019) | B9: =Historico!E18/Historico!E8 -> 0.008962624 | C9: Caja 2019 / ventas 2019 (0,9%): escenario sin reponer la caja.
A10: Tasa efectiva de impuestos (2019) | B10: =Historico!E14/Historico!E13 -> 0.392 | C10: Impuestos 2019 / utilidad operativa 2019.
A11: Salario anual de los dueños (en SG&A) | B11: 50 | C11: Caso p.2: los Barton retiran USD 50 mil al año como salario, registrado en SG&A.
A12: Descuento por pronto pago proveedores | B12: 0.02 | C12: Caso p.2: 2% si se paga dentro de 10 días.
A13: Días para obtener el descuento | B13: 10 | C13: Caso p.2: términos 2/10 neto 30.
A14: Plazo neto proveedores (días) | B14: 30 | C14: Caso p.2: términos 2/10 neto 30.
A16: Los escenarios de la hoja 'Proyeccion 2020' toman estos valores salvo cuando la celda del escenario está en azul con fondo amarillo (supuesto propio del escenario).

Sheet Historico
A1: Estados financieros históricos (miles de USD)
A2: Fuente: Nelson Nurseries (UVA-F-1944), Exhibit 1. Subtotales recalculados con fórmulas.
B6: 2016 | C6: 2017 | D6: 2018 | E6: 2019
A7: Estado de resultados
A8: Ventas | B8: 788.5 | C8: 807.6 | D8: 908.2 | E8: 1048.8
A9: Costo de ventas | B9: 402.9 | C9: 428.8 | D9: 437.7 | E9: 503.4
A10: Utilidad bruta | B10: =B8-B9 -> 385.6 | C10: =C8-C9 -> 378.8 | D10: =D8-D9 -> 470.5 | E10: =E8-E9 -> 545.4
A11: Gastos de venta y administración (SG&A) | B11: 301.2 | C11: 302 | D11: 356 | E11: 404.5
A12: Depreciación | B12: 34.2 | C12: 38.4 | D12: 36.3 | E12: 40.9
A13: Utilidad operativa (EBIT) | B13: =B10-B11-B12 -> 50.2 | C13: =C10-C11-C12 -> 38.4 | D13: =D10-D11-D12 -> 78.2 | E13: =E10-E11-E12 -> 100
A14: Impuestos | B14: 17.6 | C14: 13.1 | D14: 26.2 | E14: 39.2
A15: Utilidad neta | B15: =B13-B14 -> 32.6 | C15: =C13-C14 -> 25.3 | D15: =D13-D14 -> 52 | E15: =E13-E14 -> 60.8
A17: Balance general
A18: Caja | B18: 120.1 | C18: 105.2 | D18: 66.8 | E18: 9.4
A19: Cuentas por cobrar | B19: 90.6 | C19: 99.5 | D19: 119.5 | E19: 146.4
A20: Inventario | B20: 468.3 | C20: 507.6 | D20: 523.4 | E20: 656.9
A21: Otros activos corrientes | B21: 20.9 | C21: 19.3 | D21: 22.6 | E21: 20.9
A22: Activo corriente | B22: =SUM(B18:B21) -> 699.9 | C22: =SUM(C18:C21) -> 731.6 | D22: =SUM(D18:D21) -> 732.3 | E22: =SUM(E18:E21) -> 833.6
A23: Activo fijo neto | B23: 332.1 | C23: 332.5 | D23: 384.3 | E23: 347.9
A24: Activo total | B24: =B22+B23 -> 1032 | C24: =C22+C23 -> 1064.1 | D24: =D22+D23 -> 1116.6 | E24: =E22+E23 -> 1181.5
A26: Cuentas por pagar (proveedores) | B26: 6 | C26: 5.3 | D26: 4.5 | E26: 5
A27: Salarios por pagar | B27: 19.7 | C27: 22 | D27: 22.1 | E27: 24.4
A28: Otras cuentas por pagar | B28: 10.2 | C28: 15.4 | D28: 16.6 | E28: 17.9
A29: Pasivo corriente | B29: =SUM(B26:B28) -> 35.9 | C29: =SUM(C26:C28) -> 42.7 | D29: =SUM(D26:D28) -> 43.2 | E29: =SUM(E26:E28) -> 47.3
A30: Patrimonio (net worth) | B30: =B24-B29 -> 996.1 | C30: =C24-C29 -> 1021.4 | D30: =D24-D29 -> 1073.4 | E30: =E24-E29 -> 1134.2
A32: Inversión en activo fijo (capex) | B32: 22 | C32: 38.8 | D32: 88.1 | E32: 4.5
A33: Compras a proveedores | B33: 140.8 | C33: 145.2 | D33: 161.2 | E33: 185.1
A35: Verificaciones (deben ser 0)
A36: Patrimonio - (patrimonio año anterior + utilidad neta) | C36: =ROUND(C30-(B30+C15),6) -> 0 | D36: =ROUND(D30-(C30+D15),6) -> 0 | E36: =ROUND(E30-(D30+E15),6) -> 0
A37: Activo fijo - (AF anterior + capex - depreciación) | C37: =ROUND(C23-(B23+C32-C12),6) -> 0 | D37: =ROUND(D23-(C23+D32-D12),6) -> 0 | E37: =ROUND(E23-(D23+E32-E12),6) -> 0
A38: Ambas cuadran: no hubo dividendos ni aportes, y el activo fijo no tuvo ventas ni ajustes.

Sheet Indicadores
A1: Indicadores históricos vs. benchmark
A2: Calculados desde 'Historico'. Columnas H-K: valores publicados en el Exhibit 2; L-O: diferencia (solo redondeo).
H3: Publicado Exhibit 2 | L3: Diferencia calculado - publicado
B4: 2016 | C4: 2017 | D4: 2018 | E4: 2019 | F4: Benchmark | H4: 2016 | I4: 2017 | J4: 2018 | K4: 2019 | L4: 2016 | M4: 2017 | N4: 2018 | O4: 2019
A5: Crecimiento de ventas | B5: 0.029 | C5: =Historico!C8/Historico!B8-1 -> 0.024223209 | D5: =Historico!D8/Historico!C8-1 -> 0.12456662 | E5: =Historico!E8/Historico!D8-1 -> 0.15481172 | F5: -0.018 | H5: 0.029 | I5: 0.024 | J5: 0.125 | K5: 0.155 | L5: =B5-H5 -> 0 | M5: =C5-I5 -> 0.00022320862 | N5: =D5-J5 -> -0.00043338286 | O5: =E5-K5 -> -0.00018828452
A6: Margen bruto | B6: =Historico!B10/Historico!B8 -> 0.4890298 | C6: =Historico!C10/Historico!C8 -> 0.46904408 | D6: =Historico!D10/Historico!D8 -> 0.5180577 | E6: =Historico!E10/Historico!E8 -> 0.52002288 | F6: 0.489 | H6: 0.489 | I6: 0.469 | J6: 0.518 | K6: 0.52 | L6: =B6-H6 -> 2.9803424e-05 | M6: =C6-I6 -> 4.4081228e-05 | N6: =D6-J6 -> 5.7696543e-05 | O6: =E6-K6 -> 2.2883295e-05
A7: SG&A / ventas | B7: =Historico!B11/Historico!B8 -> 0.38199112 | C7: =Historico!C11/Historico!C8 -> 0.3739475 | D7: =Historico!D11/Historico!D8 -> 0.39198414 | E7: =Historico!E11/Historico!E8 -> 0.38567887
A8: Margen operativo | B8: =Historico!B13/Historico!B8 -> 0.063665187 | C8: =Historico!C13/Historico!C8 -> 0.047548291 | D8: =Historico!D13/Historico!D8 -> 0.086104382 | E8: =Historico!E13/Historico!E8 -> 0.095347063 | F8: 0.076 | H8: 0.064 | I8: 0.048 | J8: 0.086 | K8: 0.095 | L8: =B8-H8 -> -0.00033481294 | M8: =C8-I8 -> -0.00045170877 | N8: =D8-J8 -> 0.00010438229 | O8: =E8-K8 -> 0.00034706331
A9: Tasa efectiva de impuestos | B9: =Historico!B14/Historico!B13 -> 0.35059761 | C9: =Historico!C14/Historico!C13 -> 0.34114583 | D9: =Historico!D14/Historico!D13 -> 0.33503836 | E9: =Historico!E14/Historico!E13 -> 0.392
A10: Margen neto | B10: =Historico!B15/Historico!B8 -> 0.041344325 | C10: =Historico!C15/Historico!C8 -> 0.03132739 | D10: =Historico!D15/Historico!D8 -> 0.057256111 | E10: =Historico!E15/Historico!E8 -> 0.057971014 | F10: 0.028 | H10: 0.041 | I10: 0.031 | J10: 0.057 | K10: 0.058 | L10: =B10-H10 -> 0.00034432467 | M10: =C10-I10 -> 0.0003273898 | N10: =D10-J10 -> 0.00025611099 | O10: =E10-K10 -> -2.8985507e-05
A11: ROA (utilidad neta / activo total) | B11: =Historico!B15/Historico!B24 -> 0.031589147 | C11: =Historico!C15/Historico!C24 -> 0.023775961 | D11: =Historico!D15/Historico!D24 -> 0.046569944 | E11: =Historico!E15/Historico!E24 -> 0.051460008 | F11: 0.029 | H11: 0.032 | I11: 0.024 | J11: 0.047 | K11: 0.051 | L11: =B11-H11 -> -0.00041085271 | M11: =C11-I11 -> -0.00022403909 | N11: =D11-J11 -> -0.00043005553 | O11: =E11-K11 -> 0.00046000846
A12: ROE (utilidad neta / patrimonio) | B12: =Historico!B15/Historico!B30 -> 0.032727638 | C12: =Historico!C15/Historico!C30 -> 0.024769924 | D12: =Historico!D15/Historico!D30 -> 0.048444196 | E12: =Historico!E15/Historico!E30 -> 0.053606066 | F12: 0.04 | H12: 0.033 | I12: 0.025 | J12: 0.048 | K12: 0.054 | L12: =B12-H12 -> -0.00027236221 | M12: =C12-I12 -> -0.00023007637 | N12: =D12-J12 -> 0.00044419601 | O12: =E12-K12 -> -0.00039393405
A13: Días de cartera (DSO) | B13: =Historico!B19/Historico!B8*365 -> 41.939125 | C13: =Historico!C19/Historico!C8*365 -> 44.969663 | D13: =Historico!D19/Historico!D8*365 -> 48.026316 | E13: =Historico!E19/Historico!E8*365 -> 50.949657 | F13: 21.8 | H13: 41.9 | I13: 45 | J13: 48 | K13: 50.9 | L13: =B13-H13 -> 0.039124921 | M13: =C13-I13 -> -0.0303368 | N13: =D13-J13 -> 0.026315789 | O13: =E13-K13 -> 0.049656751
A14: Días de inventario (DIO) | B14: =Historico!B20/Historico!B9*365 -> 424.24795 | C14: =Historico!C20/Historico!C9*365 -> 432.07556 | D14: =Historico!D20/Historico!D9*365 -> 436.46562 | E14: =Historico!E20/Historico!E9*365 -> 476.29817 | F14: 386.3 | H14: 424.2 | I14: 432.1 | J14: 436.5 | K14: 476.3 | L14: =B14-H14 -> 0.047952345 | M14: =C14-I14 -> -0.024440299 | N14: =D14-J14 -> -0.034384281 | O14: =E14-K14 -> -0.0018275725
A15: Días de proveedores (DPO, sobre compras) | B15: =Historico!B26/Historico!B33*365 -> 15.553977 | C15: =Historico!C26/Historico!C33*365 -> 13.323003 | D15: =Historico!D26/Historico!D33*365 -> 10.189206 | E15: =Historico!E26/Historico!E33*365 -> 9.8595354 | F15: 26.9 | H15: 15.6 | I15: 13.3 | J15: 10.2 | K15: 9.9 | L15: =B15-H15 -> -0.046022727 | M15: =C15-I15 -> 0.023002755 | N15: =D15-J15 -> -0.010794045 | O15: =E15-K15 -> -0.040464614
A16: Ciclo de conversión de caja (DSO+DIO-DPO) | B16: =B13+B14-B15 -> 450.6331 | C16: =C13+C14-C15 -> 463.72222 | D16: =D13+D14-D15 -> 474.30273 | E16: =E13+E14-E15 -> 517.38829 | F16: =F13+F14-F15 -> 381.2
A17: Rotación de activo fijo (ventas / AF neto) | B17: =Historico!B8/Historico!B23 -> 2.3742849 | C17: =Historico!C8/Historico!C23 -> 2.4288722 | D17: =Historico!D8/Historico!D23 -> 2.3632579 | E17: =Historico!E8/Historico!E23 -> 3.0146594 | F17: 2.7 | H17: 2.4 | I17: 2.4 | J17: 2.4 | K17: 3 | L17: =B17-H17 -> -0.025715146 | M17: =C17-I17 -> 0.02887218 | N17: =D17-J17 -> -0.036742129 | O17: =E17-K17 -> 0.014659385
A18: Rotación de activo total (ventas / activo total) | B18: =Historico!B8/Historico!B24 -> 0.76405039 | C18: =Historico!C8/Historico!C24 -> 0.75895123 | D18: =Historico!D8/Historico!D24 -> 0.81336199 | E18: =Historico!E8/Historico!E24 -> 0.88768515
A19: Caja / ventas (meta 8%) | B19: =Historico!B18/Historico!B8 -> 0.15231452 | C19: =Historico!C18/Historico!C8 -> 0.13026251 | D19: =Historico!D18/Historico!D8 -> 0.073552081 | E19: =Historico!E18/Historico!E8 -> 0.008962624
A20: Razón corriente | B20: =Historico!B22/Historico!B29 -> 19.495822 | C20: =Historico!C22/Historico!C29 -> 17.133489 | D20: =Historico!D22/Historico!D29 -> 16.951389 | E20: =Historico!E22/Historico!E29 -> 17.623679
A21: Prueba ácida ((caja + CxC) / pasivo corriente) | B21: =(Historico!B18+Historico!B19)/Historico!B29 -> 5.8690808 | C21: =(Historico!C18+Historico!C19)/Historico!C29 -> 4.793911 | D21: =(Historico!D18+Historico!D19)/Historico!D29 -> 4.3125 | E21: =(Historico!E18+Historico!E19)/Historico!E29 -> 3.2938689
A22: Capital de trabajo operativo (CxC+Inv+OAC-PC) | B22: =Historico!B19+Historico!B20+Historico!B21-Historico!B29 -> 543.9 | C22: =Historico!C19+Historico!C20+Historico!C21-Historico!C29 -> 583.7 | D22: =Historico!D19+Historico!D20+Historico!D21-Historico!D29 -> 622.3 | E22: =Historico!E19+Historico!E20+Historico!E21-Historico!E29 -> 776.9
A23: Capital de trabajo operativo / ventas | B23: =B22/Historico!B8 -> 0.68979074 | C23: =C22/Historico!C8 -> 0.72275879 | D23: =D22/Historico!D8 -> 0.6852015 | E23: =E22/Historico!E8 -> 0.74075133
A26: Crecimiento autosostenible 2020 (sin deuda ni aportes, ratios 2019)
A27: Activo total / ventas 2019 | E27: =Historico!E24/Historico!E8 -> 1.1265256
A28: Pasivo espontáneo / ventas 2019 | E28: =Historico!E29/Historico!E8 -> 0.045099161
A29: Margen neto 2019 | E29: =E10 -> 0.057971014
A30: Crecimiento autosostenible = m / (A/V - P/V - m) | E30: =E29/(E27-E28-E29) -> 0.056642445
A31: Comprobación: ROE sobre patrimonio inicial 2019 (sin dividendos) | E31: =Historico!E15/Historico!D30 -> 0.056642445

Sheet Flujo de caja
A1: Flujo de caja histórico, método indirecto (miles de USD)
A2: Explica por qué la caja cayó de 120,1 a 9,4 pese a utilidades crecientes.
C4: 2017 | D4: 2018 | E4: 2019 | F4: Total 17-19
A5: Utilidad neta | C5: =Historico!C15 -> 25.3 | D5: =Historico!D15 -> 52 | E5: =Historico!E15 -> 60.8 | F5: =SUM(C5:E5) -> 138.1
A6: + Depreciación | C6: =Historico!C12 -> 38.4 | D6: =Historico!D12 -> 36.3 | E6: =Historico!E12 -> 40.9 | F6: =SUM(C6:E6) -> 115.6
A7: - Aumento cuentas por cobrar | C7: =-(Historico!C19-Historico!B19) -> -8.9 | D7: =-(Historico!D19-Historico!C19) -> -20 | E7: =-(Historico!E19-Historico!D19) -> -26.9 | F7: =SUM(C7:E7) -> -55.8
A8: - Aumento inventario | C8: =-(Historico!C20-Historico!B20) -> -39.3 | D8: =-(Historico!D20-Historico!C20) -> -15.8 | E8: =-(Historico!E20-Historico!D20) -> -133.5 | F8: =SUM(C8:E8) -> -188.6
A9: - Aumento otros activos corrientes | C9: =-(Historico!C21-Historico!B21) -> 1.6 | D9: =-(Historico!D21-Historico!C21) -> -3.3 | E9: =-(Historico!E21-Historico!D21) -> 1.7 | F9: =SUM(C9:E9) -> 0
A10: + Aumento pasivo corriente | C10: =Historico!C29-Historico!B29 -> 6.8 | D10: =Historico!D29-Historico!C29 -> 0.5 | E10: =Historico!E29-Historico!D29 -> 4.1 | F10: =SUM(C10:E10) -> 11.4
A11: Flujo de caja operativo | C11: =SUM(C5:C10) -> 23.9 | D11: =SUM(D5:D10) -> 49.7 | E11: =SUM(E5:E10) -> -52.9 | F11: =SUM(C11:E11) -> 20.7
A12: - Capex | C12: =-Historico!C32 -> -38.8 | D12: =-Historico!D32 -> -88.1 | E12: =-Historico!E32 -> -4.5 | F12: =SUM(C12:E12) -> -131.4
A13: Flujo de caja libre | C13: =C11+C12 -> -14.9 | D13: =D11+D12 -> -38.4 | E13: =E11+E12 -> -57.4 | F13: =SUM(C13:E13) -> -110.7
A14: Variación de caja según balance | C14: =Historico!C18-Historico!B18 -> -14.9 | D14: =Historico!D18-Historico!C18 -> -38.4 | E14: =Historico!E18-Historico!D18 -> -57.4 | F14: =SUM(C14:E14) -> -110.7
A15: Diferencia (debe ser 0) | C15: =ROUND(C13-C14,6) -> 0 | D15: =ROUND(D13-D14,6) -> 0 | E15: =ROUND(E13-E14,6) -> 0 | F15: =SUM(C15:E15) -> 0
A17: Uso del flujo operativo antes de cambios en capital de trabajo (utilidad + depreciación)
A18: Utilidad + depreciación (2017-2019) | F18: =F5+F6 -> 253.7
A19: Absorbido por inventario | F19: =-F8 -> 188.6
A20: Absorbido por cuentas por cobrar | F20: =-F7 -> 55.8
A21: Inventario + cartera como % de utilidad + depreciación | F21: =(F19+F20)/F18 -> 0.96334253

Sheet Proyeccion 2020
A1: Proyección 2020 por escenario (miles de USD)
A2: Base = se mantienen los ratios de 2019 y se crece 30%. La deuda paga 6,5% sobre el saldo de cierre; se resuelve en forma cerrada (fila 57) para evitar referencias circulares.
A3: Supuestos de cada escenario (azul con fondo amarillo = distinto de la base)
B4: Base: ratios 2019 | C4: Base sin reponer caja (0,9%) | D4: Medida: cobranza DSO 45 | E4: Medida: inventario DIO 450 | F4: Base con salario dueños fijo | G4: Plan combinado (DSO 45 + DIO 450) | H4: Plan recomendado: combinado + caja 3% con línea comprometida | I4: Riesgo: alza salario H2A (+2 pp costo) | J4: Riesgo: ventas +15%, inventario para +30%
A5: Supuestos
A6: Crecimiento de ventas | B6: =Supuestos!$B$4 -> 0.3 | C6: =Supuestos!$B$4 -> 0.3 | D6: =Supuestos!$B$4 -> 0.3 | E6: =Supuestos!$B$4 -> 0.3 | F6: =Supuestos!$B$4 -> 0.3 | G6: =Supuestos!$B$4 -> 0.3 | H6: =Supuestos!$B$4 -> 0.3 | I6: =Supuestos!$B$4 -> 0.3 | J6: 0.15
A7: Crecimiento para el que se arma inventario y compras | B7: =B6 -> 0.3 | C7: =C6 -> 0.3 | D7: =D6 -> 0.3 | E7: =E6 -> 0.3 | F7: =F6 -> 0.3 | G7: =G6 -> 0.3 | H7: =H6 -> 0.3 | I7: =I6 -> 0.3 | J7: 0.3
A8: Días de cartera (DSO) | B8: =Historico!$E$19/Historico!$E$8*365 -> 50.949657 | C8: =Historico!$E$19/Historico!$E$8*365 -> 50.949657 | D8: 45 | E8: =Historico!$E$19/Historico!$E$8*365 -> 50.949657 | F8: =Historico!$E$19/Historico!$E$8*365 -> 50.949657 | G8: 45 | H8: 45 | I8: =Historico!$E$19/Historico!$E$8*365 -> 50.949657 | J8: =Historico!$E$19/Historico!$E$8*365 -> 50.949657
A9: Días de inventario (DIO, sobre costo de ventas) | B9: =Historico!$E$20/Historico!$E$9*365 -> 476.29817 | C9: =Historico!$E$20/Historico!$E$9*365 -> 476.29817 | D9: =Historico!$E$20/Historico!$E$9*365 -> 476.29817 | E9: 450 | F9: =Historico!$E$20/Historico!$E$9*365 -> 476.29817 | G9: 450 | H9: 450 | I9: =Historico!$E$20/Historico!$E$9*365 -> 476.29817 | J9: =Historico!$E$20/Historico!$E$9*365 -> 476.29817
A10: Días de proveedores (DPO, sobre compras) | B10: =Historico!$E$26/Historico!$E$33*365 -> 9.8595354 | C10: =Historico!$E$26/Historico!$E$33*365 -> 9.8595354 | D10: =Historico!$E$26/Historico!$E$33*365 -> 9.8595354 | E10: =Historico!$E$26/Historico!$E$33*365 -> 9.8595354 | F10: =Historico!$E$26/Historico!$E$33*365 -> 9.8595354 | G10: =Historico!$E$26/Historico!$E$33*365 -> 9.8595354 | H10: =Historico!$E$26/Historico!$E$33*365 -> 9.8595354 | I10: =Historico!$E$26/Historico!$E$33*365 -> 9.8595354 | J10: =Historico!$E$26/Historico!$E$33*365 -> 9.8595354
A11: Cambio en costo de ventas / ventas (pp) | B11: 0 | C11: 0 | D11: 0 | E11: 0 | F11: 0 | G11: 0 | H11: 0 | I11: 0.02 | J11: 0
A12: Parte fija del SG&A | B12: 0 | C12: 0 | D12: 0 | E12: 0 | F12: =Supuestos!$B$11 -> 50 | G12: 0 | H12: 0 | I12: 0 | J12: 0
A13: Caja objetivo (% ventas) | B13: =Supuestos!$B$8 -> 0.08 | C13: =Supuestos!$B$9 -> 0.008962624 | D13: =Supuestos!$B$8 -> 0.08 | E13: =Supuestos!$B$8 -> 0.08 | F13: =Supuestos!$B$8 -> 0.08 | G13: =Supuestos!$B$8 -> 0.08 | H13: 0.03 | I13: =Supuestos!$B$8 -> 0.08 | J13: =Supuestos!$B$8 -> 0.08
A14: Capex | B14: =Supuestos!$B$5 -> 75 | C14: =Supuestos!$B$5 -> 75 | D14: =Supuestos!$B$5 -> 75 | E14: =Supuestos!$B$5 -> 75 | F14: =Supuestos!$B$5 -> 75 | G14: =Supuestos!$B$5 -> 75 | H14: =Supuestos!$B$5 -> 75 | I14: =Supuestos!$B$5 -> 75 | J14: =Supuestos!$B$5 -> 75
A15: Depreciación | B15: =Supuestos!$B$6 -> 46 | C15: =Supuestos!$B$6 -> 46 | D15: =Supuestos!$B$6 -> 46 | E15: =Supuestos!$B$6 -> 46 | F15: =Supuestos!$B$6 -> 46 | G15: =Supuestos!$B$6 -> 46 | H15: =Supuestos!$B$6 -> 46 | I15: =Supuestos!$B$6 -> 46 | J15: =Supuestos!$B$6 -> 46
A16: Tasa de interés deuda nueva | B16: =Supuestos!$B$7 -> 0.065 | C16: =Supuestos!$B$7 -> 0.065 | D16: =Supuestos!$B$7 -> 0.065 | E16: =Supuestos!$B$7 -> 0.065 | F16: =Supuestos!$B$7 -> 0.065 | G16: =Supuestos!$B$7 -> 0.065 | H16: =Supuestos!$B$7 -> 0.065 | I16: =Supuestos!$B$7 -> 0.065 | J16: =Supuestos!$B$7 -> 0.065
A17: Tasa de impuestos | B17: =Supuestos!$B$10 -> 0.392 | C17: =Supuestos!$B$10 -> 0.392 | D17: =Supuestos!$B$10 -> 0.392 | E17: =Supuestos!$B$10 -> 0.392 | F17: =Supuestos!$B$10 -> 0.392 | G17: =Supuestos!$B$10 -> 0.392 | H17: =Supuestos!$B$10 -> 0.392 | I17: =Supuestos!$B$10 -> 0.392 | J17: =Supuestos!$B$10 -> 0.392
A19: Estado de resultados 2020
A20: Ventas | B20: =Historico!$E$8*(1+B6) -> 1363.44 | C20: =Historico!$E$8*(1+C6) -> 1363.44 | D20: =Historico!$E$8*(1+D6) -> 1363.44 | E20: =Historico!$E$8*(1+E6) -> 1363.44 | F20: =Historico!$E$8*(1+F6) -> 1363.44 | G20: =Historico!$E$8*(1+G6) -> 1363.44 | H20: =Historico!$E$8*(1+H6) -> 1363.44 | I20: =Historico!$E$8*(1+I6) -> 1363.44 | J20: =Historico!$E$8*(1+J6) -> 1206.12
A21: Costo de ventas | B21: =B20*(Historico!$E$9/Historico!$E$8+B11) -> 654.42 | C21: =C20*(Historico!$E$9/Historico!$E$8+C11) -> 654.42 | D21: =D20*(Historico!$E$9/Historico!$E$8+D11) -> 654.42 | E21: =E20*(Historico!$E$9/Historico!$E$8+E11) -> 654.42 | F21: =F20*(Historico!$E$9/Historico!$E$8+F11) -> 654.42 | G21: =G20*(Historico!$E$9/Historico!$E$8+G11) -> 654.42 | H21: =H20*(Historico!$E$9/Historico!$E$8+H11) -> 654.42 | I21: =I20*(Historico!$E$9/Historico!$E$8+I11) -> 681.6888 | J21: =J20*(Historico!$E$9/Historico!$E$8+J11) -> 578.91
A22: Utilidad bruta | B22: =B20-B21 -> 709.02 | C22: =C20-C21 -> 709.02 | D22: =D20-D21 -> 709.02 | E22: =E20-E21 -> 709.02 | F22: =F20-F21 -> 709.02 | G22: =G20-G21 -> 709.02 | H22: =H20-H21 -> 709.02 | I22: =I20-I21 -> 681.7512 | J22: =J20-J21 -> 627.21
A23: SG&A | B23: =B12+B20*(Historico!$E$11-B12)/Historico!$E$8 -> 525.85 | C23: =C12+C20*(Historico!$E$11-C12)/Historico!$E$8 -> 525.85 | D23: =D12+D20*(Historico!$E$11-D12)/Historico!$E$8 -> 525.85 | E23: =E12+E20*(Historico!$E$11-E12)/Historico!$E$8 -> 525.85 | F23: =F12+F20*(Historico!$E$11-F12)/Historico!$E$8 -> 510.85 | G23: =G12+G20*(Historico!$E$11-G12)/Historico!$E$8 -> 525.85 | H23: =H12+H20*(Historico!$E$11-H12)/Historico!$E$8 -> 525.85 | I23: =I12+I20*(Historico!$E$11-I12)/Historico!$E$8 -> 525.85 | J23: =J12+J20*(Historico!$E$11-J12)/Historico!$E$8 -> 465.175
A24: Depreciación | B24: =B15 -> 46 | C24: =C15 -> 46 | D24: =D15 -> 46 | E24: =E15 -> 46 | F24: =F15 -> 46 | G24: =G15 -> 46 | H24: =H15 -> 46 | I24: =I15 -> 46 | J24: =J15 -> 46
A25: Utilidad operativa (EBIT) | B25: =B22-B23-B24 -> 137.17 | C25: =C22-C23-C24 -> 137.17 | D25: =D22-D23-D24 -> 137.17 | E25: =E22-E23-E24 -> 137.17 | F25: =F22-F23-F24 -> 152.17 | G25: =G22-G23-G24 -> 137.17 | H25: =H22-H23-H24 -> 137.17 | I25: =I22-I23-I24 -> 109.9012 | J25: =J22-J23-J24 -> 116.035
A26: Intereses | B26: =B47*B16 -> 18.836914 | C26: =C47*C16 -> 12.282288 | D26: =D47*D16 -> 17.332872 | E26: =E47*E16 -> 15.646006 | F26: =F47*F16 -> 18.219723 | G26: =G47*G16 -> 14.141964 | H26: =H47*H16 -> 9.5284581 | I26: =I47*I16 -> 22.367033 | J26: =J47*J16 -> 17.585916
A27: Utilidad antes de impuestos | B27: =B25-B26 -> 118.33309 | C27: =C25-C26 -> 124.88771 | D27: =D25-D26 -> 119.83713 | E27: =E25-E26 -> 121.52399 | F27: =F25-F26 -> 133.95028 | G27: =G25-G26 -> 123.02804 | H27: =H25-H26 -> 127.64154 | I27: =I25-I26 -> 87.534167 | J27: =J25-J26 -> 98.449084
A28: Impuestos | B28: =B27*B17 -> 46.38657 | C28: =C27*C17 -> 48.955983 | D28: =D27*D17 -> 46.976154 | E28: =E27*E17 -> 47.637406 | F28: =F27*F17 -> 52.508509 | G28: =G27*G17 -> 48.22699 | H28: =H27*H17 -> 50.035484 | I28: =I27*I17 -> 34.313393 | J28: =J27*J17 -> 38.592041
A29: Utilidad neta | B29: =B27-B28 -> 71.946516 | C29: =C27-C28 -> 75.931729 | D29: =D27-D28 -> 72.860974 | E29: =E27-E28 -> 73.886588 | F29: =F27-F28 -> 81.441768 | G29: =G27-G28 -> 74.801046 | H29: =H27-H28 -> 77.606057 | I29: =I27-I28 -> 53.220773 | J29: =J27-J28 -> 59.857043
A31: Balance 2020
A32: Caja objetivo | B32: =B13*B20 -> 109.0752 | C32: =C13*C20 -> 12.22 | D32: =D13*D20 -> 109.0752 | E32: =E13*E20 -> 109.0752 | F32: =F13*F20 -> 109.0752 | G32: =G13*G20 -> 109.0752 | H32: =H13*H20 -> 40.9032 | I32: =I13*I20 -> 109.0752 | J32: =J13*J20 -> 96.4896
A33: Excedente de caja | B33: =MAX(-B57,0) -> 0 | C33: =MAX(-C57,0) -> 0 | D33: =MAX(-D57,0) -> 0 | E33: =MAX(-E57,0) -> 0 | F33: =MAX(-F57,0) -> 0 | G33: =MAX(-G57,0) -> 0 | H33: =MAX(-H57,0) -> 0 | I33: =MAX(-I57,0) -> 0 | J33: =MAX(-J57,0) -> 0
A34: Caja total | B34: =B32+B33 -> 109.0752 | C34: =C32+C33 -> 12.22 | D34: =D32+D33 -> 109.0752 | E34: =E32+E33 -> 109.0752 | F34: =F32+F33 -> 109.0752 | G34: =G32+G33 -> 109.0752 | H34: =H32+H33 -> 40.9032 | I34: =I32+I33 -> 109.0752 | J34: =J32+J33 -> 96.4896
A35: Cuentas por cobrar | B35: =B20*B8/365 -> 190.32 | C35: =C20*C8/365 -> 190.32 | D35: =D20*D8/365 -> 168.09534 | E35: =E20*E8/365 -> 190.32 | F35: =F20*F8/365 -> 190.32 | G35: =G20*G8/365 -> 168.09534 | H35: =H20*H8/365 -> 168.09534 | I35: =I20*I8/365 -> 190.32 | J35: =J20*J8/365 -> 168.36
A36: Inventario | B36: =Historico!$E$8*(1+B7)*(Historico!$E$9/Historico!$E$8+B11)*B9/365 -> 853.97 | C36: =Historico!$E$8*(1+C7)*(Historico!$E$9/Historico!$E$8+C11)*C9/365 -> 853.97 | D36: =Historico!$E$8*(1+D7)*(Historico!$E$9/Historico!$E$8+D11)*D9/365 -> 853.97 | E36: =Historico!$E$8*(1+E7)*(Historico!$E$9/Historico!$E$8+E11)*E9/365 -> 806.81918 | F36: =Historico!$E$8*(1+F7)*(Historico!$E$9/Historico!$E$8+F11)*F9/365 -> 853.97 | G36: =Historico!$E$8*(1+G7)*(Historico!$E$9/Historico!$E$8+G11)*G9/365 -> 806.81918 | H36: =Historico!$E$8*(1+H7)*(Historico!$E$9/Historico!$E$8+H11)*H9/365 -> 806.81918 | I36: =Historico!$E$8*(1+I7)*(Historico!$E$9/Historico!$E$8+I11)*I9/365 -> 889.55378 | J36: =Historico!$E$8*(1+J7)*(Historico!$E$9/Historico!$E$8+J11)*J9/365 -> 853.97
A37: Otros activos corrientes | B37: =B20*Historico!$E$21/Historico!$E$8 -> 27.17 | C37: =C20*Historico!$E$21/Historico!$E$8 -> 27.17 | D37: =D20*Historico!$E$21/Historico!$E$8 -> 27.17 | E37: =E20*Historico!$E$21/Historico!$E$8 -> 27.17 | F37: =F20*Historico!$E$21/Historico!$E$8 -> 27.17 | G37: =G20*Historico!$E$21/Historico!$E$8 -> 27.17 | H37: =H20*Historico!$E$21/Historico!$E$8 -> 27.17 | I37: =I20*Historico!$E$21/Historico!$E$8 -> 27.17 | J37: =J20*Historico!$E$21/Historico!$E$8 -> 24.035
A38: Activo corriente | B38: =SUM(B34:B37) -> 1180.5352 | C38: =SUM(C34:C37) -> 1083.68 | D38: =SUM(D34:D37) -> 1158.3105 | E38: =SUM(E34:E37) -> 1133.3844 | F38: =SUM(F34:F37) -> 1180.5352 | G38: =SUM(G34:G37) -> 1111.1597 | H38: =SUM(H34:H37) -> 1042.9877 | I38: =SUM(I34:I37) -> 1216.119 | J38: =SUM(J34:J37) -> 1142.8546
A39: Activo fijo neto | B39: =Historico!$E$23+B14-B15 -> 376.9 | C39: =Historico!$E$23+C14-C15 -> 376.9 | D39: =Historico!$E$23+D14-D15 -> 376.9 | E39: =Historico!$E$23+E14-E15 -> 376.9 | F39: =Historico!$E$23+F14-F15 -> 376.9 | G39: =Historico!$E$23+G14-G15 -> 376.9 | H39: =Historico!$E$23+H14-H15 -> 376.9 | I39: =Historico!$E$23+I14-I15 -> 376.9 | J39: =Historico!$E$23+J14-J15 -> 376.9
A40: Activo total | B40: =B38+B39 -> 1557.4352 | C40: =C38+C39 -> 1460.58 | D40: =D38+D39 -> 1535.2105 | E40: =E38+E39 -> 1510.2844 | F40: =F38+F39 -> 1557.4352 | G40: =G38+G39 -> 1488.0597 | H40: =H38+H39 -> 1419.8877 | I40: =I38+I39 -> 1593.019 | J40: =J38+J39 -> 1519.7546
A42: Compras a proveedores | B42: =Historico!$E$33*(1+B7) -> 240.63 | C42: =Historico!$E$33*(1+C7) -> 240.63 | D42: =Historico!$E$33*(1+D7) -> 240.63 | E42: =Historico!$E$33*(1+E7) -> 240.63 | F42: =Historico!$E$33*(1+F7) -> 240.63 | G42: =Historico!$E$33*(1+G7) -> 240.63 | H42: =Historico!$E$33*(1+H7) -> 240.63 | I42: =Historico!$E$33*(1+I7) -> 240.63 | J42: =Historico!$E$33*(1+J7) -> 240.63
A43: Cuentas por pagar | B43: =B42*B10/365 -> 6.5 | C43: =C42*C10/365 -> 6.5 | D43: =D42*D10/365 -> 6.5 | E43: =E42*E10/365 -> 6.5 | F43: =F42*F10/365 -> 6.5 | G43: =G42*G10/365 -> 6.5 | H43: =H42*H10/365 -> 6.5 | I43: =I42*I10/365 -> 6.5 | J43: =J42*J10/365 -> 6.5
...

Sheet Sensibilidad
A1: Sensibilidad de la necesidad de financiamiento al crecimiento (miles de USD)
A2: Ratios de 2019. Columnas B-I: reponiendo la caja a 8% de ventas; J-Q: manteniendo la caja en 0,9% de ventas.
A3: Supuestos de cada escenario (azul con fondo amarillo = distinto de la base)
B4: Crec. 0% caja 8% | C4: Crec. 5% caja 8% | D4: Crec. 10% caja 8% | E4: Crec. 15% caja 8% | F4: Crec. 20% caja 8% | G4: Crec. 25% caja 8% | H4: Crec. 30% caja 8% | I4: Crec. 35% caja 8% | J4: Crec. 0% caja 0,9% | K4: Crec. 5% caja 0,9% | L4: Crec. 10% caja 0,9% | M4: Crec. 15% caja 0,9% | N4: Crec. 20% caja 0,9% | O4: Crec. 25% caja 0,9% | P4: Crec. 30% caja 0,9% | Q4: Crec. 35% caja 0,9%
A5: Supuestos
A6: Crecimiento de ventas | B6: 0 | C6: 0.05 | D6: 0.1 | E6: 0.15 | F6: 0.2 | G6: 0.25 | H6: 0.3 | I6: 0.35 | J6: 0 | K6: 0.05 | L6: 0.1 | M6: 0.15 | N6: 0.2 | O6: 0.25 | P6: 0.3 | Q6: 0.35
A7: Crecimiento para el que se arma inventario y compras | B7: =B6 -> 0 | C7: =C6 -> 0.05 | D7: =D6 -> 0.1 | E7: =E6 -> 0.15 | F7: =F6 -> 0.2 | G7: =G6 -> 0.25 | H7: =H6 -> 0.3 | I7: =I6 -> 0.35 | ... Q7: =Q6 -> 0.35
A8: Días de cartera (DSO) | B8: =Historico!$E$19/Historico!$E$8*365 -> 50.949657 | C8: =Historico!$E$19/Historico!$E$8*365 -> 50.949657 | D8: =Historico!$E$19/Historico!$E$8*365 -> 50.949657 | E8: =Historico!$E$19/Historico!$E$8*365 -> 50.949657 | F8: =Historico!$E$19/Historico!$E$8*365 -> 50.949657 | G8: =Historico!$E$19/Historico!$E$8*365 -> 50.949657 | H8: =Historico!$E$19/Historico!$E$8*365 -> 50.949657 | I8: =Historico!$E$19/Historico!$E$8*365 -> 50.949657 | ... Q8: =Historico!$E$19/Historico!$E$8*365 -> 50.949657
A9: Días de inventario (DIO, sobre costo de ventas) | B9: =Historico!$E$20/Historico!$E$9*365 -> 476.29817 | C9: =Historico!$E$20/Historico!$E$9*365 -> 476.29817 | D9: =Historico!$E$20/Historico!$E$9*365 -> 476.29817 | E9: =Historico!$E$20/Historico!$E$9*365 -> 476.29817 | F9: =Historico!$E$20/Historico!$E$9*365 -> 476.29817 | G9: =Historico!$E$20/Historico!$E$9*365 -> 476.29817 | H9: =Historico!$E$20/Historico!$E$9*365 -> 476.29817 | I9: =Historico!$E$20/Historico!$E$9*365 -> 476.29817 | ... Q9: =Historico!$E$20/Historico!$E$9*365 -> 476.29817
A10: Días de proveedores (DPO, sobre compras) | B10: =Historico!$E$26/Historico!$E$33*365 -> 9.8595354 | C10: =Historico!$E$26/Historico!$E$33*365 -> 9.8595354 | D10: =Historico!$E$26/Historico!$E$33*365 -> 9.8595354 | E10: =Historico!$E$26/Historico!$E$33*365 -> 9.8595354 | F10: =Historico!$E$26/Historico!$E$33*365 -> 9.8595354 | G10: =Historico!$E$26/Historico!$E$33*365 -> 9.8595354 | H10: =Historico!$E$26/Historico!$E$33*365 -> 9.8595354 | I10: =Historico!$E$26/Historico!$E$33*365 -> 9.8595354 | ... Q10: =Historico!$E$26/Historico!$E$33*365 -> 9.8595354
A11: Cambio en costo de ventas / ventas (pp) | B11: 0 | C11: 0 | D11: 0 | E11: 0 | F11: 0 | G11: 0 | H11: 0 | I11: 0 | J11: 0 | K11: 0 | L11: 0 | M11: 0 | N11: 0 | O11: 0 | P11: 0 | Q11: 0
A12: Parte fija del SG&A | B12: 0 | C12: 0 | D12: 0 | E12: 0 | F12: 0 | G12: 0 | H12: 0 | I12: 0 | J12: 0 | K12: 0 | L12: 0 | M12: 0 | N12: 0 | O12: 0 | P12: 0 | Q12: 0
A13: Caja objetivo (% ventas) | B13: =Supuestos!$B$8 -> 0.08 | C13: =Supuestos!$B$8 -> 0.08 | D13: =Supuestos!$B$8 -> 0.08 | E13: =Supuestos!$B$8 -> 0.08 | F13: =Supuestos!$B$8 -> 0.08 | G13: =Supuestos!$B$8 -> 0.08 | H13: =Supuestos!$B$8 -> 0.08 | I13: =Supuestos!$B$8 -> 0.08 | J13: =Supuestos!$B$9 -> 0.008962624 | K13: =Supuestos!$B$9 -> 0.008962624 | L13: =Supuestos!$B$9 -> 0.008962624 | M13: =Supuestos!$B$9 -> 0.008962624 | N13: =Supuestos!$B$9 -> 0.008962624 | O13: =Supuestos!$B$9 -> 0.008962624 | P13: =Supuestos!$B$9 -> 0.008962624 | Q13: =Supuestos!$B$9 -> 0.008962624
A14: Capex | B14: =Supuestos!$B$5 -> 75 | C14: =Supuestos!$B$5 -> 75 | D14: =Supuestos!$B$5 -> 75 | E14: =Supuestos!$B$5 -> 75 | F14: =Supuestos!$B$5 -> 75 | G14: =Supuestos!$B$5 -> 75 | H14: =Supuestos!$B$5 -> 75 | I14: =Supuestos!$B$5 -> 75 | ... Q14: =Supuestos!$B$5 -> 75
A15: Depreciación | B15: =Supuestos!$B$6 -> 46 | C15: =Supuestos!$B$6 -> 46 | D15: =Supuestos!$B$6 -> 46 | E15: =Supuestos!$B$6 -> 46 | F15: =Supuestos!$B$6 -> 46 | G15: =Supuestos!$B$6 -> 46 | H15: =Supuestos!$B$6 -> 46 | I15: =Supuestos!$B$6 -> 46 | ... Q15: =Supuestos!$B$6 -> 46
A16: Tasa de interés deuda nueva | B16: =Supuestos!$B$7 -> 0.065 | C16: =Supuestos!$B$7 -> 0.065 | D16: =Supuestos!$B$7 -> 0.065 | E16: =Supuestos!$B$7 -> 0.065 | F16: =Supuestos!$B$7 -> 0.065 | G16: =Supuestos!$B$7 -> 0.065 | H16: =Supuestos!$B$7 -> 0.065 | I16: =Supuestos!$B$7 -> 0.065 | ... Q16: =Supuestos!$B$7 -> 0.065
A17: Tasa de impuestos | B17: =Supuestos!$B$10 -> 0.392 | C17: =Supuestos!$B$10 -> 0.392 | D17: =Supuestos!$B$10 -> 0.392 | E17: =Supuestos!$B$10 -> 0.392 | F17: =Supuestos!$B$10 -> 0.392 | G17: =Supuestos!$B$10 -> 0.392 | H17: =Supuestos!$B$10 -> 0.392 | I17: =Supuestos!$B$10 -> 0.392 | ... Q17: =Supuestos!$B$10 -> 0.392
A19: Estado de resultados 2020
A20: Ventas | B20: =Historico!$E$8*(1+B6) -> 1048.8 | C20: =Historico!$E$8*(1+C6) -> 1101.24 | D20: =Historico!$E$8*(1+D6) -> 1153.68 | E20: =Historico!$E$8*(1+E6) -> 1206.12 | F20: =Historico!$E$8*(1+F6) -> 1258.56 | G20: =Historico!$E$8*(1+G6) -> 1311 | H20: =Historico!$E$8*(1+H6) -> 1363.44 | I20: =Historico!$E$8*(1+I6) -> 1415.88 | ... Q20: =Historico!$E$8*(1+Q6) -> 1415.88
A21: Costo de ventas | B21: =B20*(Historico!$E$9/Historico!$E$8+B11) -> 503.4 | C21: =C20*(Historico!$E$9/Historico!$E$8+C11) -> 528.57 | D21: =D20*(Historico!$E$9/Historico!$E$8+D11) -> 553.74 | E21: =E20*(Historico!$E$9/Historico!$E$8+E11) -> 578.91 | F21: =F20*(Historico!$E$9/Historico!$E$8+F11) -> 604.08 | G21: =G20*(Historico!$E$9/Historico!$E$8+G11) -> 629.25 | H21: =H20*(Historico!$E$9/Historico!$E$8+H11) -> 654.42 | I21: =I20*(Historico!$E$9/Historico!$E$8+I11) -> 679.59 | ... Q21: =Q20*(Historico!$E$9/Historico!$E$8+Q11) -> 679.59
A22: Utilidad bruta | B22: =B20-B21 -> 545.4 | C22: =C20-C21 -> 572.67 | D22: =D20-D21 -> 599.94 | E22: =E20-E21 -> 627.21 | F22: =F20-F21 -> 654.48 | G22: =G20-G21 -> 681.75 | H22: =H20-H21 -> 709.02 | I22: =I20-I21 -> 736.29 | ... Q22: =Q20-Q21 -> 736.29
A23: SG&A | B23: =B12+B20*(Historico!$E$11-B12)/Historico!$E$8 -> 404.5 | C23: =C12+C20*(Historico!$E$11-C12)/Historico!$E$8 -> 424.725 | D23: =D12+D20*(Historico!$E$11-D12)/Historico!$E$8 -> 444.95 | E23: =E12+E20*(Historico!$E$11-E12)/Historico!$E$8 -> 465.175 | F23: =F12+F20*(Historico!$E$11-F12)/Historico!$E$8 -> 485.4 | G23: =G12+G20*(Historico!$E$11-G12)/Historico!$E$8 -> 505.625 | H23: =H12+H20*(Historico!$E$11-H12)/Historico!$E$8 -> 525.85 | I23: =I12+I20*(Historico!$E$11-I12)/Historico!$E$8 -> 546.075 | ... Q23: =Q12+Q20*(Historico!$E$11-Q12)/Historico!$E$8 -> 546.075
A24: Depreciación | B24: =B15 -> 46 | C24: =C15 -> 46 | D24: =D15 -> 46 | E24: =E15 -> 46 | F24: =F15 -> 46 | G24: =G15 -> 46 | H24: =H15 -> 46 | I24: =I15 -> 46 | ... Q24: =Q15 -> 46
A25: Utilidad operativa (EBIT) | B25: =B22-B23-B24 -> 94.9 | C25: =C22-C23-C24 -> 101.945 | D25: =D22-D23-D24 -> 108.99 | E25: =E22-E23-E24 -> 116.035 | F25: =F22-F23-F24 -> 123.08 | G25: =G22-G23-G24 -> 130.125 | H25: =H22-H23-H24 -> 137.17 | I25: =I22-I23-I24 -> 144.215 | ... Q25: =Q22-Q23-Q24 -> 144.215
A26: Intereses | B26: =B47*B16 -> 3.0998168 | C26: =C47*C16 -> 5.7226664 | D26: =D47*D16 -> 8.345516 | E26: =E47*E16 -> 10.968366 | F26: =F47*F16 -> 13.591215 | G26: =G47*G16 -> 16.214065 | H26: =H47*H16 -> 18.836914 | I26: =I47*I16 -> 21.459764 | ... Q26: =Q47*Q16 -> 14.653036
A27: Utilidad antes de impuestos | B27: =B25-B26 -> 91.800183 | C27: =C25-C26 -> 96.222334 | D27: =D25-D26 -> 100.64448 | E27: =E25-E26 -> 105.06663 | F27: =F25-F26 -> 109.48878 | G27: =G25-G26 -> 113.91094 | H27: =H25-H26 -> 118.33309 | I27: =I25-I26 -> 122.75524 | ... Q27: =Q25-Q26 -> 129.56196
A28: Impuestos | B28: =B27*B17 -> 35.985672 | C28: =C27*C17 -> 37.719155 | D28: =D27*D17 -> 39.452638 | E28: =E27*E17 -> 41.186121 | F28: =F27*F17 -> 42.919604 | G28: =G27*G17 -> 44.653087 | H28: =H27*H17 -> 46.38657 | I28: =I27*I17 -> 48.120052 | ... Q28: =Q27*Q17 -> 50.78829
A29: Utilidad neta | B29: =B27-B28 -> 55.814511 | C29: =C27-C28 -> 58.503179 | D29: =D27-D28 -> 61.191846 | E29: =E27-E28 -> 63.880514 | F29: =F27-F28 -> 66.569181 | G29: =G27-G28 -> 69.257849 | H29: =H27-H28 -> 71.946516 | I29: =I27-I28 -> 74.635183 | ... Q29: =Q27-Q28 -> 78.773674
A31: Balance 2020
A32: Caja objetivo | B32: =B13*B20 -> 83.904 | C32: =C13*C20 -> 88.0992 | D32: =D13*D20 -> 92.2944 | E32: =E13*E20 -> 96.4896 | F32: =F13*F20 -> 100.6848 | G32: =G13*G20 -> 104.88 | H32: =H13*H20 -> 109.0752 | I32: =I13*I20 -> 113.2704 | ... Q32: =Q13*Q20 -> 12.69
A33: Excedente de caja | B33: =MAX(-B57,0) -> 0 | C33: =MAX(-C57,0) -> 0 | D33: =MAX(-D57,0) -> 0 | E33: =MAX(-E57,0) -> 0 | F33: =MAX(-F57,0) -> 0 | G33: =MAX(-G57,0) -> 0 | H33: =MAX(-H57,0) -> 0 | I33: =MAX(-I57,0) -> 0 | ... Q33: =MAX(-Q57,0) -> 0
A34: Caja total | B34: =B32+B33 -> 83.904 | C34: =C32+C33 -> 88.0992 | D34: =D32+D33 -> 92.2944 | E34: =E32+E33 -> 96.4896 | F34: =F32+F33 -> 100.6848 | G34: =G32+G33 -> 104.88 | H34: =H32+H33 -> 109.0752 | I34: =I32+I33 -> 113.2704 | ... Q34: =Q32+Q33 -> 12.69
A35: Cuentas por cobrar | B35: =B20*B8/365 -> 146.4 | C35: =C20*C8/365 -> 153.72 | D35: =D20*D8/365 -> 161.04 | E35: =E20*E8/365 -> 168.36 | F35: =F20*F8/365 -> 175.68 | G35: =G20*G8/365 -> 183 | H35: =H20*H8/365 -> 190.32 | I35: =I20*I8/365 -> 197.64 | ... Q35: =Q20*Q8/365 -> 197.64
A36: Inventario | B36: =Historico!$E$8*(1+B7)*(Historico!$E$9/Historico!$E$8+B11)*B9/365 -> 656.9 | C36: =Historico!$E$8*(1+C7)*(Historico!$E$9/Historico!$E$8+C11)*C9/365 -> 689.745 | D36: =Historico!$E$8*(1+D7)*(Historico!$E$9/Historico!$E$8+D11)*D9/365 -> 722.59 | E36: =Historico!$E$8*(1+E7)*(Historico!$E$9/Historico!$E$8+E11)*E9/365 -> 755.435 | F36: =Historico!$E$8*(1+F7)*(Historico!$E$9/Historico!$E$8+F11)*F9/365 -> 788.28 | G36: =Historico!$E$8*(1+G7)*(Historico!$E$9/Historico!$E$8+G11)*G9/365 -> 821.125 | H36: =Historico!$E$8*(1+H7)*(Historico!$E$9/Historico!$E$8+H11)*H9/365 -> 853.97 | I36: =Historico!$E$8*(1+I7)*(Historico!$E$9/Historico!$E$8+I11)*I9/365 -> 886.815 | ... Q36: =Historico!$E$8*(1+Q7)*(Historico!$E$9/Historico!$E$8+Q11)*Q9/365 -> 886.815
A37: Otros activos corrientes | B37: =B20*Historico!$E$21/Historico!$E$8 -> 20.9 | C37: =C20*Historico!$E$21/Historico!$E$8 -> 21.945 | D37: =D20*Historico!$E$21/Historico!$E$8 -> 22.99 | E37: =E20*Historico!$E$21/Historico!$E$8 -> 24.035 | F37: =F20*Historico!$E$21/Historico!$E$8 -> 25.08 | G37: =G20*Historico!$E$21/Historico!$E$8 -> 26.125 | H37: =H20*Historico!$E$21/Historico!$E$8 -> 27.17 | I37: =I20*Historico!$E$21/Historico!$E$8 -> 28.215 | ... Q37: =Q20*Historico!$E$21/Historico!$E$8 -> 28.215
A38: Activo corriente | B38: =SUM(B34:B37) -> 908.104 | C38: =SUM(C34:C37) -> 953.5092 | D38: =SUM(D34:D37) -> 998.9144 | E38: =SUM(E34:E37) -> 1044.3196 | F38: =SUM(F34:F37) -> 1089.7248 | G38: =SUM(G34:G37) -> 1135.13 | H38: =SUM(H34:H37) -> 1180.5352 | I38: =SUM(I34:I37) -> 1225.9404 | ... Q38: =SUM(Q34:Q37) -> 1125.36
A39: Activo fijo neto | B39: =Historico!$E$23+B14-B15 -> 376.9 | C39: =Historico!$E$23+C14-C15 -> 376.9 | D39: =Historico!$E$23+D14-D15 -> 376.9 | E39: =Historico!$E$23+E14-E15 -> 376.9 | F39: =Historico!$E$23+F14-F15 -> 376.9 | G39: =Historico!$E$23+G14-G15 -> 376.9 | H39: =Historico!$E$23+H14-H15 -> 376.9 | I39: =Historico!$E$23+I14-I15 -> 376.9 | ... Q39: =Historico!$E$23+Q14-Q15 -> 376.9
A40: Activo total | B40: =B38+B39 -> 1285.004 | C40: =C38+C39 -> 1330.4092 | D40: =D38+D39 -> 1375.8144 | E40: =E38+E39 -> 1421.2196 | F40: =F38+F39 -> 1466.6248 | G40: =G38+G39 -> 1512.03 | H40: =H38+H39 -> 1557.4352 | I40: =I38+I39 -> 1602.8404 | ... Q40: =Q38+Q39 -> 1502.26
A42: Compras a proveedores | B42: =Historico!$E$33*(1+B7) -> 185.1 | C42: =Historico!$E$33*(1+C7) -> 194.355 | D42: =Historico!$E$33*(1+D7) -> 203.61 | E42: =Historico!$E$33*(1+E7) -> 212.865 | F42: =Historico!$E$33*(1+F7) -> 222.12 | G42: =Historico!$E$33*(1+G7) -> 231.375 | H42: =Historico!$E$33*(1+H7) -> 240.63 | I42: =Historico!$E$33*(1+I7) -> 249.885 | ... Q42: =Historico!$E$33*(1+Q7) -> 249.885
A43: Cuentas por pagar | B43: =B42*B10/365 -> 5 | C43: =C42*C10/365 -> 5.25 | D43: =D42*D10/365 -> 5.5 | E43: =E42*E10/365 -> 5.75 | F43: =F42*F10/365 -> 6 | G43: =G42*G10/365 -> 6.25 | H43: =H42*H10/365 -> 6.5 | I43: =I42*I10/365 -> 6.75 | ... Q43: =Q42*Q10/365 -> 6.75
...

Sheet Descuento proveedores
A1: ¿Conviene dejar de tomar el descuento 2/10 neto 30?
A2: Compara el costo implícito de financiarse con proveedores contra la tasa bancaria.
A4: Descuento | B4: =Supuestos!B12 -> 0.02
A5: Días para obtener descuento | B5: =Supuestos!B13 -> 10
A6: Plazo neto | B6: =Supuestos!B14 -> 30
A7: Costo anual simple de no tomar el descuento | B7: =B4/(1-B4)*365/(B6-B5) -> 0.37244898
A8: Costo anual efectivo (compuesto) | B8: =(1+B4/(1-B4))^(365/(B6-B5))-1 -> 0.44585293
A9: Tasa de la deuda bancaria / hipotecaria | B9: =Supuestos!B7 -> 0.065
A10: Compras 2020 (escenario base) | B10: ='Proyeccion 2020'!B42 -> 240.63
A11: Ahorro anual por tomar el descuento | B11: =B10*B4 -> 4.8126
A12: Financiamiento adicional si se paga al día 30 | B12: =B10*(B6-B5)/365 -> 13.185205
A13: Costo de esa misma suma con deuda bancaria | B13: =B12*B9 -> 0.85703836
A15: Conclusión: seguir tomando el descuento (pagar el día 10, no antes). Dejar de tomarlo liberaría poca caja a un costo implícito de ~37% anual, muy superior a la deuda bancaria.
