Workbook

Sheet Resumen
A1: Resumen para la Junta Directiva – Tasa de descuento de AdeN
A2: Todos los valores se calculan en las hojas 'Alternativas' y 'Datos'.
A4: Indicador | B4: A. Postura del regulador | C4: B. Máximo de la empresa | D4: C. Propuesta recomendada
A5: WACC = Ke (US$ nominal) | B5: =Alternativas!B18 -> 0.07352 | C5: =Alternativas!C18 -> 0.4217512 | D5: =Alternativas!D18 -> 0.15658
A6: Beta ajustada | B6: =Alternativas!B10 -> 0.6525 | C6: =Alternativas!C10 -> 0.9396 | D6: =Alternativas!D10 -> 0.783
A7: Riesgo país (pb) | B7: =Alternativas!B12 -> 0 | C7: =Alternativas!C12 -> 2857 | D7: =Alternativas!D12 -> 619
A8: Costo anual del capital (miles $) | B8: =Alternativas!B22 -> 421.19608 | C8: =Alternativas!C22 -> 2416.2126 | D8: =Alternativas!D22 -> 897.04682
A9: Costo del capital por pasajero ($) | B9: =Alternativas!B24 -> 1.3154978 | C9: =Alternativas!C24 -> 7.5464196 | D9: =Alternativas!D24 -> 2.8016954
A10: Costo del capital / ingresos 2004 | B10: =Alternativas!B26 -> 0.21116819 | C10: =Alternativas!C26 -> 1.211377 | D10: =Alternativas!D26 -> 0.4497377
A12: Recomendación
A13: Proponer al regulador un WACC de alrededor de 15,7% en dólares nominales (alternativa C). Mínimo aceptable 12,1% (C con ERP 4,8% y riesgo país igual al EMBI+ global de 354 pb, ver 'Sensibilidad'). Abrir la negociación sumando la prima regulatoria del 2% (≈17,7%). Exigir que los flujos se expresen en dólares, o que se sume a la tasa el diferencial de inflación.

Sheet Datos
A1: Datos del caso – Aeropuertos del Neuquén S.A. (A)
A2: Insumos tomados del caso IAE FZ-C-204-IA-1-s. Azul = dato ingresado; negro = fórmula.
A4: 1. Tasa libre de riesgo – Bonos del Tesoro de EE.UU. (Anexo 2)
A5: Bono 5 años – spot 23/12/2004 | B5: 0.0358
A6: Bono 10 años – spot 23/12/2004 | B6: 0.0422
A7: Bono 30 años – spot 23/12/2004 | B7: 0.0484 | F7: Fuente: Anexo 2 y p. 5 del caso
A8: Bono 10 años – promedio ene-2000 a dic-2004 | B8: 0.0477
A10: 2. Prima de riesgo de mercado EE.UU. hasta 2003 (Anexo 2)
A11: Período | B11: Años | C11: Ibbotson (arit.) | D11: Damodaran (arit.) | E11: Damodaran (geom.)
A12: 1926/28 – 2003 | B12: 77 | C12: 0.072 | D12: 0.065 | E12: 0.048
A13: 1933 – 2003 | B13: 70 | C13: 0.081 | D13: 0.078 | E13: 0.059
A14: 1945 – 2003 | B14: 58 | C14: 0.074 | D14: 0.074 | E14: 0.058
A15: 1955 – 2003 | B15: 48 | C15: 0.056 | D15: 0.057 | E15: 0.041
A16: 1965 – 2003 | B16: 38 | C16: 0.043 | D16: 0.041 | E16: 0.029
A17: 1975 – 2003 | B17: 28 | C17: 0.07 | D17: 0.058 | E17: 0.04
A18: 1990 – 2003 | B18: 13 | C18: 0.06 | D18: 0.041 | E18: 0.036
A19: Promedio de todas las estimaciones | C19: =AVERAGE(C12:C18) -> 0.065142857 | D19: =AVERAGE(D12:D18) -> 0.059142857 | E19: =AVERAGE(E12:E18) -> 0.044428571
B21: Mínimo | C21: Máximo | D21: Punto medio
A22: ERP en decisiones regulatorias: EE.UU., Australia, Irlanda | B22: 0.05 | C22: 0.07 | D22: =AVERAGE(B22:C22) -> 0.06 | F22: Fuente: p. 5 del caso
A23: ERP en decisiones regulatorias: Reino Unido | B23: 0.025 | C23: 0.05 | D23: =AVERAGE(B23:C23) -> 0.0375
A25: 3. Betas de activos de operadores de aeropuertos (Anexo 3)
A26: Empresa | B26: Beta activos | C26: Regulación
A27: Sydney Airport – SACL (2000) | B27: 0.7 | C27: Price cap | F27: Los cuatro comparables operan bajo price cap, como AdeN.
A28: Auckland Intl. Airport – AIAL (2001) | B28: 0.55 | C28: Price cap
A29: Melbourne Airport – MUDT (2000) | B29: 0.75 | C29: Price cap
A30: Dublin Airport Authority – DAA (2005) | B30: 0.61 | C30: Price cap
A31: Promedio comparables | B31: =AVERAGE(B27:B30) -> 0.6525
A32: Mediana comparables | B32: =MEDIAN(B27:B30) -> 0.655
A34: 4. Ajustes de riesgo (pp. 6–9 del caso)
A35: Prima por riesgo regulatorio (consenso de mercado) | B35: 0.02
A36: Ajuste a la beta por menor calificación (precedente DAA) | B36: 0.2
A37: Ajuste a la beta por tamaño (supuesto, igual al de la DAA) | B37: 0.2
A39: 5. Riesgo país – EMBI+ en puntos básicos (Anexo 3)
A40: Medida | B40: Argentina | C40: EMBI+ global
A41: Spot 23/12/2004 | B41: 4668 | C41: 354
A42: Promedio diciembre 2004 | B42: 5027 | C42: 368
A43: Promedio año 2004 | B43: 5210 | C43: 437
A44: Promedio 1996 – 2004 | B44: 2857 | C44: 752
A45: Promedio año 2003 | B45: 5561 | C45: 561
A46: Promedio 1996 – 2000 (pre-crisis) | B46: 659 | C46: 887
...

Sheet Alternativas
A1: Costo de capital de AdeN – tres alternativas de negociación
A2: Ke = rf + β·ERP + prima regulatoria + riesgo país. En dólares nominales. Verde = vínculo a 'Datos'; celdas amarillas = palancas de cada alternativa.
A4: Componente | B4: A. Postura del regulador | C4: B. Máximo de la empresa | D4: C. Propuesta recomendada
A5: Tasa libre de riesgo rf | B5: =Datos!B6 -> 0.0422 | C5: =Datos!B7 -> 0.0484 | D5: =Datos!B8 -> 0.0477
A6: Prima de riesgo de mercado ERP | B6: =Datos!E12 -> 0.048 | C6: =Datos!C12 -> 0.072 | D6: =Datos!D22 -> 0.06
A7: Beta de activos (promedio comparables) | B7: =Datos!B31 -> 0.6525 | C7: =Datos!B31 -> 0.6525 | D7: =Datos!B31 -> 0.6525
A8: Ajuste por calificación crediticia | B8: 0 | C8: =Datos!B36 -> 0.2 | D8: =Datos!B36 -> 0.2
A9: Ajuste por tamaño (un solo aeropuerto regional) | B9: 0 | C9: =Datos!B37 -> 0.2 | D9: 0
A10: Beta apalancada ajustada (D = 0 ⇒ βE = βA) | B10: =B7*(1+B8)*(1+B9) -> 0.6525 | C10: =C7*(1+C8)*(1+C9) -> 0.9396 | D10: =D7*(1+D8)*(1+D9) -> 0.783
A11: Prima por riesgo regulatorio | B11: 0 | C11: =Datos!B35 -> 0.02 | D11: 0
A12: Riesgo país (puntos básicos) | B12: =Datos!B48 -> 0 | C12: =Datos!B44 -> 2857 | D12: =Datos!B47 -> 619
A13: Riesgo país (%) | B13: =B12/10000 -> 0 | C13: =C12/10000 -> 0.2857 | D13: =D12/10000 -> 0.0619
A15: Costo del capital propio Ke | B15: =B5+B10*B6+B11+B13 -> 0.07352 | C15: =C5+C10*C6+C11+C13 -> 0.4217512 | D15: =D5+D10*D6+D11+D13 -> 0.15658
A16: Peso de la deuda D/(D+E) | B16: =Datos!B60 -> 0 | C16: =Datos!B60 -> 0 | D16: =Datos!B60 -> 0
A17: Kd × (1 − T) | B17: =Datos!B61*(1-Datos!B62) -> 0 | C17: =Datos!B61*(1-Datos!B62) -> 0 | D17: =Datos!B61*(1-Datos!B62) -> 0
A18: WACC (tasa de descuento) | B18: =B17*B16+B15*(1-B16) -> 0.07352 | C18: =C17*C16+C15*(1-C16) -> 0.4217512 | D18: =D17*D16+D15*(1-D16) -> 0.15658
A20: Impacto sobre la tarifa (costo anual del capital = WACC × RAB)
A21: Base de activos regulados – RAB (miles $) | B21: =Datos!B51 -> 5729 | C21: =Datos!B51 -> 5729 | D21: =Datos!B51 -> 5729
A22: Costo anual del capital (miles $) | B22: =B18*B21 -> 421.19608 | C22: =C18*C21 -> 2416.2126 | D22: =D18*D21 -> 897.04682
A23: Pasajeros 2004 (miles) | B23: =Datos!B53 -> 320.18 | C23: =Datos!B53 -> 320.18 | D23: =Datos!B53 -> 320.18
A24: Costo del capital por pasajero ($) | B24: =IF(B23=0,0,B22/B23) -> 1.3154978 | C24: =IF(C23=0,0,C22/C23) -> 7.5464196 | D24: =IF(D23=0,0,D22/D23) -> 2.8016954
A25: Ingreso total por pasajero 2004 ($) | B25: =Datos!B56 -> 6.2296208 | C25: =Datos!B56 -> 6.2296208 | D25: =Datos!B56 -> 6.2296208
A26: Costo del capital / ingresos totales 2004 | B26: =IF(Datos!$B$54=0,0,B22/Datos!$B$54) -> 0.21116819 | C26: =IF(Datos!$B$54=0,0,C22/Datos!$B$54) -> 1.211377 | D26: =IF(Datos!$B$54=0,0,D22/Datos!$B$54) -> 0.4497377
A27: Diferencia de WACC frente a la propuesta C (pp) | B27: =(B18-$D$18)*100 -> -8.306 | C27: =(C18-$D$18)*100 -> 26.51712 | D27: =(D18-$D$18)*100 -> 0
A28: Valor presente de $100 anuales a perpetuidad ($) | B28: =IF(B18=0,0,100/B18) -> 1360.1741 | C28: =IF(C18=0,0,100/C18) -> 237.10662 | D28: =IF(D18=0,0,100/D18) -> 638.65117
A30: Criterio de cada alternativa
A31: rf | B31: Bono a 10 años del día (4,22%), el valor más bajo y actual. | C31: Bono a 30 años (4,84%): coincide con un plazo de concesión largo. | D31: Promedio del bono a 10 años 2000–2004 (4,77%): suaviza un mínimo coyuntural.
A32: ERP | B32: Damodaran, media geométrica 1928–2003 (4,8%). | C32: Ibbotson, media aritmética 1926–2003 (7,2%). | D32: Punto medio de lo aceptado por reguladores con price cap en EE.UU., Australia e Irlanda (6,0%).
A33: β | B33: Promedio de comparables, sin ajustes. | C33: +20% por calificación y +20% por tamaño. | D33: +20% por calificación (precedente DAA: A+→A; AA2000 es BBB+).
A34: Prima regulatoria | B34: No aplica: los comparables ya están regulados por price cap. | C34: Agrega el 2% de 'consenso'. | D34: No se suma: los 4 comparables ya son price cap; sumarla es contar el riesgo dos veces.
A35: Riesgo país | B35: Cero (precedente EPRE San Juan; estudio McKinsey). | C35: Promedio Argentina 1996–2004 (2.857 pb). Con el spot (4.668 pb) sería aún mayor. | D35: Riesgo normalizado: 619 pb (CREG Colombia). Es casi igual al de Argentina antes de la crisis (659 pb).
A37: Evaluación
A38: ¿La acepta la contraparte? | B38: Sí (es su propuesta) | C38: No: duplica la tarifa | D38: Probable: cada supuesto tiene precedente
A39: ¿Atrae capital? | B39: No: menos que un bono argentino | C39: Sí, en exceso | D39: Sí: cubre el riesgo argentino
A40: ¿Sostiene el negocio? | B40: No: consolida las pérdidas | C40: No: rompe la negociación | D40: Sí

Sheet Sensibilidad
A1: Sensibilidad del Ke de la propuesta C
A2: Mantiene rf, β ajustada y prima regulatoria de la alternativa C (hoja 'Alternativas') y varía ERP, riesgo país y β.
A4: Tabla 1. Ke según ERP (filas) y riesgo país en pb (columnas)
A5: ERP \ Riesgo país | B5: 0 | C5: 354 | D5: 619 | E5: 659 | F5: 1500 | G5: 2857 | H5: 4668
A6: 0.029 | B6: =Alternativas!$D$5+Alternativas!$D$10*$A6+Alternativas!$D$11+B$5/10000 -> 0.070407 | C6: =Alternativas!$D$5+Alternativas!$D$10*$A6+Alternativas!$D$11+C$5/10000 -> 0.105807 | D6: =Alternativas!$D$5+Alternativas!$D$10*$A6+Alternativas!$D$11+D$5/10000 -> 0.132307 | E6: =Alternativas!$D$5+Alternativas!$D$10*$A6+Alternativas!$D$11+E$5/10000 -> 0.136307 | F6: =Alternativas!$D$5+Alternativas!$D$10*$A6+Alternativas!$D$11+F$5/10000 -> 0.220407 | G6: =Alternativas!$D$5+Alternativas!$D$10*$A6+Alternativas!$D$11+G$5/10000 -> 0.356107 | H6: =Alternativas!$D$5+Alternativas!$D$10*$A6+Alternativas!$D$11+H$5/10000 -> 0.537207
A7: 0.041 | B7: =Alternativas!$D$5+Alternativas!$D$10*$A7+Alternativas!$D$11+B$5/10000 -> 0.079803 | C7: =Alternativas!$D$5+Alternativas!$D$10*$A7+Alternativas!$D$11+C$5/10000 -> 0.115203 | D7: =Alternativas!$D$5+Alternativas!$D$10*$A7+Alternativas!$D$11+D$5/10000 -> 0.141703 | E7: =Alternativas!$D$5+Alternativas!$D$10*$A7+Alternativas!$D$11+E$5/10000 -> 0.145703 | F7: =Alternativas!$D$5+Alternativas!$D$10*$A7+Alternativas!$D$11+F$5/10000 -> 0.229803 | G7: =Alternativas!$D$5+Alternativas!$D$10*$A7+Alternativas!$D$11+G$5/10000 -> 0.365503 | H7: =Alternativas!$D$5+Alternativas!$D$10*$A7+Alternativas!$D$11+H$5/10000 -> 0.546603
A8: 0.048 | B8: =Alternativas!$D$5+Alternativas!$D$10*$A8+Alternativas!$D$11+B$5/10000 -> 0.085284 | C8: =Alternativas!$D$5+Alternativas!$D$10*$A8+Alternativas!$D$11+C$5/10000 -> 0.120684 | D8: =Alternativas!$D$5+Alternativas!$D$10*$A8+Alternativas!$D$11+D$5/10000 -> 0.147184 | E8: =Alternativas!$D$5+Alternativas!$D$10*$A8+Alternativas!$D$11+E$5/10000 -> 0.151184 | F8: =Alternativas!$D$5+Alternativas!$D$10*$A8+Alternativas!$D$11+F$5/10000 -> 0.235284 | G8: =Alternativas!$D$5+Alternativas!$D$10*$A8+Alternativas!$D$11+G$5/10000 -> 0.370984 | H8: =Alternativas!$D$5+Alternativas!$D$10*$A8+Alternativas!$D$11+H$5/10000 -> 0.552084
A9: 0.055 | B9: =Alternativas!$D$5+Alternativas!$D$10*$A9+Alternativas!$D$11+B$5/10000 -> 0.090765 | C9: =Alternativas!$D$5+Alternativas!$D$10*$A9+Alternativas!$D$11+C$5/10000 -> 0.126165 | D9: =Alternativas!$D$5+Alternativas!$D$10*$A9+Alternativas!$D$11+D$5/10000 -> 0.152665 | E9: =Alternativas!$D$5+Alternativas!$D$10*$A9+Alternativas!$D$11+E$5/10000 -> 0.156665 | F9: =Alternativas!$D$5+Alternativas!$D$10*$A9+Alternativas!$D$11+F$5/10000 -> 0.240765 | G9: =Alternativas!$D$5+Alternativas!$D$10*$A9+Alternativas!$D$11+G$5/10000 -> 0.376465 | H9: =Alternativas!$D$5+Alternativas!$D$10*$A9+Alternativas!$D$11+H$5/10000 -> 0.557565
A10: 0.06 | B10: =Alternativas!$D$5+Alternativas!$D$10*$A10+Alternativas!$D$11+B$5/10000 -> 0.09468 | C10: =Alternativas!$D$5+Alternativas!$D$10*$A10+Alternativas!$D$11+C$5/10000 -> 0.13008 | D10: =Alternativas!$D$5+Alternativas!$D$10*$A10+Alternativas!$D$11+D$5/10000 -> 0.15658 | E10: =Alternativas!$D$5+Alternativas!$D$10*$A10+Alternativas!$D$11+E$5/10000 -> 0.16058 | F10: =Alternativas!$D$5+Alternativas!$D$10*$A10+Alternativas!$D$11+F$5/10000 -> 0.24468 | G10: =Alternativas!$D$5+Alternativas!$D$10*$A10+Alternativas!$D$11+G$5/10000 -> 0.38038 | H10: =Alternativas!$D$5+Alternativas!$D$10*$A10+Alternativas!$D$11+H$5/10000 -> 0.56148
A11: 0.065 | B11: =Alternativas!$D$5+Alternativas!$D$10*$A11+Alternativas!$D$11+B$5/10000 -> 0.098595 | C11: =Alternativas!$D$5+Alternativas!$D$10*$A11+Alternativas!$D$11+C$5/10000 -> 0.133995 | D11: =Alternativas!$D$5+Alternativas!$D$10*$A11+Alternativas!$D$11+D$5/10000 -> 0.160495 | E11: =Alternativas!$D$5+Alternativas!$D$10*$A11+Alternativas!$D$11+E$5/10000 -> 0.164495 | F11: =Alternativas!$D$5+Alternativas!$D$10*$A11+Alternativas!$D$11+F$5/10000 -> 0.248595 | G11: =Alternativas!$D$5+Alternativas!$D$10*$A11+Alternativas!$D$11+G$5/10000 -> 0.384295 | H11: =Alternativas!$D$5+Alternativas!$D$10*$A11+Alternativas!$D$11+H$5/10000 -> 0.565395
A12: 0.072 | B12: =Alternativas!$D$5+Alternativas!$D$10*$A12+Alternativas!$D$11+B$5/10000 -> 0.104076 | C12: =Alternativas!$D$5+Alternativas!$D$10*$A12+Alternativas!$D$11+C$5/10000 -> 0.139476 | D12: =Alternativas!$D$5+Alternativas!$D$10*$A12+Alternativas!$D$11+D$5/10000 -> 0.165976 | E12: =Alternativas!$D$5+Alternativas!$D$10*$A12+Alternativas!$D$11+E$5/10000 -> 0.169976 | F12: =Alternativas!$D$5+Alternativas!$D$10*$A12+Alternativas!$D$11+F$5/10000 -> 0.254076 | G12: =Alternativas!$D$5+Alternativas!$D$10*$A12+Alternativas!$D$11+G$5/10000 -> 0.389776 | H12: =Alternativas!$D$5+Alternativas!$D$10*$A12+Alternativas!$D$11+H$5/10000 -> 0.570876
A13: 0.081 | B13: =Alternativas!$D$5+Alternativas!$D$10*$A13+Alternativas!$D$11+B$5/10000 -> 0.111123 | C13: =Alternativas!$D$5+Alternativas!$D$10*$A13+Alternativas!$D$11+C$5/10000 -> 0.146523 | D13: =Alternativas!$D$5+Alternativas!$D$10*$A13+Alternativas!$D$11+D$5/10000 -> 0.173023 | E13: =Alternativas!$D$5+Alternativas!$D$10*$A13+Alternativas!$D$11+E$5/10000 -> 0.177023 | F13: =Alternativas!$D$5+Alternativas!$D$10*$A13+Alternativas!$D$11+F$5/10000 -> 0.261123 | G13: =Alternativas!$D$5+Alternativas!$D$10*$A13+Alternativas!$D$11+G$5/10000 -> 0.396823 | H13: =Alternativas!$D$5+Alternativas!$D$10*$A13+Alternativas!$D$11+H$5/10000 -> 0.577923
A14: Fila resaltada: ERP de la propuesta (6,0%). Columna resaltada: riesgo país normalizado (619 pb).
A16: Tabla 2. Ke según β ajustada (filas) y ERP (columnas), con riesgo país de 619 pb
A17: β \ ERP | B17: 0.041 | C17: 0.048 | D17: 0.055 | E17: 0.06 | F17: 0.065 | G17: 0.072
A18: 0.55 | B18: =Alternativas!$D$5+$A18*B$17+Alternativas!$D$11+Alternativas!$D$13 -> 0.13215 | C18: =Alternativas!$D$5+$A18*C$17+Alternativas!$D$11+Alternativas!$D$13 -> 0.136 | D18: =Alternativas!$D$5+$A18*D$17+Alternativas!$D$11+Alternativas!$D$13 -> 0.13985 | E18: =Alternativas!$D$5+$A18*E$17+Alternativas!$D$11+Alternativas!$D$13 -> 0.1426 | F18: =Alternativas!$D$5+$A18*F$17+Alternativas!$D$11+Alternativas!$D$13 -> 0.14535 | G18: =Alternativas!$D$5+$A18*G$17+Alternativas!$D$11+Alternativas!$D$13 -> 0.1492
A19: 0.6525 | B19: =Alternativas!$D$5+$A19*B$17+Alternativas!$D$11+Alternativas!$D$13 -> 0.1363525 | C19: =Alternativas!$D$5+$A19*C$17+Alternativas!$D$11+Alternativas!$D$13 -> 0.14092 | D19: =Alternativas!$D$5+$A19*D$17+Alternativas!$D$11+Alternativas!$D$13 -> 0.1454875 | E19: =Alternativas!$D$5+$A19*E$17+Alternativas!$D$11+Alternativas!$D$13 -> 0.14875 | F19: =Alternativas!$D$5+$A19*F$17+Alternativas!$D$11+Alternativas!$D$13 -> 0.1520125 | G19: =Alternativas!$D$5+$A19*G$17+Alternativas!$D$11+Alternativas!$D$13 -> 0.15658
A20: 0.7 | B20: =Alternativas!$D$5+$A20*B$17+Alternativas!$D$11+Alternativas!$D$13 -> 0.1383 | C20: =Alternativas!$D$5+$A20*C$17+Alternativas!$D$11+Alternativas!$D$13 -> 0.1432 | D20: =Alternativas!$D$5+$A20*D$17+Alternativas!$D$11+Alternativas!$D$13 -> 0.1481 | E20: =Alternativas!$D$5+$A20*E$17+Alternativas!$D$11+Alternativas!$D$13 -> 0.1516 | F20: =Alternativas!$D$5+$A20*F$17+Alternativas!$D$11+Alternativas!$D$13 -> 0.1551 | G20: =Alternativas!$D$5+$A20*G$17+Alternativas!$D$11+Alternativas!$D$13 -> 0.16
A21: 0.75 | B21: =Alternativas!$D$5+$A21*B$17+Alternativas!$D$11+Alternativas!$D$13 -> 0.14035 | C21: =Alternativas!$D$5+$A21*C$17+Alternativas!$D$11+Alternativas!$D$13 -> 0.1456 | D21: =Alternativas!$D$5+$A21*D$17+Alternativas!$D$11+Alternativas!$D$13 -> 0.15085 | E21: =Alternativas!$D$5+$A21*E$17+Alternativas!$D$11+Alternativas!$D$13 -> 0.1546 | F21: =Alternativas!$D$5+$A21*F$17+Alternativas!$D$11+Alternativas!$D$13 -> 0.15835 | G21: =Alternativas!$D$5+$A21*G$17+Alternativas!$D$11+Alternativas!$D$13 -> 0.1636
A22: 0.783 | B22: =Alternativas!$D$5+$A22*B$17+Alternativas!$D$11+Alternativas!$D$13 -> 0.141703 | C22: =Alternativas!$D$5+$A22*C$17+Alternativas!$D$11+Alternativas!$D$13 -> 0.147184 | D22: =Alternativas!$D$5+$A22*D$17+Alternativas!$D$11+Alternativas!$D$13 -> 0.152665 | E22: =Alternativas!$D$5+$A22*E$17+Alternativas!$D$11+Alternativas!$D$13 -> 0.15658 | F22: =Alternativas!$D$5+$A22*F$17+Alternativas!$D$11+Alternativas!$D$13 -> 0.160495 | G22: =Alternativas!$D$5+$A22*G$17+Alternativas!$D$11+Alternativas!$D$13 -> 0.165976
A23: 0.85 | B23: =Alternativas!$D$5+$A23*B$17+Alternativas!$D$11+Alternativas!$D$13 -> 0.14445 | C23: =Alternativas!$D$5+$A23*C$17+Alternativas!$D$11+Alternativas!$D$13 -> 0.1504 | D23: =Alternativas!$D$5+$A23*D$17+Alternativas!$D$11+Alternativas!$D$13 -> 0.15635 | E23: =Alternativas!$D$5+$A23*E$17+Alternativas!$D$11+Alternativas!$D$13 -> 0.1606 | F23: =Alternativas!$D$5+$A23*F$17+Alternativas!$D$11+Alternativas!$D$13 -> 0.16485 | G23: =Alternativas!$D$5+$A23*G$17+Alternativas!$D$11+Alternativas!$D$13 -> 0.1708
A24: 0.94 | B24: =Alternativas!$D$5+$A24*B$17+Alternativas!$D$11+Alternativas!$D$13 -> 0.14814 | C24: =Alternativas!$D$5+$A24*C$17+Alternativas!$D$11+Alternativas!$D$13 -> 0.15472 | D24: =Alternativas!$D$5+$A24*D$17+Alternativas!$D$11+Alternativas!$D$13 -> 0.1613 | E24: =Alternativas!$D$5+$A24*E$17+Alternativas!$D$11+Alternativas!$D$13 -> 0.166 | F24: =Alternativas!$D$5+$A24*F$17+Alternativas!$D$11+Alternativas!$D$13 -> 0.1707 | G24: =Alternativas!$D$5+$A24*G$17+Alternativas!$D$11+Alternativas!$D$13 -> 0.17728
A26: Tabla 3. Costo del capital por pasajero ($) según riesgo país (ERP y β de la propuesta)
A27: Riesgo país (pb) | B27: 0 | C27: 354 | D27: 619 | E27: 659 | F27: 1500 | G27: 2857 | H27: 4668
A28: WACC | B28: =Alternativas!$D$5+Alternativas!$D$10*Alternativas!$D$6+Alternativas!$D$11+B27/10000 -> 0.09468 | C28: =Alternativas!$D$5+Alternativas!$D$10*Alternativas!$D$6+Alternativas!$D$11+C27/10000 -> 0.13008 | D28: =Alternativas!$D$5+Alternativas!$D$10*Alternativas!$D$6+Alternativas!$D$11+D27/10000 -> 0.15658 | E28: =Alternativas!$D$5+Alternativas!$D$10*Alternativas!$D$6+Alternativas!$D$11+E27/10000 -> 0.16058 | F28: =Alternativas!$D$5+Alternativas!$D$10*Alternativas!$D$6+Alternativas!$D$11+F27/10000 -> 0.24468 | G28: =Alternativas!$D$5+Alternativas!$D$10*Alternativas!$D$6+Alternativas!$D$11+G27/10000 -> 0.38038 | H28: =Alternativas!$D$5+Alternativas!$D$10*Alternativas!$D$6+Alternativas!$D$11+H27/10000 -> 0.56148
A29: $ por pasajero | B29: =B28*Datos!$B$51/Datos!$B$53 -> 1.6941149 | C29: =C28*Datos!$B$51/Datos!$B$53 -> 2.3275293 | D29: =D28*Datos!$B$51/Datos!$B$53 -> 2.8016954 | E29: =E28*Datos!$B$51/Datos!$B$53 -> 2.8732676 | F29: =F28*Datos!$B$51/Datos!$B$53 -> 4.378074 | G29: =G28*Datos!$B$51/Datos!$B$53 -> 6.8061622 | H29: =H28*Datos!$B$51/Datos!$B$53 -> 10.046595
A30: % del ingreso total 2004 | B30: =B28*Datos!$B$51/Datos!$B$54 -> 0.27194511 | C30: =C28*Datos!$B$51/Datos!$B$54 -> 0.37362294 | D30: =D28*Datos!$B$51/Datos!$B$54 -> 0.4497377 | E30: =E28*Datos!$B$51/Datos!$B$54 -> 0.46122672 | F30: =F28*Datos!$B$51/Datos!$B$54 -> 0.70278338 | G30: =G28*Datos!$B$51/Datos!$B$54 -> 1.0925484 | H30: =H28*Datos!$B$51/Datos!$B$54 -> 1.6127138
