Workbook

Sheet Recomendación
A1: Recomendación ejecutiva
A2: Decisión basada en el caso y en el modelo financiero adjunto
A4: Respuesta a las cuatro preguntas
A5: 1. ¿Operaciones suficientes? | B5: NO. En 2012 deuda/activos es 60.9% y multiplicador 3.3x, frente a máximos de 55.0% y 2.7x. Incluso en 2015 el multiplicador sigue por encima. | C5: [Seguro]
A6: 2. ¿Programa de TV? | B6: SÍ. TIR ~41% y VPN positivo. Financiar con la emisión de capital, no con más deuda; reservar primero la necesidad máxima del proyecto y usar el saldo para amortizar deuda. | C6: [Seguro]
A7: 3. ¿Emitir acciones externas? | B7: SÍ, pese al descuento de 15.6%. Es costoso, pero restaura holgura bancaria y financia el TV. Negociaría derechos, lock-up y uso explícito de fondos. | C7: [Probable]
A8: 4. ¿Adquirir HCS? | B8: SÍ, PERO CONDICIONAL. El DCF base excede US$13.2m, pero el valor es muy sensible al WACC y al crecimiento terminal. Proceder solo con due diligence y protección contractual. | C8: [Probable]
A11: Secuencia recomendada
A12: 1 | B12: 1) Cerrar la emisión de 400,000 acciones y amortizar deuda bancaria.
A13: 2 | B13: 2) Aprobar el programa de TV y separar su fondeo total; no usar deuda incremental.
A14: 3 | B14: 3) Cerrar HCS con acciones, condicionado a due diligence y métricas de desempeño.
A15: 4 | B15: 4) Monitorear covenants trimestralmente y limitar crecimiento si el capital de trabajo vuelve a absorber caja.
A18: Punto de desacuerdo clave
A19: No estoy de acuerdo con asumir que la rentabilidad por sí sola resolverá el apalancamiento. El crecimiento consume activos y capital de trabajo más rápido que la retención de utilidades. Esto es lo que haría en tu lugar: recapitalizar primero, luego invertir. El riesgo del enfoque contrario es incumplir los covenants, perder acceso al crédito y verse obligado a financiarse en condiciones peores.
A23: Controles del modelo
A24: Cifras en azul | B24: inputs editables
A25: Cifras verdes | B25: vínculos entre hojas
A26: Cifras negras | B26: fórmulas

Sheet Supuestos
A1: Pacific Grove Spice Company - Supuestos
A2: USD millones, salvo acciones y precio por acción
A4: Supuestos generales
A5: Tasa de impuestos | B5: 0.27
A6: Tasa libre de riesgo | B6: 0.0425
A7: Prima de riesgo de mercado | B7: 0.07
A8: Crecimiento terminal HCS | B8: 0.048
A9: Precio actual por acción | B9: 32.6
A10: Acciones actuales | B10: 1165327
A11: Acciones nuevas externas | B11: 400000
A12: Producido neto por acción | B12: 27.5
A13: Acciones para adquirir HCS | B13: 404908
A14: Precio de adquisición HCS | B14: 13.2
A15: Pagarés bancarios HCS (30/06/11) | B15: 0.902
A16: Prima de riesgo adicional programa TV | B16: 0
A17: Requisitos del banco
A18: Deuda con intereses / activos máxima | B18: 0.55
A19: Multiplicador de patrimonio máximo | B19: 2.7
A22: Betas y estructura de capital comparables
A23: Compañía | B23: Beta equity | C23: Deuda | D23: Equity mercado | E23: D/E | F23: Beta desapalancada
A24: McCormick | B24: 0.5 | C24: 989.7 | D24: 6567 | E24: =C24/D24 -> 0.15070809 | F24: =B24/(1+(1-$B$5)*E24) -> 0.45044359
A25: ConAgra | B25: 0.6 | C25: 3233.8 | D25: 11069.1 | E25: =C25/D25 -> 0.29214661 | F25: =B25/(1+(1-$B$5)*E25) -> 0.49453252
A26: Pacific Grove | B26: 0.85 | C26: 37.172 | D26: 37.99 | E26: =C26/D26 -> 0.97846802 | F26: =B26/(1+(1-$B$5)*E26) -> 0.49583451
A28: Beta de activos promedio | B28: =AVERAGE(F24:F26) -> 0.48027021
A29: Costo de capital de activos HCS | B29: =$B$6+B28*$B$7 -> 0.076118914
A31: Supuestos operativos HCS (del caso)
B32: 2012 | C32: 2013 en adelante
A33: COGS / ventas | B33: 0.615 | C33: 0.585
A34: I+D / ventas | B34: 0.01 | C34: 0.016
A35: Gastos generales y adm. / ventas | B35: 0.301 | C35: 0.315
A36: Efectivo (días de gastos operativos) | B36: 20
A37: Cuentas por cobrar (días de ventas) | B37: 75
A38: Rotación de inventario (veces COGS) | B38: 4
A39: Gastos pre-pagados / ventas | B39: 0.012
A40: Rotación propiedades y equipo (veces ventas) | B40: 4
A41: Otros activos de largo plazo / ventas | B41: 0.045
A42: Cuentas por pagar (días de COGS) | B42: 30
A43: Gastos devengados / ventas | B43: 0.0166

Sheet PGS Standalone
A1: PGS - Proyección Standalone
A2: USD millones
A4: Estado de resultados y balance resumido
B5: 2011 | C5: 2012 | D5: 2013 | E5: 2014 | F5: 2015
A6: Ventas | B6: 80.94 | C6: 93.081 | D6: 105.182 | E6: 116.751 | F6: 127.259
A7: EBIT | B7: 6.07 | C7: 7.819 | D7: 8.835 | E7: 9.807 | F7: 10.69
A8: Intereses | B8: 2.817 | C8: 3.237 | D8: 3.582 | E8: 3.894 | F8: 4.124
A9: Utilidad neta | B9: 2.374 | C9: 3.344 | D9: 3.835 | E9: 4.316 | F9: 4.793
A10: Activos | B10: 59.62 | C10: 67.874 | D10: 76.697 | E10: 85.134 | F10: 92.797
A11: Pagarés bancarios | B11: 13.442 | C11: 15.492 | D11: 17.506 | E11: 19.432 | F11: 21.181
A12: Porción corriente deuda LP | B12: 1.483 | C12: 1.614 | D12: 1.751 | E12: 1.842 | F12: 1.869
A13: Deuda largo plazo | B13: 22.247 | C13: 24.204 | D13: 26.258 | E13: 27.614 | F13: 28.028
A14: Patrimonio | B14: 17.198 | C14: 20.543 | D14: 24.378 | E14: 28.694 | F14: 33.488
A16: Cumplimiento de covenants
A17: Deuda con intereses | B17: =SUM(B11:B13) -> 37.172 | C17: =SUM(C11:C13) -> 41.31 | D17: =SUM(D11:D13) -> 45.515 | E17: =SUM(E11:E13) -> 48.888 | F17: =SUM(F11:F13) -> 51.078
A18: Deuda / activos | B18: =B17/B10 -> 0.62348205 | C18: =C17/C10 -> 0.60862775 | D18: =D17/D10 -> 0.59343912 | E18: =E17/E10 -> 0.57424766 | F18: =F17/F10 -> 0.55042728
A19: Límite banco | B19: =Supuestos!$B$18 -> 0.55 | C19: =Supuestos!$B$18 -> 0.55 | D19: =Supuestos!$B$18 -> 0.55 | E19: =Supuestos!$B$18 -> 0.55 | F19: =Supuestos!$B$18 -> 0.55
A20: Holgura / (incumplimiento) | B20: =B19-B18 -> -0.073482053 | C20: =C19-C18 -> -0.058627751 | D20: =D19-D18 -> -0.043439118 | E20: =E19-E18 -> -0.024247657 | F20: =F19-F18 -> -0.00042727674
A21: Multiplicador patrimonio | B21: =B10/B14 -> 3.4666822 | C21: =C10/C14 -> 3.3039965 | D21: =D10/D14 -> 3.1461564 | E21: =E10/E14 -> 2.9669617 | F21: =F10/F14 -> 2.7710523
A22: Límite banco | B22: =Supuestos!$B$19 -> 2.7 | C22: =Supuestos!$B$19 -> 2.7 | D22: =Supuestos!$B$19 -> 2.7 | E22: =Supuestos!$B$19 -> 2.7 | F22: =Supuestos!$B$19 -> 2.7
A23: Holgura / (incumplimiento) | B23: =B22-B21 -> -0.76668217 | C23: =C22-C21 -> -0.6039965 | D23: =D22-D21 -> -0.44615637 | E23: =E22-E21 -> -0.26696173 | F23: =F22-F21 -> -0.071052317
A24: Cobertura de intereses | B24: =B7/B8 -> 2.1547746 | C24: =C7/C8 -> 2.4155082 | D24: =D7/D8 -> 2.4664992 | E24: =E7/E8 -> 2.51849 | F24: =F7/F8 -> 2.5921435
A26: Conclusión | B26: =IF(AND(C18<=C19,C21<=C22),"Cumple en 2012","NO cumple en 2012") -> NO cumple en 2012

Sheet Programa TV
A1: Programa de televisión - Presupuesto de capital
A2: USD millones
A4: Supuestos
A5: Inversión equipo | B5: 1.44
A6: Ventas año 1 | B6: 8.1
A7: Crecimiento ventas | B7: 0.05
A8: COGS / ventas | B8: 0.585
A9: Promoción / ventas | B9: 0.11
A10: G&A año 1 | B10: 0.76
A11: Vida / depreciación | B11: 5
A12: DSO | B12: 75
A13: Rotación inventario | B13: 4
A14: Días cuentas por pagar | B14: 30
A15: Tasa de descuento base (costo de activos + prima TV) | B15: =Supuestos!B29+Supuestos!B16 -> 0.076118914
A17: Flujos del proyecto
A18: Concepto | B18: 0 | C18: 1 | D18: 2 | E18: 3 | F18: 4 | G18: 5
A19: Ventas | C19: =$B$6 -> 8.1 | D19: =C19*(1+$B$7) -> 8.505 | E19: =D19*(1+$B$7) -> 8.93025 | F19: =E19*(1+$B$7) -> 9.3767625 | G19: =F19*(1+$B$7) -> 9.8456006
A20: COGS | C20: =C19*$B$8 -> 4.7385 | D20: =D19*$B$8 -> 4.975425 | E20: =E19*$B$8 -> 5.2241963 | F20: =F19*$B$8 -> 5.4854061 | G20: =G19*$B$8 -> 5.7596764
A21: Margen bruto | C21: =C19-C20 -> 3.3615 | D21: =D19-D20 -> 3.529575 | E21: =E19-E20 -> 3.7060538 | F21: =F19-F20 -> 3.8913564 | G21: =G19-G20 -> 4.0859243
A22: Promoción | C22: =C19*$B$9 -> 0.891 | D22: =D19*$B$9 -> 0.93555 | E22: =E19*$B$9 -> 0.9823275 | F22: =F19*$B$9 -> 1.0314439 | G22: =G19*$B$9 -> 1.0830161
A23: G&A | C23: =$B$10 -> 0.76 | D23: =C23*(1+$B$7) -> 0.798 | E23: =D23*(1+$B$7) -> 0.8379 | F23: =E23*(1+$B$7) -> 0.879795 | G23: =F23*(1+$B$7) -> 0.92378475
A24: Depreciación | C24: =$B$5/$B$11 -> 0.288 | D24: =$B$5/$B$11 -> 0.288 | E24: =$B$5/$B$11 -> 0.288 | F24: =$B$5/$B$11 -> 0.288 | G24: =$B$5/$B$11 -> 0.288
A25: EBIT incremental | C25: =C21-C22-C23-C24 -> 1.4225 | D25: =D21-D22-D23-D24 -> 1.508025 | E25: =E21-E22-E23-E24 -> 1.5978263 | F25: =F21-F22-F23-F24 -> 1.6921176 | G25: =G21-G22-G23-G24 -> 1.7911234
A26: Impuestos | C26: =C25*Supuestos!$B$5 -> 0.384075 | D26: =D25*Supuestos!$B$5 -> 0.40716675 | E26: =E25*Supuestos!$B$5 -> 0.43141309 | F26: =F25*Supuestos!$B$5 -> 0.45687174 | G26: =G25*Supuestos!$B$5 -> 0.48360333
A27: NOPAT | C27: =C25-C26 -> 1.038425 | D27: =D25-D26 -> 1.1008582 | E27: =E25-E26 -> 1.1664132 | F27: =F25-F26 -> 1.2352458 | G27: =G25-G26 -> 1.3075201
A28: Flujo operativo | C28: =C27+C24 -> 1.326425 | D28: =D27+D24 -> 1.3888582 | E28: =E27+E24 -> 1.4544132 | F28: =F27+F24 -> 1.5232458 | G28: =G27+G24 -> 1.5955201
A29: A/R requerido | C29: =C19*$B$12/365 -> 1.6643836 | D29: =D19*$B$12/365 -> 1.7476027 | E29: =E19*$B$12/365 -> 1.8349829 | F29: =F19*$B$12/365 -> 1.926732 | G29: =G19*$B$12/365 -> 2.0230686
A30: Inventario requerido | C30: =C20/$B$13 -> 1.184625 | D30: =D20/$B$13 -> 1.2438563 | E30: =E20/$B$13 -> 1.3060491 | F30: =F20/$B$13 -> 1.3713515 | G30: =G20/$B$13 -> 1.4399191
A31: A/P requerido | C31: =C20*$B$14/365 -> 0.38946575 | D31: =D20*$B$14/365 -> 0.40893904 | E31: =E20*$B$14/365 -> 0.42938599 | F31: =F20*$B$14/365 -> 0.45085529 | G31: =G20*$B$14/365 -> 0.47339806
A32: Capital de trabajo neto | C32: =C29+C30-C31 -> 2.4595428 | D32: =D29+D30-D31 -> 2.5825199 | E32: =E29+E30-E31 -> 2.7116459 | F32: =F29+F30-F31 -> 2.8472282 | G32: =G29+G30-G31 -> 2.9895897
A33: Cambio en capital de trabajo | C33: =C32 -> 2.4595428 | D33: =D32-C32 -> 0.12297714 | E33: =E32-D32 -> 0.129126 | F33: =F32-E32 -> 0.1355823 | G33: =G32-F32 -> 0.14236141
A34: Recuperación capital trabajo | C34: =0 -> 0 | D34: =0 -> 0 | E34: =0 -> 0 | F34: =0 -> 0 | G34: =G32 -> 2.9895897
A35: Flujo total proyecto | B35: =-$B$5 -> -1.44 | C35: =C28-C33+C34 -> -1.1331178 | D35: =D28-D33+D34 -> 1.2658811 | E35: =E28-E33+E34 -> 1.3252872 | F35: =F28-F33+F34 -> 1.3876635 | G35: =G28-G33+G34 -> 4.4427484
A37: TIR | B37: =IRR(B35:G35) -> 0.41275224
A38: VPN a tasa base | B38: =NPV($B$15,C35:G35)+B35 -> 3.776992
A39: Necesidad máxima acumulada | B39: =-MIN(B35,SUM(B35:C35),SUM(B35:D35),SUM(B35:E35),SUM(B35:F35),SUM(B35:G35)) -> 2.5731178
A40: Tasa conservadora | B40: 0.15
A41: VPN a tasa conservadora | B41: =NPV($B$40,C35:G35)+B35 -> 2.4054982
A43: Sensibilidad: ventas menores, promoción y G&A en montos proyectados
A44: Ventas como % de la proyección | B44: 0.75
...

Sheet Emisión Acciones
A1: Emisión externa de acciones
A2: USD millones salvo datos por acción
A4: Economía de la transacción
A5: Producido neto | B5: =Supuestos!B11*Supuestos!B12/1000000 -> 11
A6: Descuento vs. mercado | B6: =1-Supuestos!B12/Supuestos!B9 -> 0.15644172
A7: Acciones post emisión | B7: =Supuestos!B10+Supuestos!B11 -> 1565327
A8: Participación de nuevos accionistas | B8: =Supuestos!B11/B7 -> 0.25553766
A9: Patrimonio 2012 pro forma | B9: ='PGS Standalone'!C14+B5 -> 31.543
A10: Deuda 2012 pro forma | B10: ='PGS Standalone'!C17-B5 -> 30.31
A11: Deuda / activos 2012 | B11: =B10/'PGS Standalone'!C10 -> 0.44656275
A12: Multiplicador patrimonio 2012 | B12: ='PGS Standalone'!C10/B9 -> 2.1517928
A13: Exceso después de financiar TV | B13: =B5-'Programa TV'!B39 -> 8.4268822
A16: Conclusión | B16: =IF(AND(B11<=Supuestos!B18,B12<=Supuestos!B19),"Restaura cumplimiento; aceptar","No restaura cumplimiento") -> Restaura cumplimiento; aceptar

Sheet Adquisición HCS
A1: High Country Seasonings - DCF
A2: USD millones
A4: Proyección operativa
B5: 2011 | C5: 2012 | D5: 2013 | E5: 2014 | F5: 2015
A6: Crecimiento ventas | C6: 0.07 | D6: 0.06 | E6: 0.05 | F6: 0.048
A7: Ventas | B7: 17.564 | C7: =B7*(1+C6) -> 18.79348 | D7: =C7*(1+D6) -> 19.921089 | E7: =D7*(1+E6) -> 20.917143 | F7: =E7*(1+F6) -> 21.921166
A8: COGS % | C8: =Supuestos!$B$33 -> 0.615 | D8: =Supuestos!$C$33 -> 0.585 | E8: =Supuestos!$C$33 -> 0.585 | F8: =Supuestos!$C$33 -> 0.585
A9: R&D % | C9: =Supuestos!$B$34 -> 0.01 | D9: =Supuestos!$C$34 -> 0.016 | E9: =Supuestos!$C$34 -> 0.016 | F9: =Supuestos!$C$34 -> 0.016
A10: SG&A % | C10: =Supuestos!$B$35 -> 0.301 | D10: =Supuestos!$C$35 -> 0.315 | E10: =Supuestos!$C$35 -> 0.315 | F10: =Supuestos!$C$35 -> 0.315
A11: EBIT | C11: =C7*(1-C8-C9-C10) -> 1.3907175 | D11: =D7*(1-D8-D9-D10) -> 1.6733715 | E11: =E7*(1-E8-E9-E10) -> 1.75704 | F11: =F7*(1-F8-F9-F10) -> 1.841378
A12: NOPAT | C12: =C11*(1-Supuestos!$B$5) -> 1.0152238 | D12: =D11*(1-Supuestos!$B$5) -> 1.2215612 | E12: =E11*(1-Supuestos!$B$5) -> 1.2826392 | F12: =F11*(1-Supuestos!$B$5) -> 1.3442059
A13: Activos operativos | C13: =C7*(C8+C9+C10)*Supuestos!$B$36/365+C7*Supuestos!$B$37/365+C7*C8/Supuestos!$B$38+C7*Supuestos!$B$39+C7/Supuestos!$B$40+C7*Supuestos!$B$41 -> 13.474346 | D13: =D7*(D8+D9+D10)*Supuestos!$B$36/365+D7*Supuestos!$B$37/365+D7*D8/Supuestos!$B$38+D7*Supuestos!$B$39+D7/Supuestos!$B$40+D7*Supuestos!$B$41 -> 14.122483 | E13: =E7*(E8+E9+E10)*Supuestos!$B$36/365+E7*Supuestos!$B$37/365+E7*E8/Supuestos!$B$38+E7*Supuestos!$B$39+E7/Supuestos!$B$40+E7*Supuestos!$B$41 -> 14.828607 | F13: =F7*(F8+F9+F10)*Supuestos!$B$36/365+F7*Supuestos!$B$37/365+F7*F8/Supuestos!$B$38+F7*Supuestos!$B$39+F7/Supuestos!$B$40+F7*Supuestos!$B$41 -> 15.54038
A14: Pasivos operativos | C14: =C7*C8*Supuestos!$B$42/365+C7*Supuestos!$B$43 -> 1.2619436 | D14: =D7*D8*Supuestos!$B$42/365+D7*Supuestos!$B$43 -> 1.2885397 | E14: =E7*E8*Supuestos!$B$42/365+E7*Supuestos!$B$43 -> 1.3529667 | F14: =F7*F8*Supuestos!$B$42/365+F7*Supuestos!$B$43 -> 1.4179091
A15: Capital operativo neto | B15: 10.626 | C15: =C13-C14 -> 12.212402 | D15: =D13-D14 -> 12.833943 | E15: =E13-E14 -> 13.47564 | F15: =F13-F14 -> 14.122471
A16: Cambio capital operativo | C16: =C15-B15 -> 1.5864023 | D16: =D15-C15 -> 0.6215408 | E16: =E15-D15 -> 0.64169716 | F16: =F15-E15 -> 0.64683073
A17: Flujo libre de caja | C17: =C12-C16 -> -0.57117855 | D17: =D12-D16 -> 0.60002036 | E17: =E12-E16 -> 0.64094207 | F17: =F12-F16 -> 0.69737517
A20: Costo de capital y valoración
A21: WACC / costo de activos | B21: =Supuestos!B29 -> 0.076118914
A22: Valor terminal | B22: =F17*(1+Supuestos!B8)/(B21-Supuestos!B8) -> 25.991372
A23: Valor presente empresa | B23: =NPV(B21,C17:F17)+B22/(1+B21)^4 -> 20.403248
A24: (-) Pagarés bancarios HCS | B24: =Supuestos!B15 -> 0.902
A25: Valor del patrimonio | B25: =B23-B24 -> 19.501248
A26: Precio solicitado | B26: =Supuestos!B14 -> 13.2
A27: VPN adquisición | B27: =B25-B26 -> 6.3012477
A28: WACC de estrés | B28: 0.09
A29: Valor del patrimonio a WACC de estrés | B29: =NPV(B28,C17:F17)+(F17*(1+Supuestos!B8)/(B28-Supuestos!B8))/(1+B28)^4-B24 -> 12.395399 | C29: =IF(B29<B26,"Por debajo del precio de US$13.2m","Sobre el precio de US$13.2m") -> Por debajo del precio de US$13.2m
A31: Conclusión | B31: =IF(B27>0,"Adquirir, sujeto a validar sinergias y crecimiento terminal","No adquirir al precio solicitado") -> Adquirir, sujeto a validar sinergias y crecimiento terminal

Sheet Comparativo Opciones
A1: Comparativo de opciones - Covenants, BPA y valor
A2: USD millones salvo acciones (millones) y BPA. Combina TV, emisión y adquisición de HCS; los pagarés bancarios cuadran el balance (como indica el caso).
A4: Supuestos del comparativo
A5: Tasa pagarés bancarios (preferencial 3.25% + 5%) | B5: 0.0825
A6: Patrimonio en libros HCS (30/06/11) | B6: 9.724
A7: Fondo de comercio HCS | B7: =Supuestos!B14-B6 -> 3.476
A8: Intereses adicionales al consolidar HCS | C8: 0.2 | D8: 0.3 | E8: 0.4 | F8: 0.5
A9: Acciones actuales (millones) | B9: =Supuestos!B10/1000000 -> 1.165327
A10: Acciones nuevas por emisión (millones) | B10: =Supuestos!B11/1000000 -> 0.4
A11: Acciones entregadas a HCS (millones) | B11: =Supuestos!B13/1000000 -> 0.404908
A12: Producido neto de la emisión | B12: ='Emisión Acciones'!B5 -> 11
A13: Transferencia a nuevos accionistas por descuento | B13: =Supuestos!B11*(Supuestos!B9-Supuestos!B12)/1000000 -> 2.04
A15: Bloques de construcción por año
B16: 2011 | C16: 2012 | D16: 2013 | E16: 2014 | F16: 2015
A17: PGS standalone
A18: EBIT | C18: ='PGS Standalone'!C7 -> 7.819 | D18: ='PGS Standalone'!D7 -> 8.835 | E18: ='PGS Standalone'!E7 -> 9.807 | F18: ='PGS Standalone'!F7 -> 10.69
A19: Intereses | C19: ='PGS Standalone'!C8 -> 3.237 | D19: ='PGS Standalone'!D8 -> 3.582 | E19: ='PGS Standalone'!E8 -> 3.894 | F19: ='PGS Standalone'!F8 -> 4.124
A20: Activos | C20: ='PGS Standalone'!C10 -> 67.874 | D20: ='PGS Standalone'!D10 -> 76.697 | E20: ='PGS Standalone'!E10 -> 85.134 | F20: ='PGS Standalone'!F10 -> 92.797
A21: Pasivos sin intereses | C21: ='PGS Standalone'!C10-'PGS Standalone'!C14-'PGS Standalone'!C17 -> 6.021 | D21: ='PGS Standalone'!D10-'PGS Standalone'!D14-'PGS Standalone'!D17 -> 6.804 | E21: ='PGS Standalone'!E10-'PGS Standalone'!E14-'PGS Standalone'!E17 -> 7.552 | F21: ='PGS Standalone'!F10-'PGS Standalone'!F14-'PGS Standalone'!F17 -> 8.231
A22: Patrimonio inicial | B22: ='PGS Standalone'!B14 -> 17.198
A23: Programa de TV (año 1 = FY2012)
A24: EBIT incremental | C24: ='Programa TV'!C25 -> 1.4225 | D24: ='Programa TV'!D25 -> 1.508025 | E24: ='Programa TV'!E25 -> 1.5978263 | F24: ='Programa TV'!F25 -> 1.6921176
A25: Equipo neto | C25: ='Programa TV'!$B$5-SUM('Programa TV'!$C$24:C24) -> 1.152 | D25: ='Programa TV'!$B$5-SUM('Programa TV'!$C$24:D24) -> 0.864 | E25: ='Programa TV'!$B$5-SUM('Programa TV'!$C$24:E24) -> 0.576 | F25: ='Programa TV'!$B$5-SUM('Programa TV'!$C$24:F24) -> 0.288
A26: Cuentas por cobrar + inventario | C26: ='Programa TV'!C29+'Programa TV'!C30 -> 2.8490086 | D26: ='Programa TV'!D29+'Programa TV'!D30 -> 2.991459 | E26: ='Programa TV'!E29+'Programa TV'!E30 -> 3.1410319 | F26: ='Programa TV'!F29+'Programa TV'!F30 -> 3.2980835
A27: Cuentas por pagar | C27: ='Programa TV'!C31 -> 0.38946575 | D27: ='Programa TV'!D31 -> 0.40893904 | E27: ='Programa TV'!E31 -> 0.42938599 | F27: ='Programa TV'!F31 -> 0.45085529
A28: Deuda que financia el TV (inicio del año) | C28: =-'Programa TV'!$B$35 -> 1.44 | D28: =MAX(0,C28-'Programa TV'!C35) -> 2.5731178 | E28: =MAX(0,D28-'Programa TV'!D35) -> 1.3072367 | F28: =MAX(0,E28-'Programa TV'!E35) -> 0
A29: Intereses por financiar el TV | C29: =C28*$B$5 -> 0.1188 | D29: =D28*$B$5 -> 0.21228222 | E29: =E28*$B$5 -> 0.10784703 | F29: =F28*$B$5 -> 0
A30: High Country Seasonings (consolidada)
A31: EBIT | C31: ='Adquisición HCS'!C11 -> 1.3907175 | D31: ='Adquisición HCS'!D11 -> 1.6733715 | E31: ='Adquisición HCS'!E11 -> 1.75704 | F31: ='Adquisición HCS'!F11 -> 1.841378
A32: Activos operativos | C32: ='Adquisición HCS'!C13 -> 13.474346 | D32: ='Adquisición HCS'!D13 -> 14.122483 | E32: ='Adquisición HCS'!E13 -> 14.828607 | F32: ='Adquisición HCS'!F13 -> 15.54038
A33: Pasivos operativos | C33: ='Adquisición HCS'!C14 -> 1.2619436 | D33: ='Adquisición HCS'!D14 -> 1.2885397 | E33: ='Adquisición HCS'!E14 -> 1.3529667 | F33: ='Adquisición HCS'!F14 -> 1.4179091
A34: Intereses adicionales | C34: =C8 -> 0.2 | D34: =D8 -> 0.3 | E34: =E8 -> 0.4 | F34: =F8 -> 0.5
A35: Emisión de acciones
A36: Intereses ahorrados al amortizar pagarés | C36: =$B$12*$B$5 -> 0.9075 | D36: =$B$12*$B$5 -> 0.9075 | E36: =$B$12*$B$5 -> 0.9075 | F36: =$B$12*$B$5 -> 0.9075
A38: Resumen de escenarios (1 = se hace, 0 = no)
A39: Escenario | B39: TV | C39: Emisión | D39: HCS | E39: Deuda/activos 2012 | F39: Multiplicador 2012 | G39: ¿Cumple 2012? | H39: Deuda/activos 2015 | I39: Multiplicador 2015 | J39: BPA 2012 | K39: BPA 2015 | L39: VPN accionistas actuales | M39: VPN por acción actual
A40: 1. Sin hacer nada | B40: 0 | C40: 0 | D40: 0 | E40: =C60 -> 0.60862981 | F40: =C61 -> 3.304019 | G40: =C65 -> No cumple | H40: =F60 -> 0.55043568 | I40: =F61 -> 2.7711169 | J40: =C64 -> 2.8703188 | K40: =F64 -> 4.1131631 | L40: =$B$40*'Programa TV'!$B$38+$D$40*'Adquisición HCS'!$B$27-$C$40*$B$13 -> 0 | M40: =L40/$B$9 -> 0
A41: 2. Solo TV | B41: 1 | C41: 0 | D41: 0 | E41: =C75 -> 0.6117562 | F41: =C76 -> 3.3438696 | G41: =C80 -> No cumple | H41: =F75 -> 0.51869563 | I41: =F76 -> 2.5560554 | J41: =C79 -> 3.6870003 | K41: =F79 -> 5.1731624 | L41: =$B$41*'Programa TV'!$B$38+$D$41*'Adquisición HCS'!$B$27-$C$41*$B$13 -> 3.776992 | M41: =L41/$B$9 -> 3.2411434
A42: 3. Solo emisión | B42: 0 | C42: 1 | D42: 0 | E42: =C90 -> 0.43680445 | F42: =C91 -> 2.107539 | G42: =C95 -> Cumple | H42: =F90 -> 0.40334149 | I42: =F91 -> 1.9686608 | J42: =C94 -> 2.5600625 | K42: =F94 -> 3.4853133 | L42: =$B$42*'Programa TV'!$B$38+$D$42*'Adquisición HCS'!$B$27-$C$42*$B$13 -> -2.04 | M42: =L42/$B$9 -> -1.7505816
A43: 4. Solo HCS | B43: 0 | C43: 0 | D43: 1 | E43: =C105 -> 0.50609666 | F43: =C106 -> 2.4507148 | G43: =C110 -> Cumple | H43: =F105 -> 0.46180181 | I43: =F106 -> 2.2128622 | J43: =C109 -> 2.6837281 | K43: =F109 -> 3.6761287 | L43: =$B$43*'Programa TV'!$B$38+$D$43*'Adquisición HCS'!$B$27-$C$43*$B$13 -> 6.3012477 | M43: =L43/$B$9 -> 5.4072786
...
