Workbook

Sheet Supuestos
A1: Supuestos del modelo (millones de US$, salvo indicación)
A2: Convención: azul = dato o supuesto escrito a mano; negro = fórmula; verde = vínculo a otra hoja; fondo amarillo = selector o supuesto clave que se puede cambiar.
A4: 1. Mercado, deuda e impuestos
C5: Valor | I5: Fuente / tipo
A6: Tasa de impuestos | C6: 0.4 | I6: Caso, Anexo 1 (40% en todos los años proyectados).
A7: Costo de la deuda (Kd), BBB+ | C7: 0.055 | I7: Caso, p. 8: 'tasa de interés de aproximadamente 5,50%'.
A8: Diferencial sobre el bono del Tesoro a 10 años | C8: 0.0125 | I8: Caso, p. 8: '125 pb sobre el rendimiento actual del Tesoro a 10 años'.
A9: Tasa libre de riesgo (Tesoro a 10 años) = Kd − diferencial | C9: =C7-C8 -> 0.0425 | I9: Derivada del caso (5,50% − 1,25%). El caso no da el plazo de 20 o 30 años.
A10: Prima de riesgo de mercado (PRM) | C10: 0.05 | I10: Caso, p. 8: recomendación de Bianco (R&R). No dice período ni si es promedio aritmético o geométrico.
A11: Cobertura EBITDA / intereses para dimensionar la deuda | C11: 5 | I11: Caso, p. 2 y p. 8 (≥ 5,0x sobre EBITDA 2007).
A12: Deuda / valor máximo admitido | C12: 0.5 | I12: Caso, p. 2 y p. 8 (45%-50%).
A13: Plazo de amortización de la deuda (meses) | C13: 120 | I13: Caso, p. 8 y Anexo 6.
A14: Mes del pago bullet (refinanciación) | C14: 60 | I14: Caso, p. 8: pago bullet al final del año 5.
A15: Múltiplo P/U histórico de la industria | C15: 19.095 | I15: Caso, nota 3.
A16: Costo de salir a bolsa (% del patrimonio), tope razonable del descuento | C16: 0.1 | I16: Caso, nota 6.
A17: Descuento por iliquidez, Anexo 8 (empresa rentable, ingresos US$1.000 MM) | C17: 0.157 | I17: Lectura aproximada de un gráfico (imagen); el valor exacto no está en el caso.
A18: Descuento por iliquidez, regla práctica (20%-30%), punto medio | C18: 0.25 | I18: Caso, p. 8.
A19: Descuento por iliquidez, investigación académica | C19: 0.35 | I19: Caso, p. 8 y nota 5 (Moroney 35%; Silber 33,75%).
A21: 2. Selectores de decisiones metodológicas (cambiar el número para ver el efecto)
A22: Beta desapalancada: 1 = Hamada (βd = 0); 2 = Harris-Pringle (βd = 0); 3 = Harris-Pringle con βd implícita | C22: 3 | I22: Elección propia: la deuda BBB+ paga 125 pb sobre el Tesoro, así que su beta no es cero (ver hoja Costo_Capital).
A23: Estructura objetivo D/V: 1 = promedio comparables; 2 = mediana comparables; 3 = máximo de R&R (50%) | C23: 1 | I23: Caso, p. 8: la deuda se paga hasta niveles de la industria; nota del Anexo 7: promedio de 3 años.
A24: Crecimiento a perpetuidad: 1 = fundamental (ROIC × tasa de reinversión 2012); 2 = manual | C24: 1 | I24: Caso, p. 8 y notas 7 y 8: g depende del retorno sobre el capital y de la tasa de reinversión.
A25: Crecimiento manual (solo si el selector anterior = 2) | C25: 0.03 | I25: Supuesto propio para sensibilidad; no sale del caso.
A26: Múltiplo terminal VE/EBITDA: 1 = promedio comparables; 2 = mediana | C26: 2 | I26: Elección propia: la mediana es menos sensible a los extremos (2,6x a 19,1x).
A27: Valor de afiliadas e interés minoritario: 1 = P/U de la industria; 2 = valor en libros | C27: 1 | I27: Caso, p. 6 y nota 3 (Jennifer propone múltiplos de mercado).
A28: Margen de las sinergias de ingresos: 1 = margen EBITDA proyectado de ATC; 2 = margen sin SG&A ni equipos | C28: 1 | I28: El caso (Tabla 5) solo da ingresos, no la utilidad bruta que menciona el texto. Supuesto propio.
A29: Descuento por iliquidez aplicado al patrimonio | C29: 0 | I29: Elección propia (ver informe): comprador estratégico del 100%, empresa grande y rentable con opción de salir a bolsa.
A30: Porcentaje de sinergias que se realiza | C30: 1 | I30: Escenario base del caso (Tablas 4 y 5).
A31: Parte de las sinergias de backhaul que se cede al vendedor en el precio objetivo | C31: 0.5 | I31: Supuesto propio de negociación (reparto en partes iguales de la sinergia más cierta).
A32: Variación de g para el análisis tornado (± pp) | C32: 0.005 | I32: Supuesto propio para sensibilidad.
A34: 3. Supuestos operativos 2008-2012 (Anexo 1)
A35: Año | D35: 2008 | E35: 2009 | F35: 2010 | G35: 2011 | H35: 2012
A36: Crecimiento de ingresos por servicios | D36: 0.14 | E36: 0.14 | F36: 0.125 | G36: 0.1 | H36: 0.07 | I36: Caso, Anexo 1.
A37: Costos de operación del sistema / ingresos por servicios | D37: 0.2 | E37: 0.2 | F37: 0.2 | G37: 0.2 | H37: 0.2 | I37: Caso, Anexo 1.
A38: Costo de equipos vendidos / ingresos por equipos | D38: 2.4 | E38: 2.4 | F38: 2.4 | G38: 2.4 | H38: 2.4 | I38: Caso, Anexo 1 (240%: los equipos se subsidian).
A39: SG&A / ingresos totales | D39: 0.4 | E39: 0.4 | F39: 0.4 | G39: 0.4 | H39: 0.4 | I39: Caso, Anexo 1.
A40: Depreciación y amortización | D40: 705.22932 | E40: 803.96142 | F40: 867.43875 | G40: 922.37654 | H40: 952.91038 | I40: Caso, Anexo 1 (valores absolutos).
A41: Capex / ingresos totales | D41: 0.14 | E41: 0.14 | F41: 0.15 | G41: 0.1525 | H41: 0.155 | I41: Caso, Anexo 1 (incluye licencias y listas de clientes).
A42: D&A / ingresos totales (implícito en el Anexo 1) | D42: =D40/Proyeccion!D8 -> 0.15640123 | E42: =E40/Proyeccion!E8 -> 0.15640123 | F42: =F40/Proyeccion!F8 -> 0.15 | G42: =G40/Proyeccion!G8 -> 0.145 | H42: =H40/Proyeccion!H8 -> 0.14 | I42: Derivado: D&A del Anexo 1 / ingresos del escenario base. En los escenarios la D&A se mueve con los ingresos.
A44: Razones de capital de trabajo (promedio 2005-2007, año de 360 días)
...

Sheet Historicos
A1: Datos históricos 2005-2007, controles de consistencia e indicadores (millones de US$)
A3: A. Estado de resultados (Anexo 4)
C4: 2005 | D4: 2006 | E4: 2007
A5: Ingresos por servicios | C5: 2827.022 | D5: 3214.41 | E5: 3679.237
A6: Ingresos por equipos | C6: 203.743 | D6: 258.745 | E6: 267.027
A7: Ingresos totales | C7: =C5+C6 -> 3030.765 | D7: =D5+D6 -> 3473.155 | E7: =E5+E6 -> 3946.264
A8: Costos de operación del sistema | C8: 604.093 | D8: 639.683 | E8: 717.075
A9: Costo de equipos vendidos | C9: 511.939 | D9: 568.903 | E9: 640.225
A10: Gastos de ventas, generales y de administración (SG&A) | C10: 1217.709 | D10: 1399.561 | E10: 1555.639
A11: EBITDA | C11: =C7-C8-C9-C10 -> 697.024 | D11: =D7-D8-D9-D10 -> 865.008 | E11: =E7-E8-E9-E10 -> 1033.325
A12: Depreciación y amortización | C12: 490.093 | D12: 555.525 | E12: 582.269
A13: EBIT (utilidad operativa) | C13: =C11-C12 -> 206.931 | D13: =D11-D12 -> 309.483 | E13: =E11-E12 -> 451.056
A14: Gasto de intereses | C14: 84.867 | D14: 93.674 | E14: 84.679
A15: Participación en utilidades de afiliadas | C15: 66.719 | D15: 93.119 | E15: 90.033
A16: Ganancias (pérdidas) en inversiones | C16: 18.063 | D16: 50.84 | E16: 83.13
A17: Otros ingresos | C17: 54.501 | D17: -46.63 | E17: 6.961
A18: Utilidad antes de impuestos | C18: =C13-C14+C15+C16+C17 -> 261.347 | D18: =D13-D14+D15+D16+D17 -> 313.138 | E18: =E13-E14+E15+E16+E17 -> 546.501
A19: Impuestos | C19: 95.856 | D19: 120.604 | E19: 216.711
A20: Utilidad antes de interés minoritario | C20: =C18-C19 -> 165.491 | D20: =D18-D19 -> 192.534 | E20: =E18-E19 -> 329.79
A21: Interés minoritario | C21: 10.54 | D21: 13.044 | E21: 15.056
A22: Utilidad neta | C22: =C20-C21 -> 154.951 | D22: =D20-D21 -> 179.49 | E22: =E20-E21 -> 314.734
A24: Control: subtotales publicados en el Anexo 4 (PDF) | G24: Diferencia máx.
A25: Ingresos totales publicado | C25: 3030.8 | D25: 3473.2 | E25: 3946.3 | G25: =MAX(ABS(C25-C7),ABS(D25-D7),ABS(E25-E7)) -> 0.045 | H25: =IF(G25<0.06,"Cuadra (redondeo)","NO CUADRA") -> Cuadra (redondeo)
A26: EBITDA publicado | C26: 697 | D26: 865 | E26: 1033.3 | G26: =MAX(ABS(C26-C11),ABS(D26-D11),ABS(E26-E11)) -> 0.025 | H26: =IF(G26<0.06,"Cuadra (redondeo)","NO CUADRA") -> Cuadra (redondeo)
A27: EBIT (utilidad operativa) publicado | C27: 206.9 | D27: 309.5 | E27: 451.1 | G27: =MAX(ABS(C27-C13),ABS(D27-D13),ABS(E27-E13)) -> 0.044 | H27: =IF(G27<0.06,"Cuadra (redondeo)","NO CUADRA") -> Cuadra (redondeo)
A28: Utilidad antes de impuestos publicado | C28: 261.3 | D28: 313.1 | E28: 546.5 | G28: =MAX(ABS(C28-C18),ABS(D28-D18),ABS(E28-E18)) -> 0.047 | H28: =IF(G28<0.06,"Cuadra (redondeo)","NO CUADRA") -> Cuadra (redondeo)
A29: Utilidad antes de interés minoritario publicado | C29: 165.5 | D29: 192.5 | E29: 329.8 | G29: =MAX(ABS(C29-C20),ABS(D29-D20),ABS(E29-E20)) -> 0.034 | H29: =IF(G29<0.06,"Cuadra (redondeo)","NO CUADRA") -> Cuadra (redondeo)
A30: Utilidad neta publicado | C30: 155 | D30: 179.5 | E30: 314.7 | G30: =MAX(ABS(C30-C22),ABS(D30-D22),ABS(E30-E22)) -> 0.049 | H30: =IF(G30<0.06,"Cuadra (redondeo)","NO CUADRA") -> Cuadra (redondeo)
A31: Diferencia máxima de todos los subtotales del estado de resultados | G31: =MAX(G25:G30) -> 0.049
A33: B. Balance general (Anexo 5)
C34: 2005 | D34: 2006 | E34: 2007
A35: Caja y equivalentes | C35: 29.003 | D35: 32.912 | E35: 204.533
A36: Valores negociables | C36: 0 | D36: 249.039 | E36: 16.352
A37: Cuentas por cobrar | C37: 362.359 | D37: 407.438 | E37: 435.497
A38: Inventario | C38: 92.748 | D38: 117.189 | E38: 100.99
A39: Gastos prepagados | C39: 32.068 | D39: 34.955 | E39: 41.588
A40: Impuestos diferidos (activo corriente) | C40: 8.218 | D40: 0 | E40: 18.566
A41: Otros activos corrientes | C41: 15.489 | D41: 13.385 | E41: 16.227
A42: Total activos corrientes | C42: =SUM(C35:C41) -> 539.885 | D42: =SUM(D35:D41) -> 854.918 | E42: =SUM(E35:E41) -> 833.753
A43: Propiedad, planta y equipo | C43: 2553.029 | D43: 2628.848 | E43: 2595.096
...

Sheet Comparables
A1: Comparables inalámbricos (Anexo 7) y Tabla 3
A2: Unidades del Anexo 7 rotuladas como miles de US$; por magnitud parecen millones. Las razones no dependen de la unidad.
A4: Empresa | B4: Patrimonio de mercado | C4: Deuda neta | D4: D/V publicado | E4: D/P publicado | F4: Beta patrimonio | G4: Ingresos | H4: EBIT | I4: EBITDA | J4: Utilidad neta | K4: D/V calculado | L4: Margen EBIT | M4: Margen EBITDA | N4: Margen neto | O4: Valor empresa (VE) | P4: VE/EBITDA | Q4: VE/EBIT | R4: VE/Ingresos | S4: P/U | T4: D/P calculado
A5: Universal Mobile | B5: 118496.87 | C5: 69130 | D5: 0.36844404 | E5: 0.58339095 | F5: 0.86 | G5: 43882 | H5: 11795 | I5: 16949 | J5: 3794 | K5: =C5/(B5+C5) -> 0.36844404 | L5: =H5/G5 -> 0.26878903 | M5: =I5/G5 -> 0.38624037 | N5: =J5/G5 -> 0.08645914 | O5: =B5+C5 -> 187626.87 | P5: =O5/I5 -> 11.070085 | Q5: =O5/H5 -> 15.907322 | R5: =O5/G5 -> 4.2757137 | S5: =IF(J5>0,B5/J5,"n.s.") -> 31.232701 | T5: =C5/B5 -> 0.58339095
A6: Neuberger Wireless | B6: 189469.95 | C6: 79351.251 | D6: 0.29518227 | E6: 0.41880653 | F6: 0.89 | G6: 42684 | H6: 7020 | I6: 14099 | J6: 4102.8 | K6: =C6/(B6+C6) -> 0.29518227 | L6: =H6/G6 -> 0.16446444 | M6: =I6/G6 -> 0.33031112 | N6: =J6/G6 -> 0.096120326 | O6: =B6+C6 -> 268821.2 | P6: =O6/I6 -> 19.066686 | Q6: =O6/H6 -> 38.293618 | R6: =O6/G6 -> 6.2979383 | S6: =IF(J6>0,B6/J6,"n.s.") -> 46.180645 | T6: =C6/B6 -> 0.41880653
A7: Agile Connections | B7: 21078.873 | C7: 5080.0084 | D7: 0.19419823 | E7: 0.241 | F7: 1.17 | G7: 34698 | H7: 1631.2202 | I7: 9914 | J7: -29.742 | K7: =C7/(B7+C7) -> 0.19419823 | L7: =H7/G7 -> 0.047011937 | M7: =I7/G7 -> 0.28572252 | N7: =J7/G7 -> -0.00085716756 | O7: =B7+C7 -> 26158.881 | P7: =O7/I7 -> 2.6385799 | Q7: =O7/H7 -> 16.036389 | R7: =O7/G7 -> 0.75390171 | S7: =IF(J7>0,B7/J7,"n.s.") -> n.s. | T7: =C7/B7 -> 0.241
A8: Big Country Communications | B8: 26285.355 | C8: 8335.086 | D8: 0.24075621 | E8: 0.3171 | F8: 0.97 | G8: 38896.458 | H8: 6701.8597 | I8: 12614.121 | J8: 3383.9918 | K8: =C8/(B8+C8) -> 0.24075621 | L8: =H8/G8 -> 0.1723 | M8: =I8/G8 -> 0.3243 | N8: =J8/G8 -> 0.087 | O8: =B8+C8 -> 34620.441 | P8: =O8/I8 -> 2.7445781 | Q8: =O8/H8 -> 5.1657961 | R8: =O8/G8 -> 0.89006666 | S8: =IF(J8>0,B8/J8,"n.s.") -> 7.7675585 | T8: =C8/B8 -> 0.3171
A9: Rocky Mountain Wireless | B9: 7359.8993 | C9: 3267.7953 | D9: 0.30747922 | E9: 0.444 | F9: 1.13 | G9: 4063.519 | H9: 510.0529 | I9: 1028.4767 | J9: 239.74762 | K9: =C9/(B9+C9) -> 0.30747922 | L9: =H9/G9 -> 0.12552 | M9: =I9/G9 -> 0.2531 | N9: =J9/G9 -> 0.059 | O9: =B9+C9 -> 10627.695 | P9: =O9/I9 -> 10.333433 | Q9: =O9/H9 -> 20.836455 | R9: =O9/G9 -> 2.6153919 | S9: =IF(J9>0,B9/J9,"n.s.") -> 30.698529 | T9: =C9/B9 -> 0.444
A11: Promedio | D11: =AVERAGE(D5:D9) -> 0.28121199 | E11: =AVERAGE(E5:E9) -> 0.4008595 | F11: =AVERAGE(F5:F9) -> 1.004 | K11: =AVERAGE(K5:K9) -> 0.28121199 | L11: =AVERAGE(L5:L9) -> 0.15561708 | M11: =AVERAGE(M5:M9) -> 0.3159348 | N11: =AVERAGE(N5:N9) -> 0.06554446 | P11: =AVERAGE(P5:P9) -> 9.1706723 | Q11: =AVERAGE(Q5:Q9) -> 19.247916 | R11: =AVERAGE(R5:R9) -> 2.9666024 | S11: =AVERAGE(S5:S9) -> 28.969858 | T11: =AVERAGE(T5:T9) -> 0.4008595
A12: D/P promedio publicado (referencia para indicadores) | I12: =E11 -> 0.4008595
A13: Mediana | D13: =MEDIAN(D5:D9) -> 0.29518227 | E13: =MEDIAN(E5:E9) -> 0.41880653 | F13: =MEDIAN(F5:F9) -> 0.97 | K13: =MEDIAN(K5:K9) -> 0.29518227 | L13: =MEDIAN(L5:L9) -> 0.16446444 | M13: =MEDIAN(M5:M9) -> 0.3243 | N13: =MEDIAN(N5:N9) -> 0.08645914 | P13: =MEDIAN(P5:P9) -> 10.333433 | Q13: =MEDIAN(Q5:Q9) -> 16.036389 | R13: =MEDIAN(R5:R9) -> 2.6153919 | S13: =MEDIAN(S5:S9) -> 30.965615 | T13: =MEDIAN(T5:T9) -> 0.41880653
A14: Tabla 3 publicada (promedio de márgenes) | L14: 0.156 | M14: 0.316 | N14: 0.066
A15: Control: diferencia Tabla 3 vs. recalculado | L15: =L14-L11 -> 0.00038292034 | M15: =M14-M11 -> 6.5196892e-05 | N15: =N14-N11 -> 0.0004555402 | O15: =MAX(ABS(L15),ABS(M15),ABS(N15)) -> 0.0004555402
A16: Control: D/V publicado − calculado (máx.) | O16: =MAX(ABS(D5-K5),ABS(D6-K6),ABS(D7-K7),ABS(D8-K8),ABS(D9-K9)) -> 0
A17: Inconsistencia: D/P promedio publicado vs. D/P implícito en el D/V promedio | D17: =D11/(1-D11) -> 0.39123078 | E17: =E11 -> 0.4008595
A18: AirThread 2007 (Tabla 3: EBIT 11,4%, EBITDA 26,2%, neto 8,0%) | L18: =Historicos!E105 -> 0.1142995 | M18: =Historicos!E104 -> 0.26184893 | N18: =Historicos!E106 -> 0.079754928
A21: Betas desapalancadas por empresa
B22: E/V | C22: 1 Hamada (βd=0) | D22: 2 Harris-Pringle (βd=0) | E22: 3 Harris-Pringle (βd>0)
A23: =A5 -> Universal Mobile | B23: =1-K5 -> 0.63155596 | C23: =F5/(1+(1-Supuestos!$C$6)*T5) -> 0.63702072 | D23: =F5*B23 -> 0.54313813 | E23: =F5*B23+Costo_Capital!$C$7*K5 -> 0.63524914
A24: =A6 -> Neuberger Wireless | B24: =1-K6 -> 0.70481773 | C24: =F6/(1+(1-Supuestos!$C$6)*T6) -> 0.71126943 | D24: =F6*B24 -> 0.62728778 | E24: =F6*B24+Costo_Capital!$C$7*K6 -> 0.70108335
A25: =A7 -> Agile Connections | B25: =1-K7 -> 0.80580177 | C25: =F7/(1+(1-Supuestos!$C$6)*T7) -> 1.0221912 | D25: =F7*B25 -> 0.94278807 | E25: =F7*B25+Costo_Capital!$C$7*K7 -> 0.99133763
A26: =A8 -> Big Country Communications | B26: =1-K8 -> 0.75924379 | C26: =F8/(1+(1-Supuestos!$C$6)*T8) -> 0.81494799 | D26: =F8*B26 -> 0.73646648 | E26: =F8*B26+Costo_Capital!$C$7*K8 -> 0.79665553
A27: =A9 -> Rocky Mountain Wireless | B27: =1-K9 -> 0.69252078 | C27: =F9/(1+(1-Supuestos!$C$6)*T9) -> 0.89229311 | D27: =F9*B27 -> 0.78254848 | E27: =F9*B27+Costo_Capital!$C$7*K9 -> 0.85941828
A28: Promedio | B28: =AVERAGE(B23:B27) -> 0.71878801 | C28: =AVERAGE(C23:C27) -> 0.81554448 | D28: =AVERAGE(D23:D27) -> 0.72644579 | E28: =AVERAGE(E23:E27) -> 0.79674879
A29: Mediana | C29: =MEDIAN(C23:C27) -> 0.81494799 | D29: =MEDIAN(D23:D27) -> 0.73646648 | E29: =MEDIAN(E23:E27) -> 0.79665553
A30: Nota: se usan D/V y D/P calculados con deuda neta, como en el anexo; el anexo aclara que reflejan promedios de 3 años.

Sheet Costo_Capital
A1: Costo de capital: insumos, opciones y elección
A3: A. Insumos elegidos
A4: Tasa libre de riesgo (Tesoro 10 años) | C4: =Supuestos!$C$9 -> 0.0425
A5: Prima de riesgo de mercado | C5: =Supuestos!$C$10 -> 0.05
A6: Costo de la deuda antes de impuestos (Kd) | C6: =Supuestos!$C$7 -> 0.055
A7: Beta de la deuda implícita en el CAPM = (Kd − rf) / PRM | C7: =(C6-C4)/C5 -> 0.25 | H7: Kd = rf + βd × PRM ⇒ βd = 0,25. La deuda BBB+ tiene riesgo sistemático; ignorarlo subestima Ku.
A8: Tasa de impuestos | C8: =Supuestos!$C$6 -> 0.4
A9: Beta desapalancada (activos) según selector | C9: =CHOOSE(Supuestos!$C$22,Comparables!C28,Comparables!D28,Comparables!E28) -> 0.79674879
A10: Costo de capital no apalancado Ku = rf + βu × PRM | C10: =C4+C9*C5 -> 0.082337439
A11: Estructura objetivo D/V (post 2012, valor terminal) | C11: =CHOOSE(Supuestos!$C$23,Comparables!$D$11,Comparables!$D$13,Supuestos!$C$12) -> 0.28121199
A12: D/P objetivo = L / (1 − L) | C12: =C11/(1-C11) -> 0.39123078
A13: Beta de la deuda usada al reapalancar | C13: =IF(Supuestos!$C$22=3,C7,0) -> 0.25
A14: Beta del patrimonio reapalancada | C14: =IF(Supuestos!$C$22=1,C9*(1+(1-C8)*C12),C9+(C9-C13)*C12) -> 1.0106537
A15: Costo del patrimonio Ke = rf + βe × PRM | C15: =C4+C14*C5 -> 0.093032687
A16: CPPC (WACC) objetivo = E/V × Ke + D/V × Kd × (1 − t) | C16: =(1-C11)*C15+C11*C6*(1-C8) -> 0.076150776
A17: Control (solo Harris-Pringle): Ku − t × Kd × D/V | C17: =C10-C8*C6*C11 -> 0.076150776
A18: Prima por tamaño | C18: 0 | H18: El caso no da primas por tamaño, regulación ni país: se dejan en 0 (ver justificación en la sección B).
A19: Prima por riesgo regulatorio | C19: 0
A20: Prima por riesgo país | C20: 0
A22: B. Opciones defendibles por insumo y su efecto en el valor del patrimonio (millones de US$)
A23: Insumo / opción | C23: Valor | D23: Ku | E23: CPPC objetivo | F23: Patrimonio | G23: Δ vs. base | H23: Fuente / comentario
A24: Beta: 1 Hamada, βd = 0 | C24: =Comparables!$C$28 -> 0.81554448 | D24: =$C$4+C24*$C$5 -> 0.083277224 | E24: =(1-$C$11)*($C$4+C24*(1+(1-$C$8)*$C$12)*$C$5)+$C$11*$C$6*(1-$C$8) -> 0.076018893 | F24: =NPV(D24,Proyeccion!$D$28:$H$28)+Proyeccion!$H$40+Proyeccion!$I$28/((E24)-Proyeccion!$H$34)/(1+D24)^5+Valoracion!$C$20-Valoracion!$C$26 -> 6747.8895 | G24: =F24-Valoracion!$C$33 -> -10.454171 | H24: Supone deuda fija y sin riesgo; incoherente con Kd > rf.
A25: Beta: 2 Harris-Pringle, βd = 0 | C25: =Comparables!$D$28 -> 0.72644579 | D25: =$C$4+C25*$C$5 -> 0.078822289 | E25: =$C$4+C25*$C$5-$C$8*$C$6*$C$11 -> 0.072635626 | F25: =NPV(D25,Proyeccion!$D$28:$H$28)+Proyeccion!$H$40+Proyeccion!$I$28/((E25)-Proyeccion!$H$34)/(1+D25)^5+Valoracion!$C$20-Valoracion!$C$26 -> 7208.3436 | G25: =F25-Valoracion!$C$33 -> 449.9999 | H25: Deuda reequilibrada; ignora el riesgo de la deuda.
A26: Beta: 3 Harris-Pringle, βd = 0,25 (elegida) | C26: =Comparables!$E$28 -> 0.79674879 | D26: =$C$4+C26*$C$5 -> 0.082337439 | E26: =$C$4+C26*$C$5-$C$8*$C$6*$C$11 -> 0.076150776 | F26: =NPV(D26,Proyeccion!$D$28:$H$28)+Proyeccion!$H$40+Proyeccion!$I$28/((E26)-Proyeccion!$H$34)/(1+D26)^5+Valoracion!$C$20-Valoracion!$C$26 -> 6758.3437 | G26: =F26-Valoracion!$C$33 -> 0 | H26: Coherente con Kd = 5,5% y con un valor terminal a CPPC con deuda reequilibrada.
A27: PRM 4% (supuesto propio, sensibilidad) | C27: 0.04 | D27: =$C$4+C27*Comparables!$D$28+($C$6-$C$4)*(1-Comparables!$B$28) -> 0.075072981 | E27: =D27-$C$8*$C$6*$C$11 -> 0.068886318 | F27: =NPV(D27,Proyeccion!$D$28:$H$28)+Proyeccion!$H$40+Proyeccion!$I$28/((E27)-Proyeccion!$H$34)/(1+D27)^5+Valoracion!$C$20-Valoracion!$C$26 -> 7773.0706 | G27: =F27-Valoracion!$C$33 -> 1014.7269 | H27: El caso solo da 5%. Ku = rf + PRM × promedio(E/V × βe) + (Kd − rf) × D/V promedio (método 3).
A28: PRM 6% (supuesto propio, sensibilidad) | C28: 0.06 | D28: =$C$4+C28*Comparables!$D$28+($C$6-$C$4)*(1-Comparables!$B$28) -> 0.089601897 | E28: =D28-$C$8*$C$6*$C$11 -> 0.083415233 | F28: =NPV(D28,Proyeccion!$D$28:$H$28)+Proyeccion!$H$40+Proyeccion!$I$28/((E28)-Proyeccion!$H$34)/(1+D28)^5+Valoracion!$C$20-Valoracion!$C$26 -> 6008.3836 | G28: =F28-Valoracion!$C$33 -> -749.96013 | H28: Ídem.
A29: D/V objetivo: promedio comparables (elegida) | C29: =Comparables!$D$11 -> 0.28121199 | D29: =$C$10 -> 0.082337439 | E29: =$C$10-$C$8*$C$6*C29 -> 0.076150776 | F29: =NPV(D29,Proyeccion!$D$28:$H$28)+Proyeccion!$H$40+Proyeccion!$I$28/((E29)-Proyeccion!$H$34)/(1+D29)^5+Valoracion!$C$20-Valoracion!$C$26 -> 6758.3437 | G29: =F29-Valoracion!$C$33 -> 0 | H29: Anexo 7; el caso pide converger a la norma de la industria.
A30: D/V objetivo: mediana comparables | C30: =Comparables!$D$13 -> 0.29518227 | D30: =$C$10 -> 0.082337439 | E30: =$C$10-$C$8*$C$6*C30 -> 0.075843429 | F30: =NPV(D30,Proyeccion!$D$28:$H$28)+Proyeccion!$H$40+Proyeccion!$I$28/((E30)-Proyeccion!$H$34)/(1+D30)^5+Valoracion!$C$20-Valoracion!$C$26 -> 6787.5187 | G30: =F30-Valoracion!$C$33 -> 29.174965 | H30: Anexo 7.
A31: D/V objetivo: 50% (máximo de R&R) a perpetuidad | C31: =Supuestos!$C$12 -> 0.5 | D31: =$C$10 -> 0.082337439 | E31: =$C$10-$C$8*$C$6*C31 -> 0.071337439 | F31: =NPV(D31,Proyeccion!$D$28:$H$28)+Proyeccion!$H$40+Proyeccion!$I$28/((E31)-Proyeccion!$H$34)/(1+D31)^5+Valoracion!$C$20-Valoracion!$C$26 -> 7262.5416 | G31: =F31-Valoracion!$C$33 -> 504.19791 | H31: Agresivo: R&R lo plantea para la compra, no como estructura permanente.
A32: Primas por tamaño, regulación o país | C32: 0 | D32: =$C$10+C32 -> 0.082337439 | E32: =$C$16+C32 -> 0.076150776 | F32: =NPV(D32,Proyeccion!$D$28:$H$28)+Proyeccion!$H$40+Proyeccion!$I$28/((E32)-Proyeccion!$H$34)/(1+D32)^5+Valoracion!$C$20-Valoracion!$C$26 -> 6758.3437 | G32: =F32-Valoracion!$C$33 -> 0 | H32: No se suman: los comparables son operadores de EE. UU. con la misma regulación (FCC); el caso no da prima por tamaño.
A34: Variable decisiva: crecimiento a perpetuidad y método del valor terminal (ver hojas Sensibilidad y Valoracion).
A35: Moneda e inflación: flujos en US$ nominales; rf nominal en US$; el caso no da inflación. g nominal.
A36: Plazo de rf: 10 años, el único que da el caso; los flujos son perpetuos (un bono a 20-30 años sería más coherente).

Sheet Deuda
A1: Deuda de adquisición: préstamo amortizable a 10 años con pago bullet al mes 60 (Anexo 6)
A3: EBITDA 2007 | C3: =Historicos!E11 -> 1033.325 | E3: Anexo 6 publicado: deuda inicial 3.758, cuota 41, saldo antes del bullet 2.166.
A4: Intereses máximos = EBITDA / cobertura | C4: =C3/Supuestos!$C$11 -> 206.665
A5: Deuda inicial = intereses máximos / Kd | C5: =C4/Supuestos!$C$7 -> 3757.5455
A6: Cuota mensual (amortización a 120 meses) | C6: =PMT(Supuestos!$C$7/12,Supuestos!$C$13,-C5) -> 40.779242
A8: Mes | B8: Fecha | C8: Saldo inicial | D8: Cuota | E8: Interés | F8: Capital | G8: Pago bullet | H8: Saldo final | I8: Año | K8: Resumen anual | L8: 2008 | M8: 2009 | N8: 2010 | O8: 2011 | P8: 2012
A9: 1 | B9: =DATE(2008,A9+1,0) -> 39478 | C9: =C5 -> 3757.5455 | D9: =$C$6 -> 40.779242 | E9: =C9*Supuestos!$C$7/12 -> 17.222083 | F9: =D9-E9 -> 23.557159 | G9: =IF(A9=Supuestos!$C$14,C9-F9,0) -> 0 | H9: =C9-F9-G9 -> 3733.9883 | I9: =YEAR(B9) -> 2008 | K9: Intereses | L9: =SUMIF($I$9:$I$68,2008,$E$9:$E$68) -> 199.42896 | M9: =SUMIF($I$9:$I$68,2009,$E$9:$E$68) -> 183.07508 | N9: =SUMIF($I$9:$I$68,2010,$E$9:$E$68) -> 165.79872 | O9: =SUMIF($I$9:$I$68,2011,$E$9:$E$68) -> 147.54783 | P9: =SUMIF($I$9:$I$68,2012,$E$9:$E$68) -> 128.26745
A10: 2 | B10: =DATE(2008,A10+1,0) -> 39507 | C10: =H9 -> 3733.9883 | D10: =$C$6 -> 40.779242 | E10: =C10*Supuestos!$C$7/12 -> 17.114113 | F10: =D10-E10 -> 23.665129 | G10: =IF(A10=Supuestos!$C$14,C10-F10,0) -> 0 | H10: =C10-F10-G10 -> 3710.3232 | I10: =YEAR(B10) -> 2008 | K10: Amortización ordinaria de capital | L10: =SUMIF($I$9:$I$68,2008,$F$9:$F$68) -> 289.92195 | M10: =SUMIF($I$9:$I$68,2009,$F$9:$F$68) -> 306.27583 | N10: =SUMIF($I$9:$I$68,2010,$F$9:$F$68) -> 323.55219 | O10: =SUMIF($I$9:$I$68,2011,$F$9:$F$68) -> 341.80308 | P10: =SUMIF($I$9:$I$68,2012,$F$9:$F$68) -> 361.08346
A11: 3 | B11: =DATE(2008,A11+1,0) -> 39538 | C11: =H10 -> 3710.3232 | D11: =$C$6 -> 40.779242 | E11: =C11*Supuestos!$C$7/12 -> 17.005648 | F11: =D11-E11 -> 23.773594 | G11: =IF(A11=Supuestos!$C$14,C11-F11,0) -> 0 | H11: =C11-F11-G11 -> 3686.5496 | I11: =YEAR(B11) -> 2008 | K11: Pago bullet (refinanciado) | L11: =SUMIF($I$9:$I$68,2008,$G$9:$G$68) -> 0 | M11: =SUMIF($I$9:$I$68,2009,$G$9:$G$68) -> 0 | N11: =SUMIF($I$9:$I$68,2010,$G$9:$G$68) -> 0 | O11: =SUMIF($I$9:$I$68,2011,$G$9:$G$68) -> 0 | P11: =SUMIF($I$9:$I$68,2012,$G$9:$G$68) -> 2134.909
A12: 4 | B12: =DATE(2008,A12+1,0) -> 39568 | C12: =H11 -> 3686.5496 | D12: =$C$6 -> 40.779242 | E12: =C12*Supuestos!$C$7/12 -> 16.896686 | F12: =D12-E12 -> 23.882557 | G12: =IF(A12=Supuestos!$C$14,C12-F12,0) -> 0 | H12: =C12-F12-G12 -> 3662.667 | I12: =YEAR(B12) -> 2008 | K12: Saldo al cierre antes del bullet | L12: =INDEX($C$9:$C$68,12)-INDEX($F$9:$F$68,12) -> 3467.6235 | M12: =INDEX($C$9:$C$68,24)-INDEX($F$9:$F$68,24) -> 3161.3477 | N12: =INDEX($C$9:$C$68,36)-INDEX($F$9:$F$68,36) -> 2837.7955 | O12: =INDEX($C$9:$C$68,48)-INDEX($F$9:$F$68,48) -> 2495.9924 | P12: =INDEX($C$9:$C$68,60)-INDEX($F$9:$F$68,60) -> 2134.909
A13: 5 | B13: =DATE(2008,A13+1,0) -> 39599 | C13: =H12 -> 3662.667 | D13: =$C$6 -> 40.779242 | E13: =C13*Supuestos!$C$7/12 -> 16.787224 | F13: =D13-E13 -> 23.992018 | G13: =IF(A13=Supuestos!$C$14,C13-F13,0) -> 0 | H13: =C13-F13-G13 -> 3638.675 | I13: =YEAR(B13) -> 2008 | K13: Escudo fiscal = intereses × t | L13: =L9*Supuestos!$C$6 -> 79.771583 | M13: =M9*Supuestos!$C$6 -> 73.230033 | N13: =N9*Supuestos!$C$6 -> 66.319487 | O13: =O9*Supuestos!$C$6 -> 59.019132 | P13: =P9*Supuestos!$C$6 -> 51.30698
A14: 6 | B14: =DATE(2008,A14+1,0) -> 39629 | C14: =H13 -> 3638.675 | D14: =$C$6 -> 40.779242 | E14: =C14*Supuestos!$C$7/12 -> 16.67726 | F14: =D14-E14 -> 24.101982 | G14: =IF(A14=Supuestos!$C$14,C14-F14,0) -> 0 | H14: =C14-F14-G14 -> 3614.573 | I14: =YEAR(B14) -> 2008 | K14: Saldo publicado en el Anexo 6 | L14: 3468 | M14: 3161 | N14: 2838 | O14: 2496 | P14: 2166
A15: 7 | B15: =DATE(2008,A15+1,0) -> 39660 | C15: =H14 -> 3614.573 | D15: =$C$6 -> 40.779242 | E15: =C15*Supuestos!$C$7/12 -> 16.566793 | F15: =D15-E15 -> 24.212449 | G15: =IF(A15=Supuestos!$C$14,C15-F15,0) -> 0 | H15: =C15-F15-G15 -> 3590.3606 | I15: =YEAR(B15) -> 2008 | K15: Control: diferencia (fila 16 − fila 14) | L15: =L16-L14 -> -0.37649403 | M15: =M16-M14 -> 0.3476806 | N15: =N16-N14 -> -0.20450877 | O15: =O16-O14 -> -0.0075848637 | P15: =P16-P14 -> -0.23820713 | Q15: =MAX(ABS(L15),ABS(M15),ABS(N15),ABS(O15),ABS(P15)) -> 0.37649403
A16: 8 | B16: =DATE(2008,A16+1,0) -> 39691 | C16: =H15 -> 3590.3606 | D16: =$C$6 -> 40.779242 | E16: =C16*Supuestos!$C$7/12 -> 16.455819 | F16: =D16-E16 -> 24.323423 | G16: =IF(A16=Supuestos!$C$14,C16-F16,0) -> 0 | H16: =C16-F16-G16 -> 3566.0371 | I16: =YEAR(B16) -> 2008 | K16: Saldo comparable con el Anexo 6 (2012: inicio del mes 60) | L16: =INDEX($H$9:$H$68,12) -> 3467.6235 | M16: =INDEX($H$9:$H$68,24) -> 3161.3477 | N16: =INDEX($H$9:$H$68,36) -> 2837.7955 | O16: =INDEX($H$9:$H$68,48) -> 2495.9924 | P16: =INDEX($C$9:$C$68,60) -> 2165.7618
A17: 9 | B17: =DATE(2008,A17+1,0) -> 39721 | C17: =H16 -> 3566.0371 | D17: =$C$6 -> 40.779242 | E17: =C17*Supuestos!$C$7/12 -> 16.344337 | F17: =D17-E17 -> 24.434905 | G17: =IF(A17=Supuestos!$C$14,C17-F17,0) -> 0 | H17: =C17-F17-G17 -> 3541.6022 | I17: =YEAR(B17) -> 2008 | K17: Cobertura EBITDA 2007 / intereses del año 1 | L17: =C3/L9 -> 5.181419
A18: 10 | B18: =DATE(2008,A18+1,0) -> 39752 | C18: =H17 -> 3541.6022 | D18: =$C$6 -> 40.779242 | E18: =C18*Supuestos!$C$7/12 -> 16.232344 | F18: =D18-E18 -> 24.546899 | G18: =IF(A18=Supuestos!$C$14,C18-F18,0) -> 0 | H18: =C18-F18-G18 -> 3517.0553 | I18: =YEAR(B18) -> 2008 | K18: Nota: el Anexo 6 rotula 84 períodos restantes en el mes 41 (deberían ser 79); no afecta la cuota.
A19: 11 | B19: =DATE(2008,A19+1,0) -> 39782 | C19: =H18 -> 3517.0553 | D19: =$C$6 -> 40.779242 | E19: =C19*Supuestos!$C$7/12 -> 16.119837 | F19: =D19-E19 -> 24.659405 | G19: =IF(A19=Supuestos!$C$14,C19-F19,0) -> 0 | H19: =C19-F19-G19 -> 3492.3959 | I19: =YEAR(B19) -> 2008
A20: 12 | B20: =DATE(2008,A20+1,0) -> 39813 | C20: =H19 -> 3492.3959 | D20: =$C$6 -> 40.779242 | E20: =C20*Supuestos!$C$7/12 -> 16.006815 | F20: =D20-E20 -> 24.772428 | G20: =IF(A20=Supuestos!$C$14,C20-F20,0) -> 0 | H20: =C20-F20-G20 -> 3467.6235 | I20: =YEAR(B20) -> 2008
A21: 13 | B21: =DATE(2008,A21+1,0) -> 39844 | C21: =H20 -> 3467.6235 | D21: =$C$6 -> 40.779242 | E21: =C21*Supuestos!$C$7/12 -> 15.893274 | F21: =D21-E21 -> 24.885968 | G21: =IF(A21=Supuestos!$C$14,C21-F21,0) -> 0 | H21: =C21-F21-G21 -> 3442.7375 | I21: =YEAR(B21) -> 2009
A22: 14 | B22: =DATE(2008,A22+1,0) -> 39872 | C22: =H21 -> 3442.7375 | D22: =$C$6 -> 40.779242 | E22: =C22*Supuestos!$C$7/12 -> 15.779214 | F22: =D22-E22 -> 25.000029 | G22: =IF(A22=Supuestos!$C$14,C22-F22,0) -> 0 | H22: =C22-F22-G22 -> 3417.7375 | I22: =YEAR(B22) -> 2009
A23: 15 | B23: =DATE(2008,A23+1,0) -> 39903 | C23: =H22 -> 3417.7375 | D23: =$C$6 -> 40.779242 | E23: =C23*Supuestos!$C$7/12 -> 15.66463 | F23: =D23-E23 -> 25.114612 | G23: =IF(A23=Supuestos!$C$14,C23-F23,0) -> 0 | H23: =C23-F23-G23 -> 3392.6229 | I23: =YEAR(B23) -> 2009
A24: 16 | B24: =DATE(2008,A24+1,0) -> 39933 | C24: =H23 -> 3392.6229 | D24: =$C$6 -> 40.779242 | E24: =C24*Supuestos!$C$7/12 -> 15.549522 | F24: =D24-E24 -> 25.229721 | G24: =IF(A24=Supuestos!$C$14,C24-F24,0) -> 0 | H24: =C24-F24-G24 -> 3367.3932 | I24: =YEAR(B24) -> 2009
A25: 17 | B25: =DATE(2008,A25+1,0) -> 39964 | C25: =H24 -> 3367.3932 | D25: =$C$6 -> 40.779242 | E25: =C25*Supuestos!$C$7/12 -> 15.433885 | F25: =D25-E25 -> 25.345357 | G25: =IF(A25=Supuestos!$C$14,C25-F25,0) -> 0 | H25: =C25-F25-G25 -> 3342.0478 | I25: =YEAR(B25) -> 2009
A26: 18 | B26: =DATE(2008,A26+1,0) -> 39994 | C26: =H25 -> 3342.0478 | D26: =$C$6 -> 40.779242 | E26: =C26*Supuestos!$C$7/12 -> 15.317719 | F26: =D26-E26 -> 25.461523 | G26: =IF(A26=Supuestos!$C$14,C26-F26,0) -> 0 | H26: =C26-F26-G26 -> 3316.5863 | I26: =YEAR(B26) -> 2009
A27: 19 | B27: =DATE(2008,A27+1,0) -> 40025 | C27: =H26 -> 3316.5863 | D27: =$C$6 -> 40.779242 | E27: =C27*Supuestos!$C$7/12 -> 15.201021 | F27: =D27-E27 -> 25.578222 | G27: =IF(A27=Supuestos!$C$14,C27-F27,0) -> 0 | H27: =C27-F27-G27 -> 3291.0081 | I27: =YEAR(B27) -> 2009
A28: 20 | B28: =DATE(2008,A28+1,0) -> 40056 | C28: =H27 -> 3291.0081 | D28: =$C$6 -> 40.779242 | E28: =C28*Supuestos!$C$7/12 -> 15.083787 | F28: =D28-E28 -> 25.695455 | G28: =IF(A28=Supuestos!$C$14,C28-F28,0) -> 0 | H28: =C28-F28-G28 -> 3265.3126 | I28: =YEAR(B28) -> 2009
A29: 21 | B29: =DATE(2008,A29+1,0) -> 40086 | C29: =H28 -> 3265.3126 | D29: =$C$6 -> 40.779242 | E29: =C29*Supuestos!$C$7/12 -> 14.966016 | F29: =D29-E29 -> 25.813226 | G29: =IF(A29=Supuestos!$C$14,C29-F29,0) -> 0 | H29: =C29-F29-G29 -> 3239.4994 | I29: =YEAR(B29) -> 2009
A30: 22 | B30: =DATE(2008,A30+1,0) -> 40117 | C30: =H29 -> 3239.4994 | D30: =$C$6 -> 40.779242 | E30: =C30*Supuestos!$C$7/12 -> 14.847706 | F30: =D30-E30 -> 25.931537 | G30: =IF(A30=Supuestos!$C$14,C30-F30,0) -> 0 | H30: =C30-F30-G30 -> 3213.5679 | I30: =YEAR(B30) -> 2009
... A68: 60 | B68: =DATE(2008,A68+1,0) -> 41274 | C68: =H67 -> 2165.7618 | D68: =$C$6 -> 40.779242 | E68: =C68*Supuestos!$C$7/12 -> 9.9264082 | F68: =D68-E68 -> 30.852834 | G68: =IF(A68=Supuestos!$C$14,C68-F68,0) -> 2134.909 | H68: =C68-F68-G68 -> 0 | I68: =YEAR(B68) -> 2012

Sheet Proyeccion
A1: Proyección 2008-2012 sin sinergias y estados financieros proforma (millones de US$)
A3: Flujo de caja libre (escenario base)
A4: Año | C4: 2007 real | D4: 2008 | E4: 2009 | F4: 2010 | G4: 2011 | H4: 2012 | I4: 2013 normal.
A5: Ingresos por servicios | C5: =Historicos!$E$5 -> 3679.237 | D5: =C5*(1+D6) -> 4194.3302 | E5: =D5*(1+E6) -> 4781.5364 | F5: =E5*(1+F6) -> 5379.2285 | G5: =F5*(1+G6) -> 5917.1513 | H5: =G5*(1+H6) -> 6331.3519
A6: Crecimiento de ingresos por servicios | C6: =Historicos!$E$103 -> 0.14460725 | D6: =Supuestos!D$36+Supuestos!$C$63 -> 0.14 | E6: =Supuestos!E$36+Supuestos!$C$63 -> 0.14 | F6: =Supuestos!F$36+Supuestos!$C$63 -> 0.125 | G6: =Supuestos!G$36+Supuestos!$C$63 -> 0.1 | H6: =Supuestos!H$36+Supuestos!$C$63 -> 0.07
A7: Ingresos por equipos | C7: =Historicos!$E$6 -> 267.027 | D7: =D5*Supuestos!$C$45 -> 314.77315 | E7: =E5*Supuestos!$C$45 -> 358.84139 | F7: =F5*Supuestos!$C$45 -> 403.69657 | G7: =G5*Supuestos!$C$45 -> 444.06622 | H7: =H5*Supuestos!$C$45 -> 475.15086
A8: Ingresos totales | C8: =Historicos!$E$7 -> 3946.264 | D8: =D5+D7 -> 4509.1033 | E8: =E5+E7 -> 5140.3778 | F8: =F5+F7 -> 5782.925 | G8: =G5+G7 -> 6361.2175 | H8: =H5+H7 -> 6806.5027
A9: Costos de operación del sistema | C9: =Historicos!$E$8 -> 717.075 | D9: =D5*Supuestos!D$37 -> 838.86604 | E9: =E5*Supuestos!E$37 -> 956.30728 | F9: =F5*Supuestos!F$37 -> 1075.8457 | G9: =G5*Supuestos!G$37 -> 1183.4303 | H9: =H5*Supuestos!H$37 -> 1266.2704
A10: Costo de equipos vendidos | C10: =Historicos!$E$9 -> 640.225 | D10: =D7*Supuestos!D$38 -> 755.45556 | E10: =E7*Supuestos!E$38 -> 861.21934 | F10: =F7*Supuestos!F$38 -> 968.87176 | G10: =G7*Supuestos!G$38 -> 1065.7589 | H10: =H7*Supuestos!H$38 -> 1140.3621
A11: SG&A | C11: =Historicos!$E$10 -> 1555.639 | D11: =D8*(Supuestos!D$39+Supuestos!$C$64) -> 1803.6413 | E11: =E8*(Supuestos!E$39+Supuestos!$C$64) -> 2056.1511 | F11: =F8*(Supuestos!F$39+Supuestos!$C$64) -> 2313.17 | G11: =G8*(Supuestos!G$39+Supuestos!$C$64) -> 2544.487 | H11: =H8*(Supuestos!H$39+Supuestos!$C$64) -> 2722.6011
A12: EBITDA | C12: =Historicos!$E$11 -> 1033.325 | D12: =D8-D9-D10-D11 -> 1111.1404 | E12: =E8-E9-E10-E11 -> 1266.7001 | F12: =F8-F9-F10-F11 -> 1425.0376 | G12: =G8-G9-G10-G11 -> 1567.5413 | H12: =H8-H9-H10-H11 -> 1677.2692
A13: Margen EBITDA | C13: =C12/C8 -> 0.26184893 | D13: =D12/D8 -> 0.24642159 | E13: =E12/E8 -> 0.24642159 | F13: =F12/F8 -> 0.24642159 | G13: =G12/G8 -> 0.24642159 | H13: =H12/H8 -> 0.24642159
A14: Depreciación y amortización | C14: =Historicos!$E$12 -> 582.269 | D14: =D8*Supuestos!D$42 -> 705.22932 | E14: =E8*Supuestos!E$42 -> 803.96142 | F14: =F8*Supuestos!F$42 -> 867.43875 | G14: =G8*Supuestos!G$42 -> 922.37654 | H14: =H8*Supuestos!H$42 -> 952.91038
A15: EBIT | C15: =Historicos!$E$13 -> 451.056 | D15: =D12-D14 -> 405.91108 | E15: =E12-E14 -> 462.73863 | F15: =F12-F14 -> 557.59881 | G15: =G12-G14 -> 645.16478 | H15: =H12-H14 -> 724.35883
A16: Impuestos operativos (EBIT × t) | D16: =D15*Supuestos!$C$6 -> 162.36443 | E16: =E15*Supuestos!$C$6 -> 185.09545 | F16: =F15*Supuestos!$C$6 -> 223.03952 | G16: =G15*Supuestos!$C$6 -> 258.06591 | H16: =H15*Supuestos!$C$6 -> 289.74353
A17: Utilidad operativa después de impuestos (NOPAT) | D17: =D15-D16 -> 243.54665 | E17: =E15-E16 -> 277.64318 | F17: =F15-F16 -> 334.55929 | G17: =G15-G16 -> 387.09887 | H17: =H15-H16 -> 434.6153 | I17: =H17*(1+H34) -> 446.69807
A18: Costos operativos en efectivo | C18: =C9+C10+C11 -> 2912.939 | D18: =D9+D10+D11 -> 3397.9629 | E18: =E9+E10+E11 -> 3873.6777 | F18: =F9+F10+F11 -> 4357.8875 | G18: =G9+G10+G11 -> 4793.6762 | H18: =H9+H10+H11 -> 5129.2335
A19: Cuentas por cobrar | C19: =Historicos!$E$37 -> 435.497 | D19: =D8*Supuestos!$C$46/360 -> 521.89513 | E19: =E8*Supuestos!$C$46/360 -> 594.96044 | F19: =F8*Supuestos!$C$46/360 -> 669.3305 | G19: =G8*Supuestos!$C$46/360 -> 736.26355 | H19: =H8*Supuestos!$C$46/360 -> 787.802
A20: Inventario | C20: =Historicos!$E$38 -> 100.99 | D20: =D7*Supuestos!$C$47/360 -> 134.96792 | E20: =E7*Supuestos!$C$47/360 -> 153.86343 | F20: =F7*Supuestos!$C$47/360 -> 173.09635 | G20: =G7*Supuestos!$C$47/360 -> 190.40599 | H20: =H7*Supuestos!$C$47/360 -> 203.73441
A21: Gastos prepagados | C21: =Historicos!$E$39 -> 41.588 | D21: =D18*Supuestos!$C$48 -> 46.914828 | E21: =E18*Supuestos!$C$48 -> 53.482904 | F21: =F18*Supuestos!$C$48 -> 60.168267 | G21: =G18*Supuestos!$C$48 -> 66.185093 | H21: =H18*Supuestos!$C$48 -> 70.81805
A22: Cuentas por pagar | C22: =Historicos!$E$52 -> 260.791 | D22: =D18*Supuestos!$C$49/360 -> 335.42132 | E22: =E18*Supuestos!$C$49/360 -> 382.3803 | F22: =F18*Supuestos!$C$49/360 -> 430.17784 | G22: =G18*Supuestos!$C$49/360 -> 473.19563 | H22: =H18*Supuestos!$C$49/360 -> 506.31932
A23: Ingresos diferidos | C23: =Historicos!$E$53 -> 143.445 | D23: =D5*Supuestos!$C$50/360 -> 163.25425 | E23: =E5*Supuestos!$C$50/360 -> 186.10984 | F23: =F5*Supuestos!$C$50/360 -> 209.37357 | G23: =G5*Supuestos!$C$50/360 -> 230.31093 | H23: =H5*Supuestos!$C$50/360 -> 246.43269
A24: Pasivos acumulados | C24: =Historicos!$E$54 -> 59.224 | D24: =D18*Supuestos!$C$51/360 -> 64.60904 | E24: =E18*Supuestos!$C$51/360 -> 73.654305 | F24: =F18*Supuestos!$C$51/360 -> 82.861094 | G24: =G18*Supuestos!$C$51/360 -> 91.147203 | H24: =H18*Supuestos!$C$51/360 -> 97.527507
A25: Capital de trabajo operativo neto | C25: =C19+C20+C21-C22-C23-C24 -> 114.615 | D25: =D19+D20+D21-D22-D23-D24 -> 140.49327 | E25: =E19+E20+E21-E22-E23-E24 -> 160.16232 | F25: =F19+F20+F21-F22-F23-F24 -> 180.18261 | G25: =G19+G20+G21-G22-G23-G24 -> 198.20087 | H25: =H19+H20+H21-H22-H23-H24 -> 212.07494
A26: Aumento del capital de trabajo operativo neto | D26: =D25-C25 -> 25.878265 | E26: =E25-D25 -> 19.669057 | F26: =F25-E25 -> 20.02029 | G26: =G25-F25 -> 18.018261 | H26: =H25-G25 -> 13.874061
A27: Capex | D27: =D8*(Supuestos!D$41+Supuestos!$C$65) -> 631.27447 | E27: =E8*(Supuestos!E$41+Supuestos!$C$65) -> 719.65289 | F27: =F8*(Supuestos!F$41+Supuestos!$C$65) -> 867.43875 | G27: =G8*(Supuestos!G$41+Supuestos!$C$65) -> 970.08567 | H27: =H8*(Supuestos!H$41+Supuestos!$C$65) -> 1055.0079
A28: Flujo de caja libre no apalancado | D28: =D17+D14-D27-D26 -> 291.62324 | E28: =E17+E14-E27-E26 -> 342.28266 | F28: =F17+F14-F27-F26 -> 314.539 | G28: =G17+G14-G27-G26 -> 321.37148 | H28: =H17+H14-H27-H26 -> 318.6437 | I28: =I17*(1-H35) -> 327.50233
A29: Capital invertido contable (patrimonio + deuda) | C29: =Historicos!$E$90+Historicos!$E$62+Historicos!$E$57 -> 4198.449 | D29: =C29+D27-D14+D26 -> 4150.3724 | E29: =D29+E27-E14+E26 -> 4085.7329 | F29: =E29+F27-F14+F26 -> 4105.7532 | G29: =F29+G27-G14+G26 -> 4171.4806 | H29: =G29+H27-H14+H26 -> 4287.4522
A30: ROIC (NOPAT / capital invertido al inicio del año) | D30: =D17/C29 -> 0.058008719 | E30: =E17/D29 -> 0.066895968 | F30: =F17/E29 -> 0.081884766 | G30: =G17/F29 -> 0.094282059 | H30: =H17/G29 -> 0.1041873
A31: Tasa de reinversión = (capex − D&A + Δ capital de trabajo) / NOPAT | D31: =(D27-D14+D26)/D17 -> -0.19740197 | E31: =(E27-E14+E26)/E17 -> -0.23281492 | F31: =(F27-F14+F26)/F17 -> 0.059840785 | G31: =(G27-G14+G26)/G17 -> 0.16979485 | H31: =(H27-H14+H26)/H17 -> 0.26683737
A33: Crecimiento fundamental = ROIC 2012 × tasa de reinversión 2012 | H33: =H30*H31 -> 0.027801065
A34: Crecimiento a perpetuidad usado (g) | H34: =IF(Supuestos!$C$24=1,H33,Supuestos!$C$25) -> 0.027801065
A35: Tasa de reinversión de largo plazo = g / ROIC 2012 | H35: =H34/H30 -> 0.26683737
A36: Valor terminal 2012 = FCF 2013 / (CPPC − g) | H36: =I28/(Costo_Capital!$C$16-H34) -> 6773.615
A37: Valor terminal 2012 por múltiplo VE/EBITDA (contraste) | H37: =H12*IF(Supuestos!$C$26=1,Comparables!$P$11,Comparables!$P$13) -> 17331.949
A38: VP de los FCF 2008-2012 a Ku | H38: =NPV(Costo_Capital!$C$10,D28:H28) -> 1258.417
A39: VP del valor terminal a Ku | H39: =H36/(1+Costo_Capital!$C$10)^5 -> 4560.4438
A40: VP de los escudos fiscales 2008-2012 a Kd | H40: =NPV(Supuestos!$C$7,Deuda!$L$13:$P$13) -> 284.78312
A41: Valor de las operaciones (APV) | H41: =H38+H39+H40 -> 6103.6439
A42: + Activos no operativos | H42: =Valoracion!$C$20 -> 1944.4871
...

Sheet Sinergias
A1: Sinergias con American Cable (Tablas 4 y 5), millones de US$
C3: 2007 | D3: 2008 | E3: 2009 | F3: 2010 | G3: 2011 | H3: 2012 | I3: 2013
A4: Costos de operación del sistema (sin sinergias) | D4: =Proyeccion!D9 -> 838.86604 | E4: =Proyeccion!E9 -> 956.30728 | F4: =Proyeccion!F9 -> 1075.8457 | G4: =Proyeccion!G9 -> 1183.4303 | H4: =Proyeccion!H9 -> 1266.2704
A5: Backhaul / costos del sistema | D5: =Supuestos!D$55 -> 0.2 | E5: =Supuestos!E$55 -> 0.2 | F5: =Supuestos!F$55 -> 0.2 | G5: =Supuestos!G$55 -> 0.2 | H5: =Supuestos!H$55 -> 0.2
A6: Costo estimado de backhaul | D6: =D4*D5 -> 167.77321 | E6: =E4*E5 -> 191.26146 | F6: =F4*F5 -> 215.16914 | G6: =G4*G5 -> 236.68605 | H6: =H4*H5 -> 253.25408
A7: Reducción del costo de backhaul | D7: =Supuestos!D$56 -> 0 | E7: =Supuestos!E$56 -> 0.07 | F7: =Supuestos!F$56 -> 0.12 | G7: =Supuestos!G$56 -> 0.222 | H7: =Supuestos!H$56 -> 0.3
A8: Ahorro de backhaul (antes de impuestos) | D8: =D6*D7 -> 0 | E8: =E6*E7 -> 13.388302 | F8: =F6*F7 -> 25.820297 | G8: =G6*G7 -> 52.544304 | H8: =H6*H7 -> 75.976223
A10: Suscriptores empresariales promedio (millones) | D10: =Supuestos!D$57 -> 0.3 | E10: =Supuestos!E$57 -> 0.5 | F10: =Supuestos!F$57 -> 0.7 | G10: =Supuestos!G$57 -> 1 | H10: =Supuestos!H$57 -> 1.2
A11: Minutos mensuales por suscriptor | D11: =Supuestos!D$58 -> 859 | E11: =Supuestos!E$58 -> 885 | F11: =Supuestos!F$58 -> 911 | G11: =Supuestos!G$58 -> 939 | H11: =Supuestos!H$58 -> 967
A12: Minutos mensuales totales (millones) | D12: =D10*D11 -> 257.7 | E12: =E10*E11 -> 442.5 | F12: =F10*F11 -> 637.7 | G12: =G10*G11 -> 939 | H12: =H10*H11 -> 1160.4
A13: Ingreso por minuto (US$) | D13: =Supuestos!D$59 -> 0.0506 | E13: =Supuestos!E$59 -> 0.0506 | F13: =Supuestos!F$59 -> 0.0506 | G13: =Supuestos!G$59 -> 0.0506 | H13: =Supuestos!H$59 -> 0.0506
A14: Ingreso anual adicional por clientes empresariales | D14: =D12*D13*12 -> 156.47544 | E14: =E12*E13*12 -> 268.686 | F14: =F12*F13*12 -> 387.21144 | G14: =G12*G13*12 -> 570.1608 | H14: =H12*H13*12 -> 704.59488
A15: Margen EBITDA aplicado a los ingresos adicionales (selector) | D15: =IF(Supuestos!$C$28=1,Proyeccion!D13,1-Supuestos!D$37-Supuestos!D$39) -> 0.24642159 | E15: =IF(Supuestos!$C$28=1,Proyeccion!E13,1-Supuestos!E$37-Supuestos!E$39) -> 0.24642159 | F15: =IF(Supuestos!$C$28=1,Proyeccion!F13,1-Supuestos!F$37-Supuestos!F$39) -> 0.24642159 | G15: =IF(Supuestos!$C$28=1,Proyeccion!G13,1-Supuestos!G$37-Supuestos!G$39) -> 0.24642159 | H15: =IF(Supuestos!$C$28=1,Proyeccion!H13,1-Supuestos!H$37-Supuestos!H$39) -> 0.24642159
A16: EBITDA adicional por clientes empresariales | D16: =D14*D15 -> 38.558926 | E16: =E14*E15 -> 66.210031 | F16: =F14*F15 -> 95.417258 | G16: =G14*G15 -> 140.49993 | H16: =H14*H15 -> 173.62739
A18: Sinergias totales antes de impuestos | D18: =D8+D16 -> 38.558926 | E18: =E8+E16 -> 79.598333 | F18: =F8+F16 -> 121.23755 | G18: =G8+G16 -> 193.04423 | H18: =H8+H16 -> 249.60361
A19: Sinergias después de impuestos | D19: =D18*(1-Supuestos!$C$6) -> 23.135356 | E19: =E18*(1-Supuestos!$C$6) -> 47.759 | F19: =F18*(1-Supuestos!$C$6) -> 72.742533 | G19: =G18*(1-Supuestos!$C$6) -> 115.82654 | H19: =H18*(1-Supuestos!$C$6) -> 149.76217
A20: Sinergias después de impuestos × % realizado | D20: =D19*Supuestos!$C$30 -> 23.135356 | E20: =E19*Supuestos!$C$30 -> 47.759 | F20: =F19*Supuestos!$C$30 -> 72.742533 | G20: =G19*Supuestos!$C$30 -> 115.82654 | H20: =H19*Supuestos!$C$30 -> 149.76217
A22: Valoración (descontadas a Ku; perpetuidad desde 2013 creciendo a g, sin inversión adicional)
C23: Backhaul | D23: Ingresos | E23: Total
A24: VP de los flujos 2008-2012 | C24: =NPV(Costo_Capital!$C$10,D8:H8)*(1-Supuestos!$C$6)*Supuestos!$C$30 -> 72.740721 | D24: =NPV(Costo_Capital!$C$10,D16:H16)*(1-Supuestos!$C$6)*Supuestos!$C$30 -> 232.00833 | E24: =C24+D24 -> 304.74905
A25: VP del valor terminal | C25: =H8*(1-Supuestos!$C$6)*Supuestos!$C$30*(1+Proyeccion!$H$34)/(Costo_Capital!$C$10-Proyeccion!$H$34)/(1+Costo_Capital!$C$10)^5 -> 578.41339 | D25: =H16*(1-Supuestos!$C$6)*Supuestos!$C$30*(1+Proyeccion!$H$34)/(Costo_Capital!$C$10-Proyeccion!$H$34)/(1+Costo_Capital!$C$10)^5 -> 1321.84 | E25: =C25+D25 -> 1900.2534
A26: Valor presente de las sinergias | C26: =C24+C25 -> 651.15411 | D26: =D24+D25 -> 1553.8483 | E26: =E24+E25 -> 2205.0024
A27: Control: total = VP de la fila 'sinergias × % realizado' + valor terminal | E27: =E26-(NPV(Costo_Capital!$C$10,D20:H20)+H20*(1+Proyeccion!$H$34)/(Costo_Capital!$C$10-Proyeccion!$H$34)/(1+Costo_Capital!$C$10)^5) -> 0
A28: VP de las sinergias con 100% de realización (para sensibilidad) | E28: =NPV(Costo_Capital!$C$10,D19:H19)+H19*(1+Proyeccion!$H$34)/(Costo_Capital!$C$10-Proyeccion!$H$34)/(1+Costo_Capital!$C$10)^5 -> 2205.0024
A30: Supuestos propios: (1) el caso solo da ingresos empresariales, no su margen; base = margen EBITDA proyectado de ATC;
A31: (2) no se asume capex ni capital de trabajo adicional (el caso dice que el negocio empresarial usa capacidad ociosa de la red);
A32: (3) ambos tipos de sinergia se descuentan a Ku; las de ingresos son más inciertas, por eso se muestran por separado;
A33: (4) los costos de integración no aparecen en el caso y no se incluyen (sesgo al alza del valor de las sinergias).

Sheet Valoracion
A1: Valoración de AirThread: APV (método de American Cable) y contrastes (millones de US$)
A3: A. Valor de las operaciones (APV, sin sinergias)
A5: Costo de capital no apalancado (Ku) | C5: =Costo_Capital!$C$10 -> 0.082337439
A6: CPPC objetivo para el valor terminal | C6: =Costo_Capital!$C$16 -> 0.076150776
A7: Crecimiento a perpetuidad (g) | C7: =Proyeccion!$H$34 -> 0.027801065
A8: VP de los flujos libres 2008-2012 | C8: =Proyeccion!$H$38 -> 1258.417
A9: VP del valor terminal (perpetuidad) | C9: =Proyeccion!$H$39 -> 4560.4438
A10: VP de los escudos fiscales de la deuda de adquisición 2008-2012 | C10: =Proyeccion!$H$40 -> 284.78312
A11: Valor de las operaciones (APV) | C11: =Proyeccion!$H$41 -> 6103.6439
A12: Valor terminal / valor de las operaciones | C12: =C9/C11 -> 0.7471674
A14: B. Activos no operativos y otros derechos
A15: Caja y valores negociables 2007 | C15: =Historicos!$E$35+Historicos!$E$36 -> 220.885 | H15: Caso, p. 6: probablemente se usarán para financiar la compra. Se suma completa.
A16: Participación en utilidades de afiliadas 2007 | C16: =Historicos!$E$15 -> 90.033 | H16: Anexo 4.
A17: Valor de las afiliadas | C17: =IF(Supuestos!$C$27=1,C16*Supuestos!$C$15,Historicos!$E$47) -> 1719.1801 | H17: Base: P/U de la industria × utilidad (caso, nota 3). Alternativa: valor en libros (157,7).
A18: Nota por cobrar de largo plazo | C18: =Historicos!$E$48 -> 4.422 | H18: Anexo 5, a valor en libros.
A19: Títulos de renta variable negociables | C19: =Historicos!$E$46 -> 0 | H19: Anexo 5 (cero en 2007).
A20: Total activos no operativos | C20: =C15+C17+C18+C19 -> 1944.4871
A22: Deuda existente (largo plazo + pagaré), se refinancia | C22: =Historicos!$E$62+Historicos!$E$57 -> 1002.293 | H22: Anexo 5.
A23: Interés minoritario en resultados 2007 | C23: =Historicos!$E$21 -> 15.056 | H23: Anexo 4.
A24: Valor del interés minoritario | C24: =IF(Supuestos!$C$27=1,C23*Supuestos!$C$15,Historicos!$E$68) -> 287.49432 | H24: Coherente con afiliadas: P/U de la industria. Alternativa: libros (43,4).
A26: Total deuda e interés minoritario | C26: =C22+C24 -> 1289.7873
A28: C. Valor del patrimonio
A29: Valor de las operaciones (APV) | C29: =C11 -> 6103.6439
A30: + Activos no operativos | C30: =C20 -> 1944.4871
A31: Valor total de la empresa | C31: =C29+C30 -> 8048.131
A32: − Deuda existente e interés minoritario | C32: =C26 -> 1289.7873
A33: Valor del patrimonio, 100%, sin sinergias (valor intrínseco independiente) | C33: =C31-C32 -> 6758.3437
A34: Descuento por iliquidez aplicado | C34: =Supuestos!$C$29 -> 0
A35: Valor del patrimonio después del descuento | C35: =C33*(1-C34) -> 6758.3437
A36: + VP sinergias de backhaul | C36: =Sinergias!$C$26 -> 651.15411
A37: + VP sinergias de ingresos empresariales | C37: =Sinergias!$D$26 -> 1553.8483
A38: Valor del patrimonio con todas las sinergias | C38: =C35+C36+C37 -> 8963.3461
A39: Control: bloque de la hoja Proyeccion − fila 33 | C39: =Proyeccion!$H$44-C33 -> 0
A41: D. Contrastes
A42: Valor terminal por múltiplo VE/EBITDA de comparables (2012) | C42: =Proyeccion!$H$37 -> 17331.949
A43: Múltiplo VE/EBITDA usado | C43: =IF(Supuestos!$C$26=1,Comparables!$P$11,Comparables!$P$13) -> 10.333433
A44: Múltiplo VE/EBITDA 2012 implícito en el valor terminal por perpetuidad | C44: =Proyeccion!$H$36/Proyeccion!H12 -> 4.0384781
A45: Valor de las operaciones con valor terminal por múltiplo | C45: =C8+C10+C42/(1+C5)^5 -> 13212.21
A46: Patrimonio con valor terminal por múltiplo (sin sinergias) | C46: =C45+C30-C32 -> 13866.909
A47: Crecimiento implícito en el múltiplo (resuelve VT = NOPAT₂₀₁₂(1+g)(1−g/ROIC)/(CPPC−g)) | C47: =(-F47-SQRT(F47^2-4*E47*D47))/(2*E47) -> 0.066469351 | D47: =C42*C6-Proyeccion!$H$17 -> 885.22606 | E47: =Proyeccion!$H$17/Proyeccion!$H$30 -> 4171.4806 | F47: =-(C42+Proyeccion!$H$17-Proyeccion!$H$17/Proyeccion!$H$30) -> -13595.084 | H47: Celdas D-F: coeficientes c, a, b de la cuadrática.
...

Sheet Escenarios
A1: Escenarios de riesgo: el mismo bloque de cálculo con ajustes (millones de US$)
A3: Escenario: Base
A4: Año | C4: 2007 real | D4: 2008 | E4: 2009 | F4: 2010 | G4: 2011 | H4: 2012 | I4: 2013 normal.
A5: Ingresos por servicios | C5: =Historicos!$E$5 -> 3679.237 | D5: =C5*(1+D6) -> 4194.3302 | E5: =D5*(1+E6) -> 4781.5364 | F5: =E5*(1+F6) -> 5379.2285 | G5: =F5*(1+G6) -> 5917.1513 | H5: =G5*(1+H6) -> 6331.3519
A6: Crecimiento de ingresos por servicios | C6: =Historicos!$E$103 -> 0.14460725 | D6: =Supuestos!D$36+Supuestos!$C$63 -> 0.14 | E6: =Supuestos!E$36+Supuestos!$C$63 -> 0.14 | F6: =Supuestos!F$36+Supuestos!$C$63 -> 0.125 | G6: =Supuestos!G$36+Supuestos!$C$63 -> 0.1 | H6: =Supuestos!H$36+Supuestos!$C$63 -> 0.07
A7: Ingresos por equipos | C7: =Historicos!$E$6 -> 267.027 | D7: =D5*Supuestos!$C$45 -> 314.77315 | E7: =E5*Supuestos!$C$45 -> 358.84139 | F7: =F5*Supuestos!$C$45 -> 403.69657 | G7: =G5*Supuestos!$C$45 -> 444.06622 | H7: =H5*Supuestos!$C$45 -> 475.15086
A8: Ingresos totales | C8: =Historicos!$E$7 -> 3946.264 | D8: =D5+D7 -> 4509.1033 | E8: =E5+E7 -> 5140.3778 | F8: =F5+F7 -> 5782.925 | G8: =G5+G7 -> 6361.2175 | H8: =H5+H7 -> 6806.5027
A9: Costos de operación del sistema | C9: =Historicos!$E$8 -> 717.075 | D9: =D5*Supuestos!D$37 -> 838.86604 | E9: =E5*Supuestos!E$37 -> 956.30728 | F9: =F5*Supuestos!F$37 -> 1075.8457 | G9: =G5*Supuestos!G$37 -> 1183.4303 | H9: =H5*Supuestos!H$37 -> 1266.2704
A10: Costo de equipos vendidos | C10: =Historicos!$E$9 -> 640.225 | D10: =D7*Supuestos!D$38 -> 755.45556 | E10: =E7*Supuestos!E$38 -> 861.21934 | F10: =F7*Supuestos!F$38 -> 968.87176 | G10: =G7*Supuestos!G$38 -> 1065.7589 | H10: =H7*Supuestos!H$38 -> 1140.3621
A11: SG&A | C11: =Historicos!$E$10 -> 1555.639 | D11: =D8*(Supuestos!D$39+Supuestos!$C$64) -> 1803.6413 | E11: =E8*(Supuestos!E$39+Supuestos!$C$64) -> 2056.1511 | F11: =F8*(Supuestos!F$39+Supuestos!$C$64) -> 2313.17 | G11: =G8*(Supuestos!G$39+Supuestos!$C$64) -> 2544.487 | H11: =H8*(Supuestos!H$39+Supuestos!$C$64) -> 2722.6011
A12: EBITDA | C12: =Historicos!$E$11 -> 1033.325 | D12: =D8-D9-D10-D11 -> 1111.1404 | E12: =E8-E9-E10-E11 -> 1266.7001 | F12: =F8-F9-F10-F11 -> 1425.0376 | G12: =G8-G9-G10-G11 -> 1567.5413 | H12: =H8-H9-H10-H11 -> 1677.2692
A13: Margen EBITDA | C13: =C12/C8 -> 0.26184893 | D13: =D12/D8 -> 0.24642159 | E13: =E12/E8 -> 0.24642159 | F13: =F12/F8 -> 0.24642159 | G13: =G12/G8 -> 0.24642159 | H13: =H12/H8 -> 0.24642159
A14: Depreciación y amortización | C14: =Historicos!$E$12 -> 582.269 | D14: =D8*Supuestos!D$42 -> 705.22932 | E14: =E8*Supuestos!E$42 -> 803.96142 | F14: =F8*Supuestos!F$42 -> 867.43875 | G14: =G8*Supuestos!G$42 -> 922.37654 | H14: =H8*Supuestos!H$42 -> 952.91038
A15: EBIT | C15: =Historicos!$E$13 -> 451.056 | D15: =D12-D14 -> 405.91108 | E15: =E12-E14 -> 462.73863 | F15: =F12-F14 -> 557.59881 | G15: =G12-G14 -> 645.16478 | H15: =H12-H14 -> 724.35883
A16: Impuestos operativos (EBIT × t) | D16: =D15*Supuestos!$C$6 -> 162.36443 | E16: =E15*Supuestos!$C$6 -> 185.09545 | F16: =F15*Supuestos!$C$6 -> 223.03952 | G16: =G15*Supuestos!$C$6 -> 258.06591 | H16: =H15*Supuestos!$C$6 -> 289.74353
A17: Utilidad operativa después de impuestos (NOPAT) | D17: =D15-D16 -> 243.54665 | E17: =E15-E16 -> 277.64318 | F17: =F15-F16 -> 334.55929 | G17: =G15-G16 -> 387.09887 | H17: =H15-H16 -> 434.6153 | I17: =H17*(1+H34) -> 446.69807
A18: Costos operativos en efectivo | C18: =C9+C10+C11 -> 2912.939 | D18: =D9+D10+D11 -> 3397.9629 | E18: =E9+E10+E11 -> 3873.6777 | F18: =F9+F10+F11 -> 4357.8875 | G18: =G9+G10+G11 -> 4793.6762 | H18: =H9+H10+H11 -> 5129.2335
A19: Cuentas por cobrar | C19: =Historicos!$E$37 -> 435.497 | D19: =D8*Supuestos!$C$46/360 -> 521.89513 | E19: =E8*Supuestos!$C$46/360 -> 594.96044 | F19: =F8*Supuestos!$C$46/360 -> 669.3305 | G19: =G8*Supuestos!$C$46/360 -> 736.26355 | H19: =H8*Supuestos!$C$46/360 -> 787.802
A20: Inventario | C20: =Historicos!$E$38 -> 100.99 | D20: =D7*Supuestos!$C$47/360 -> 134.96792 | E20: =E7*Supuestos!$C$47/360 -> 153.86343 | F20: =F7*Supuestos!$C$47/360 -> 173.09635 | G20: =G7*Supuestos!$C$47/360 -> 190.40599 | H20: =H7*Supuestos!$C$47/360 -> 203.73441
A21: Gastos prepagados | C21: =Historicos!$E$39 -> 41.588 | D21: =D18*Supuestos!$C$48 -> 46.914828 | E21: =E18*Supuestos!$C$48 -> 53.482904 | F21: =F18*Supuestos!$C$48 -> 60.168267 | G21: =G18*Supuestos!$C$48 -> 66.185093 | H21: =H18*Supuestos!$C$48 -> 70.81805
A22: Cuentas por pagar | C22: =Historicos!$E$52 -> 260.791 | D22: =D18*Supuestos!$C$49/360 -> 335.42132 | E22: =E18*Supuestos!$C$49/360 -> 382.3803 | F22: =F18*Supuestos!$C$49/360 -> 430.17784 | G22: =G18*Supuestos!$C$49/360 -> 473.19563 | H22: =H18*Supuestos!$C$49/360 -> 506.31932
A23: Ingresos diferidos | C23: =Historicos!$E$53 -> 143.445 | D23: =D5*Supuestos!$C$50/360 -> 163.25425 | E23: =E5*Supuestos!$C$50/360 -> 186.10984 | F23: =F5*Supuestos!$C$50/360 -> 209.37357 | G23: =G5*Supuestos!$C$50/360 -> 230.31093 | H23: =H5*Supuestos!$C$50/360 -> 246.43269
A24: Pasivos acumulados | C24: =Historicos!$E$54 -> 59.224 | D24: =D18*Supuestos!$C$51/360 -> 64.60904 | E24: =E18*Supuestos!$C$51/360 -> 73.654305 | F24: =F18*Supuestos!$C$51/360 -> 82.861094 | G24: =G18*Supuestos!$C$51/360 -> 91.147203 | H24: =H18*Supuestos!$C$51/360 -> 97.527507
A25: Capital de trabajo operativo neto | C25: =C19+C20+C21-C22-C23-C24 -> 114.615 | D25: =D19+D20+D21-D22-D23-D24 -> 140.49327 | E25: =E19+E20+E21-E22-E23-E24 -> 160.16232 | F25: =F19+F20+F21-F22-F23-F24 -> 180.18261 | G25: =G19+G20+G21-G22-G23-G24 -> 198.20087 | H25: =H19+H20+H21-H22-H23-H24 -> 212.07494
A26: Aumento del capital de trabajo operativo neto | D26: =D25-C25 -> 25.878265 | E26: =E25-D25 -> 19.669057 | F26: =F25-E25 -> 20.02029 | G26: =G25-F25 -> 18.018261 | H26: =H25-G25 -> 13.874061
A27: Capex | D27: =D8*(Supuestos!D$41+Supuestos!$C$65) -> 631.27447 | E27: =E8*(Supuestos!E$41+Supuestos!$C$65) -> 719.65289 | F27: =F8*(Supuestos!F$41+Supuestos!$C$65) -> 867.43875 | G27: =G8*(Supuestos!G$41+Supuestos!$C$65) -> 970.08567 | H27: =H8*(Supuestos!H$41+Supuestos!$C$65) -> 1055.0079
A28: Flujo de caja libre no apalancado | D28: =D17+D14-D27-D26 -> 291.62324 | E28: =E17+E14-E27-E26 -> 342.28266 | F28: =F17+F14-F27-F26 -> 314.539 | G28: =G17+G14-G27-G26 -> 321.37148 | H28: =H17+H14-H27-H26 -> 318.6437 | I28: =I17*(1-H35) -> 327.50233
A29: Capital invertido contable (patrimonio + deuda) | C29: =Historicos!$E$90+Historicos!$E$62+Historicos!$E$57 -> 4198.449 | D29: =C29+D27-D14+D26 -> 4150.3724 | E29: =D29+E27-E14+E26 -> 4085.7329 | F29: =E29+F27-F14+F26 -> 4105.7532 | G29: =F29+G27-G14+G26 -> 4171.4806 | H29: =G29+H27-H14+H26 -> 4287.4522
A30: ROIC (NOPAT / capital invertido al inicio del año) | D30: =D17/C29 -> 0.058008719 | E30: =E17/D29 -> 0.066895968 | F30: =F17/E29 -> 0.081884766 | G30: =G17/F29 -> 0.094282059 | H30: =H17/G29 -> 0.1041873
A31: Tasa de reinversión = (capex − D&A + Δ capital de trabajo) / NOPAT | D31: =(D27-D14+D26)/D17 -> -0.19740197 | E31: =(E27-E14+E26)/E17 -> -0.23281492 | F31: =(F27-F14+F26)/F17 -> 0.059840785 | G31: =(G27-G14+G26)/G17 -> 0.16979485 | H31: =(H27-H14+H26)/H17 -> 0.26683737
A33: Crecimiento fundamental = ROIC 2012 × tasa de reinversión 2012 | H33: =H30*H31 -> 0.027801065
A34: Crecimiento a perpetuidad usado (g) | H34: =IF(Supuestos!$C$24=1,H33,Supuestos!$C$25) -> 0.027801065
A35: Tasa de reinversión de largo plazo = g / ROIC 2012 | H35: =H34/H30 -> 0.26683737
A36: Valor terminal 2012 = FCF 2013 / (CPPC − g) | H36: =I28/(Costo_Capital!$C$16-H34) -> 6773.615
A37: Valor terminal 2012 por múltiplo VE/EBITDA (contraste) | H37: =H12*IF(Supuestos!$C$26=1,Comparables!$P$11,Comparables!$P$13) -> 17331.949
A38: VP de los FCF 2008-2012 a Ku | H38: =NPV(Costo_Capital!$C$10,D28:H28) -> 1258.417
A39: VP del valor terminal a Ku | H39: =H36/(1+Costo_Capital!$C$10)^5 -> 4560.4438
A40: VP de los escudos fiscales 2008-2012 a Kd | H40: =NPV(Supuestos!$C$7,Deuda!$L$13:$P$13) -> 284.78312
A41: Valor de las operaciones (APV) | H41: =H38+H39+H40 -> 6103.6439
A42: + Activos no operativos | H42: =Valoracion!$C$20 -> 1944.4871
...

Sheet Sensibilidad
A1: Sensibilidad del valor del patrimonio sin sinergias (millones de US$)
A3: 1. Ku (filas) × crecimiento a perpetuidad g (columnas). CPPC = Ku − t × Kd × D/V; FCF₂₀₁₃ = NOPAT₂₀₁₂(1+g)(1 − g/ROIC).
B4: 0.015 | C4: 0.02 | D4: 0.025 | E4: 0.03 | F4: 0.035 | G4: 0.04
A5: 0.075 | B5: =NPV($A5,Proyeccion!$D$28:$H$28)+Proyeccion!$H$40+Proyeccion!$H$17*(1+B$4)*(1-B$4/Proyeccion!$H$30)/(($A5-Supuestos!$C$6*Supuestos!$C$7*Costo_Capital!$C$11)-B$4)/(1+$A5)^5+Valoracion!$C$20-Valoracion!$C$26 -> 7110.6906 | C5: =NPV($A5,Proyeccion!$D$28:$H$28)+Proyeccion!$H$40+Proyeccion!$H$17*(1+C$4)*(1-C$4/Proyeccion!$H$30)/(($A5-Supuestos!$C$6*Supuestos!$C$7*Costo_Capital!$C$11)-C$4)/(1+$A5)^5+Valoracion!$C$20-Valoracion!$C$26 -> 7334.3291 | D5: =NPV($A5,Proyeccion!$D$28:$H$28)+Proyeccion!$H$40+Proyeccion!$H$17*(1+D$4)*(1-D$4/Proyeccion!$H$30)/(($A5-Supuestos!$C$6*Supuestos!$C$7*Costo_Capital!$C$11)-D$4)/(1+$A5)^5+Valoracion!$C$20-Valoracion!$C$26 -> 7605.6952 | E5: =NPV($A5,Proyeccion!$D$28:$H$28)+Proyeccion!$H$40+Proyeccion!$H$17*(1+E$4)*(1-E$4/Proyeccion!$H$30)/(($A5-Supuestos!$C$6*Supuestos!$C$7*Costo_Capital!$C$11)-E$4)/(1+$A5)^5+Valoracion!$C$20-Valoracion!$C$26 -> 7943.2338 | F5: =NPV($A5,Proyeccion!$D$28:$H$28)+Proyeccion!$H$40+Proyeccion!$H$17*(1+F$4)*(1-F$4/Proyeccion!$H$30)/(($A5-Supuestos!$C$6*Supuestos!$C$7*Costo_Capital!$C$11)-F$4)/(1+$A5)^5+Valoracion!$C$20-Valoracion!$C$26 -> 8376.2998 | G5: =NPV($A5,Proyeccion!$D$28:$H$28)+Proyeccion!$H$40+Proyeccion!$H$17*(1+G$4)*(1-G$4/Proyeccion!$H$30)/(($A5-Supuestos!$C$6*Supuestos!$C$7*Costo_Capital!$C$11)-G$4)/(1+$A5)^5+Valoracion!$C$20-Valoracion!$C$26 -> 8954.6241
A6: 0.0775 | B6: =NPV($A6,Proyeccion!$D$28:$H$28)+Proyeccion!$H$40+Proyeccion!$H$17*(1+B$4)*(1-B$4/Proyeccion!$H$30)/(($A6-Supuestos!$C$6*Supuestos!$C$7*Costo_Capital!$C$11)-B$4)/(1+$A6)^5+Valoracion!$C$20-Valoracion!$C$26 -> 6831.207 | C6: =NPV($A6,Proyeccion!$D$28:$H$28)+Proyeccion!$H$40+Proyeccion!$H$17*(1+C$4)*(1-C$4/Proyeccion!$H$30)/(($A6-Supuestos!$C$6*Supuestos!$C$7*Costo_Capital!$C$11)-C$4)/(1+$A6)^5+Valoracion!$C$20-Valoracion!$C$26 -> 7020.5929 | D6: =NPV($A6,Proyeccion!$D$28:$H$28)+Proyeccion!$H$40+Proyeccion!$H$17*(1+D$4)*(1-D$4/Proyeccion!$H$30)/(($A6-Supuestos!$C$6*Supuestos!$C$7*Costo_Capital!$C$11)-D$4)/(1+$A6)^5+Valoracion!$C$20-Valoracion!$C$26 -> 7247.7705 | E6: =NPV($A6,Proyeccion!$D$28:$H$28)+Proyeccion!$H$40+Proyeccion!$H$17*(1+E$4)*(1-E$4/Proyeccion!$H$30)/(($A6-Supuestos!$C$6*Supuestos!$C$7*Costo_Capital!$C$11)-E$4)/(1+$A6)^5+Valoracion!$C$20-Valoracion!$C$26 -> 7526.4609 | F6: =NPV($A6,Proyeccion!$D$28:$H$28)+Proyeccion!$H$40+Proyeccion!$H$17*(1+F$4)*(1-F$4/Proyeccion!$H$30)/(($A6-Supuestos!$C$6*Supuestos!$C$7*Costo_Capital!$C$11)-F$4)/(1+$A6)^5+Valoracion!$C$20-Valoracion!$C$26 -> 7877.9427 | G6: =NPV($A6,Proyeccion!$D$28:$H$28)+Proyeccion!$H$40+Proyeccion!$H$17*(1+G$4)*(1-G$4/Proyeccion!$H$30)/(($A6-Supuestos!$C$6*Supuestos!$C$7*Costo_Capital!$C$11)-G$4)/(1+$A6)^5+Valoracion!$C$20-Valoracion!$C$26 -> 8337.085
